Workbook

Sheet Detumbling
B2: Subsystem | C2: Module | E2: Product | F2: Note | G2: Manufacturer | H2: channel | I2: Mode | J2: Voltage Input | K2: Current(A) | N2: Power | R2: Duty(%) | S2: Consumption Power (W) | W2: Note
K3: Idle | L3: Nominal | M3: Peak | N3: Idel | O3: Nominal | P3: Peak | Q3: Mode | R3: Detumbling | T3: Detumbling | W3: Orbit period | X3: =parameter!C8 -> 5676.9849
Q4: Time | R4: =X3 -> 5676.9849 | T4: =X3 -> 5676.9849 | W4: Missiond period | X4: 681
B5: EPS | D5: Battery | E5: Optimus-40 | F5: When heater active | G5: AAC Clyde space | O5: 0.8 | R5: 1 | T5: =R5*O5 -> 0.8 | W5: S-band period | X5: 661
D6: PCDU | E6: Starbuck-Nano-Plus | R6: 1 | T6: =R6*O6 -> 0 | W6: sunlight | X6: =parameter!C10 -> 3654.1162
C7: MSP | D7: Solar cell | E7: 3G30C-Advanced | G7: AZURSPACE | R7: 1 | T7: =R7*O7 -> 0 | W7: Eclipse | X7: =parameter!C11 -> 2022.8687
B8: GNC(ADCS) | D8: CSS(with Solar panel) | E8: Coarse Sun Sensors | G8: GOMSPACE | H8: 3.3V | J8: 3.3 | L8: 0.00093 | O8: =J8*L8 -> 0.003069 | R8: 1 | T8: =R8*O8 -> 0.003069 | W8: solar panel efficiency | X8: 0.3
C9: ADCS Module | D9: CSS(TBD) | E9: Coarse Sun Sensors | F9: Coarse Sun Sensor x 10 | G9: CUBESPACE | J9: 3.3 | L9: =O9/J9 -> 0.0015151515 | O9: 0.005 | R9: 1 | T9: =R9*O9 -> 0.005 | W9: Emppt | X9: 0.6
D10: CUBECOM | E10: Cubecomputer | J10: 3.3 | L10: =O10/J10 -> 0.036363636 | M10: =P10/J10 -> 0.060606061 | O10: 0.12 | P10: 0.2 | R10: 1 | T10: =R10*O10 -> 0.12 | W10: Etmp | X10: 0.8
D11: FSS | E11: Cubesense V3 x 2 | J11: 3.3 | L11: =O11/J11 -> 0.060606061 | M11: =P11/J11 -> 0.12121212 | O11: 0.2 | P11: 0.4 | R11: 1 | T11: =R11*O11 -> 0.2 | W11: Eman | X11: 0.8
E12: Cubecontrol | I12: Typ | J12: 3.3 | L12: =O12/J12 -> 0.060606061 | O12: 0.2 | R12: =100%-R13 -> 1 | T12: =R12*O12 -> 0.2 | W12: Depth of Discharge | X12: 0.2
F13: Include Momentum Wheel | I13: Momentum wheel | J13: 3.3 | L13: =O13/J13 -> 0.086363636 | M13: =P13/J13 -> 0.13333333 | O13: 0.285 | P13: 0.44 | R13: =R16 -> 0 | W13: Conversion Efficiency | X13: 0.9
D14: MMT | E14: CubeMag | F14: Deployable Magnetometer | I14: Typ | J14: 3.3 | L14: =O14/J14 -> 0.010606061 | O14: 0.035 | R14: 1 | T14: =R14*O14 -> 0.035 | W14: required margin | X14: 0.4
F15: Circuit activate for 5s (0.62Ax8V) | G15: CUBESPACE | H15: VBAT(1) | I15: Deployment mag | J15: 8 | L15: 0.62 | O15: =J15*L15 -> 4.96
D16: RWA | E16: Cube Wheel Medium x 3 | G16: CUBESPACE | H16: VBAT(2) | J16: 8.26 | K16: =0.065*3/J16 -> 0.023607748 | L16: =0.19*3/J16 -> 0.069007264 | M16: =2.3*3/J16 -> 0.83535109 | N16: 0.065 | O16: 0.19 | P16: 2.3 | R16: 0 | T16: =O16*R16 -> 0
D19: MTQ | E19: CubeTorquers rod | F19: Small Rod x 2 | G19: CUBESPACE | H19: 5V | J19: 5 | L19: =0.07*2 -> 0.14 | M19: =0.167*2 -> 0.334 | O19: =L19*J19 -> 0.7 | P19: =M19*J19 -> 1.67 | R19: 0 | T19: =R19*O19 -> 0
E20: CubeTorquers coil | F20: Coil x 1 | J20: 5 | L20: 0.064 | O20: =L20*J20 -> 0.32 | R20: 0 | T20: =R20*O20 -> 0
D21: GPS ANT | E21: TW1829 | F21: Low Noise Amplifier | G21: TALLYSMAN | H21: 3.3V | J21: 3.3 | L21: =O21/J21 -> 0.0036363636 | O21: 0.012 | R21: 1 | T21: =R21*O21 -> 0.012
D22: GPS Rx | E22: OEM719 | G22: NovAtel | H22: 3.3V(1) | J22: 3.3 | L22: =O22/J22 -> 0.39393939 | O22: 1.3 | R22: 0 | T22: =R22*O22 -> 0
B23: CNDH | D23: OBC | E23: HYVRID OBC | G23: NST | H23: 3.3V | J23: 3.3 | L23: =0.13 -> 0.13 | O23: =L23*J23 -> 0.429 | R23: 1 | T23: =R23*O23 -> 0.429
B24: COMS | D24: UHF ANT | E24: Deployable Antenna System | G24: ISIS | H24: 3.3V | I24: stowed | J24: 3.3 | L24: 0.013 | O24: =L24*J24 -> 0.0429 | R24: 1 | T24: =R24*O24 -> 0.0429
F25: Typical Deployment Duration < 3s | I25: deployed | J25: 3.3 | L25: 0.011 | O25: =L25*J25 -> 0.0363
F26: During Deployment 2W Power Consumption | I26: deployment | J26: 3.3 | L26: 0.55 | O26: =L26*J26 -> 1.815
D27: UHF TRx | E27: NanoCom AX100 | G27: GOMSPACE | I27: Rx | J27: 3.3 | K27: 0.045 | L27: 0.055 | M27: 0.12 | N27: =J27*K27 -> 0.1485 | O27: =L27*J27 -> 0.1815 | P27: =M27*J27 -> 0.396 | R27: 1 | T27: =R27*O27 -> 0.1815
F28: extreme temperature : -30℃~+85℃ | I28: Tx | J28: 3.3 | K28: 0.6 | L28: 0.8 | M28: 1 | N28: =J28*K28 -> 1.98 | O28: =L28*J28 -> 2.64 | P28: =M28*J28 -> 3.3 | R28: =100%-R27 -> 0 | T28: =R28*O28 -> 0
F29: Transmitter with adjustable 24 to 30 dBm output power
D30: S-band ANT | E30: PULSAR-SANT | G30: AAC Clyde space | H30: 5V | J30: 5 | L30: 0 | O30: 0 | R30: 0 | T30: =R30*O30 -> 0
D31: S-band Tx | E31: PULSAR-STX | I31: Idle(OFF) | J31: 5 | L31: =O31/5 -> 0.122 | O31: 0.61 | R31: 0 | T31: =R31*O31 -> 0
I32: 24dBM RF | J32: 5 | L32: =O32/5 -> 0.54 | O32: 2.7 | R32: 0 | T32: =R32*O32 -> 0
I33: 30dBM RF | J33: 5 | L33: =O33/5 -> 0.92 | M33: =P33/5 -> 1 | O33: 4.6 | P33: 5 | R33: 0 | T33: =R33*O33 -> 0
B34: PAYS | C34: PAYS | D34: PAYS | E34: 레이저 감지기 | G34: Ophir | H34: 5V(2) | J34: 5 | L34: =O34/J34 -> 0.2 | O34: 1 | R34: 0 | T34: =R34*O34 -> 0
C35: PAYR | D35: PAYR | E35: 박막전개장치 | G35: in-house | H35: 5V(1) | J35: 5 | L35: =O35/J35 -> 0.2 | O35: 1 | R35: 0 | T35: =R35*O35 -> 0
D36: PAYR | E36: 박막전개장치 | G36: in-house | H36: 3.3V(3) | J36: 3.3 | M36: =P36/J36 -> 0.60606061 | P36: 2 | R36: 0 | T36: =R36*O36 -> 0
C37: PAYC | D37: PAYC | E37: Nanocam C1U | F37: Peak Power = 3.6V x 500mA @ Max | G37: GOMSPACE | H37: 3.3V(2) | J37: 3.3 | K37: =N37/J37 -> 0.11515152 | L37: =O37/J37 -> 0.24242424 | M37: =P37/J37 -> 0.54545455 | N37: 0.38 | O37: 0.8 | P37: 1.8 | R37: 0 | T37: =R37*O37 -> 0
S38: total power consumption | T38: =SUM(T5:T37)/X13 -> 2.2538544 | U38: W | V38: worst case
S39: Generated Energy(orbit average) | T39: =1.135*(6*3+6*3+4*3+4*3)/(3+3+3+3+1+1)*X6/3600 -> 4.937407 | U39: Wh
S40: Required Energy (orbit average) | T40: =T38*X3/3600 -> 3.5541938 | U40: Wh
S41: Power Margin Value | T41: =T39-T40 -> 1.3832132 | U41: Wh
S42: Power Margin | T42: =100*($T$39/T40-1) -> 38.917777 | U42: %
S43: Residual/Generation | T43: =T41/$T$39*100 -> 28.014972 | U43: % | V43: >40%
...

Sheet ① 2주기(Mission&UHF)
B2: Subsystem | C2: Module | E2: Product | F2: Note | G2: Manufacturer | H2: channel | I2: Mode | J2: Voltage Input | K2: Current(A) | N2: Power | R2: Duty(%) | U2: Consumption Power (W) | AB2: Note
K3: Idle | L3: Nominal | M3: Peak | N3: Idel | O3: Nominal | P3: Peak | Q3: Mode | R3: Stand-by(D) | S3: Stand-by(N) | T3: Mission & UHF COM | V3: Stand-by(D) | W3: Stand-by(N) | X3: Mission & UHF COM | Y3: total (time rate) | AB3: Orbit period | AC3: =parameter!C8 -> 5676.9849
Q4: Time | R4: =AC6-AC4 -> 2973.1162 | S4: =AC7 -> 2022.8687 | T4: =AC4 -> 681 | V4: =AC6-AC4 -> 2973.1162 | W4: =AC7 -> 2022.8687 | X4: =AC4 -> 681 | Y4: =V4+W4+X4 -> 5676.9849 | AB4: Missiond period | AC4: 681
B5: EPS | D5: Battery | E5: Optimus-40 | F5: When heater active | G5: AAC Clyde space | O5: 0.8 | R5: 1 | S5: 1 | T5: 1 | V5: =R5*O5*V4/Y4 -> 0.41897116 | W5: =O5*S5*W4/Y4 -> 0.28506241 | X5: =O5*T5*X4/Y4 -> 0.095966435 | Y5: =V5+W5+X5 -> 0.8 | AB5: S-band period | AC5: 661
D6: PCDU | E6: Starbuck-Nano-Plus | R6: 1 | S6: 1 | T6: 1 | V6: =R6*O6*V4/Y4 -> 0 | W6: =O6*S6*W4/Y4 -> 0 | X6: =O6*T6*X4/Y4 -> 0 | Y6: =V6+W6+X6 -> 0 | AB6: sunlight | AC6: =parameter!C10 -> 3654.1162
C7: MSP | D7: Solar cell | E7: 3G30C-Advanced | G7: AZURSPACE | R7: 1 | S7: 1 | T7: 1 | V7: =R7*O7*V4/Y4 -> 0 | W7: =O7*S7*W4/Y4 -> 0 | X7: =O7*T7*X4/Y4 -> 0 | Y7: =V7+W7+X7 -> 0 | AB7: Eclipse | AC7: =parameter!C11 -> 2022.8687
B8: GNC(ADCS) | D8: CSS(with Solar panel) | E8: Coarse Sun Sensors | G8: GOMSPACE | H8: 3.3V | J8: 3.3 | L8: 0.00093 | O8: =J8*L8 -> 0.003069 | R8: 1 | S8: 1 | T8: 1 | V8: =R8*O8*V4/Y4 -> 0.0016072781 | W8: =O8*S8*W4/Y4 -> 0.0010935707 | X8: =O8*T8*X4/Y4 -> 0.00036815124 | Y8: =V8+W8+X8 -> 0.003069 | AB8: solar panel efficiency | AC8: 0.3
C9: ADCS Module | D9: CSS(TBD) | E9: Coarse Sun Sensors | F9: Coarse Sun Sensor x 10 | G9: CUBESPACE | J9: 3.3 | L9: =O9/J9 -> 0.0015151515 | O9: 0.005 | R9: 1 | S9: 1 | T9: 1 | V9: =R9*O9*V4/Y4 -> 0.0026185697 | W9: =O9*S9*W4/Y4 -> 0.00178164 | X9: =O9*T9*X4/Y4 -> 0.00059979022 | Y9: =V9+W9+X9 -> 0.005 | AB9: Emppt | AC9: 0.6
D10: CUBECOM | E10: Cubecomputer | J10: 3.3 | L10: =O10/J10 -> 0.036363636 | M10: =P10/J10 -> 0.060606061 | O10: 0.12 | P10: 0.2 | R10: 1 | S10: 1 | T10: 1 | V10: =R10*O10*V4/Y4 -> 0.062845674 | W10: =O10*S10*W4/Y4 -> 0.042759361 | X10: =P10*T10*X4/Y4 -> 0.023991609 | Y10: =V10+W10+X10 -> 0.12959664 | AB10: Etmp | AC10: 0.8
D11: FSS | E11: Cubesense V3 x 2 | J11: 3.3 | L11: =O11/J11 -> 0.060606061 | M11: =P11/J11 -> 0.12121212 | O11: 0.2 | P11: 0.4 | R11: 1 | S11: 1 | T11: 1 | V11: =R11*O11*V4/Y4 -> 0.10474279 | W11: =O11*S11*W4/Y4 -> 0.071265601 | X11: =P11*T11*X4/Y4 -> 0.047983217 | Y11: =V11+W11+X11 -> 0.22399161 | AB11: Eman | AC11: 0.8
E12: Cubecontrol | I12: Typ | J12: 3.3 | L12: =O12/J12 -> 0.060606061 | O12: 0.2 | R12: =100%-R13 -> 0 | S12: =100%-S13 -> 0 | T12: =100%-T13 -> 0 | V12: =R12*O12*V4/Y4 -> 0 | W12: =O12*S12*W4/Y4 -> 0 | X12: =T12*P12*X4/Y4 -> 0 | Y12: =V12+W12+X12 -> 0 | AB12: Depth of Discharge | AC12: 0.2
F13: Include Momentum Wheel | I13: Momentum wheel | J13: 3.3 | L13: =O13/J13 -> 0.086363636 | M13: =P13/J13 -> 0.13333333 | O13: 0.285 | P13: 0.44 | R13: =R16 -> 1 | S13: =S16 -> 1 | T13: =T16 -> 1 | V13: =R13*O13*V4/Y4 -> 0.14925848 | W13: =O13*S13*W4/Y4 -> 0.10155348 | X13: =P13*T13*X4/Y4 -> 0.052781539 | Y13: =V13+W13+X13 -> 0.3035935 | AB13: Conversion Efficiency | AC13: 0.9
D14: MMT | E14: CubeMag | F14: Deployable Magnetometer | I14: Typ | J14: 3.3 | L14: =O14/J14 -> 0.010606061 | O14: 0.035 | R14: 1 | S14: 1 | T14: 1 | V14: =R14*O14*V4/Y4 -> 0.018329988 | W14: =O14*S14*W4/Y4 -> 0.01247148 | X14: =T14*O14*X4/Y4 -> 0.0041985315 | Y14: =V14+W14+X14 -> 0.035 | AB14: required margin | AC14: 0.4
F15: Circuit activate for 5s (0.62Ax8V) | G15: CUBESPACE | H15: VBAT(1) | I15: Deployment mag | J15: 8 | L15: 0.62 | O15: =J15*L15 -> 4.96
D16: RWA | E16: Cube Wheel Medium x 3 | G16: CUBESPACE | H16: VBAT(2) | J16: 8.26 | K16: =0.065*3/J16 -> 0.023607748 | L16: =0.19*3/J16 -> 0.069007264 | M16: =2.3*3/J16 -> 0.83535109 | N16: 0.065 | O16: 0.19 | P16: 2.3 | R16: 1 | S16: 1 | T16: 1 | V16: =R16*O16*V4/Y4 -> 0.09950565 | W16: =O16*S16*W4/Y4 -> 0.067702321 | X16: =P16*T16*X4/Y4 -> 0.2759035 | Y16: =V16+W16+X16 -> 0.44311147
D19: MTQ | E19: CubeTorquers rod | F19: Small Rod x 2 | G19: CUBESPACE | H19: 5V | J19: 5 | L19: =0.07*2 -> 0.14 | M19: =0.167*2 -> 0.334 | O19: =L19*J19 -> 0.7 | P19: =M19*J19 -> 1.67 | R19: 0 | S19: 0 | T19: 0 | V19: =R19*O19*V4/Y4 -> 0 | W19: =S19*O19*W4/Y4 -> 0 | X19: =T19*O19*X4/Y4 -> 0 | Y19: =V19+W19+X19 -> 0
E20: CubeTorquers coil | F20: Coil x 1 | J20: 5 | L20: 0.064 | O20: =L20*J20 -> 0.32 | R20: 0 | S20: 0 | T20: 0 | V20: =R20*O20*V4/Y4 -> 0 | W20: =S20*O20*W4/Y4 -> 0 | X20: =T20*O20*X4/Y4 -> 0 | Y20: =V20+W20+X20 -> 0
D21: GPS ANT | E21: TW1829 | F21: Low Noise Amplifier | G21: TALLYSMAN | H21: 3.3V | J21: 3.3 | L21: =O21/J21 -> 0.0036363636 | O21: 0.012 | R21: 1 | S21: 1 | T21: 1 | V21: =R21*O21*V4/Y4 -> 0.0062845674 | W21: =S21*O21*W4/Y4 -> 0.0042759361 | X21: =T21*O21*X4/Y4 -> 0.0014394965 | Y21: =V21+W21+X21 -> 0.012
D22: GPS Rx | E22: OEM719 | G22: NovAtel | H22: 3.3V(1) | J22: 3.3 | L22: =O22/J22 -> 0.39393939 | O22: 1.3 | R22: 0.5 | S22: 0.5 | T22: 1 | V22: =R22*O22*V4/Y4 -> 0.34041407 | W22: =S22*O22*W4/Y4 -> 0.2316132 | X22: =T22*O22*X4/Y4 -> 0.15594546 | Y22: =V22+W22+X22 -> 0.72797273
B23: CNDH | D23: OBC | E23: HYVRID OBC | G23: NST | H23: 3.3V | J23: 3.3 | L23: =0.13 -> 0.13 | O23: =L23*J23 -> 0.429 | R23: 1 | S23: 1 | T23: 1 | V23: =R23*O23*V4/Y4 -> 0.22467328 | W23: =S23*O23*W4/Y4 -> 0.15286471 | X23: =T23*O23*X4/Y4 -> 0.051462001 | Y23: =V23+W23+X23 -> 0.429
B24: COMS | D24: UHF ANT | E24: Deployable Antenna System | G24: ISIS | H24: 3.3V | I24: stowed | J24: 3.3 | L24: 0.013 | O24: =L24*J24 -> 0.0429 | V24: =R24*O24*V4/Y4 -> 0 | W24: =S24*O24*W4/Y4 -> 0 | X24: =T24*O24*X4/Y4 -> 0 | Y24: =V24+W24+X24 -> 0
F25: Typical Deployment Duration < 3s | I25: deployed | J25: 3.3 | L25: 0.011 | O25: =L25*J25 -> 0.0363 | R25: 1 | S25: 1 | T25: 1 | V25: =R25*O25*V4/Y4 -> 0.019010816 | W25: =S25*O25*W4/Y4 -> 0.012934707 | X25: =T25*O25*X4/Y4 -> 0.004354477 | Y25: =V25+W25+X25 -> 0.0363
F26: During Deployment 2W Power Consumption | I26: deployment | J26: 3.3 | L26: 0.55 | O26: =L26*J26 -> 1.815 | V26: =R26*O26*V4/Y4 -> 0 | W26: =S26*O26*W4/Y4 -> 0 | X26: =T26*O26*X4/Y4 -> 0 | Y26: =V26+W26+X26 -> 0
D27: UHF TRx | E27: NanoCom AX100 | G27: GOMSPACE | I27: Rx | J27: 3.3 | K27: 0.045 | L27: 0.055 | M27: 0.12 | N27: =J27*K27 -> 0.1485 | O27: =L27*J27 -> 0.1815 | P27: =M27*J27 -> 0.396 | R27: 0.9 | S27: 0.9 | T27: 0.8 | V27: =R27*O27*V4/Y4 -> 0.085548674 | W27: =S27*O27*W4/Y4 -> 0.05820618 | X27: =T27*P27*X4/Y4 -> 0.038002708 | Y27: =V27+W27+X27 -> 0.18175756
F28: extreme temperature : -30℃~+85℃ | I28: Tx | J28: 3.3 | K28: 0.6 | L28: 0.8 | M28: 1 | N28: =J28*K28 -> 1.98 | O28: =L28*J28 -> 2.64 | P28: =M28*J28 -> 3.3 | R28: =100%-R27 -> 0.1 | S28: =100%-S27 -> 0.1 | T28: =100%-T27 -> 0.2 | V28: =R28*O28*V4/Y4 -> 0.13826048 | W28: =S28*O28*W4/Y4 -> 0.094070594 | X28: =T28*P28*X4/Y4 -> 0.079172309 | Y28: =V28+W28+X28 -> 0.31150339
F29: Transmitter with adjustable 24 to 30 dBm output power
D30: S-band ANT | E30: PULSAR-SANT | G30: AAC Clyde space | H30: 5V | J30: 5 | L30: 0 | O30: 0 | R30: 0 | S30: 0 | T30: 0 | V30: =R30*O30*V4/Y4 -> 0 | W30: =S30*O30*W4/Y4 -> 0 | X30: =T30*O30*X4/Y4 -> 0 | Y30: =V30+W30+X30 -> 0
D31: S-band Tx | E31: PULSAR-STX | I31: Idle(OFF) | J31: 5 | L31: =O31/5 -> 0.122 | O31: 0.61 | R31: 0 | S31: 0 | T31: 0 | V31: =R31*O31*V4/Y4 -> 0 | W31: =S31*O31*W4/Y4 -> 0 | X31: =T31*O31*X4/Y4 -> 0 | Y31: =V31+W31+X31 -> 0
I32: 24dBM RF | J32: 5 | L32: =O32/5 -> 0.54 | O32: 2.7 | R32: 0 | S32: 0 | T32: 0 | V32: =R32*O32*V4/Y4 -> 0 | W32: =S32*O32*W4/Y4 -> 0 | X32: =T32*O32*X4/Y4 -> 0 | Y32: =V32+W32+X32 -> 0
I33: 30dBM RF | J33: 5 | L33: =O33/5 -> 0.92 | M33: =P33/5 -> 1 | O33: 4.6 | P33: 5 | R33: 0 | S33: 0 | T33: 0 | V33: =R33*O33*V4/Y4 -> 0 | W33: =S33*O33*W4/Y4 -> 0 | X33: =T33*P33*X4/Y4 -> 0 | Y33: =V33+W33+X33 -> 0
B34: PAYS | C34: PAYS | D34: PAYS | E34: 레이저 감지기 | G34: Ophir | H34: 5V(2) | J34: 5 | L34: =O34/J34 -> 0.2 | O34: 1 | R34: 0 | S34: 0 | T34: 1 | V34: =R34*O34*V4/Y4 -> 0 | W34: =S34*O34*W4/Y4 -> 0 | X34: =T34*O34*X4/Y4 -> 0.11995804 | Y34: =V34+W34+X34 -> 0.11995804
C35: PAYR | D35: PAYR | E35: 박막전개장치 | G35: in-house | H35: 5V(1) | J35: 5 | L35: =O35/J35 -> 0.2 | O35: 1 | R35: 0 | S35: 0 | T35: 1 | V35: =R35*O35*V4/Y4 -> 0 | W35: =S35*O35*W4/Y4 -> 0 | X35: =T35*O35*X4/Y4 -> 0.11995804 | Y35: =V35+W35+X35 -> 0.11995804
D36: PAYR | E36: 박막전개장치 | G36: in-house | H36: 3.3V(3) | J36: 3.3 | M36: =P36/J36 -> 0.60606061 | P36: 2 | R36: 0 | S36: 0 | T36: 0 | V36: =R36*O36*V4/Y4 -> 0 | W36: =S36*O36*W4/Y4 -> 0 | X36: =T36*P36*X4/Y4 -> 0 | Y36: =V36+W36+X36 -> 0
C37: PAYC | D37: PAYC | E37: Nanocam C1U | F37: Peak Power = 3.6V x 500mA @ Max | G37: GOMSPACE | H37: 3.3V(2) | J37: 3.3 | K37: =N37/J37 -> 0.11515152 | L37: =O37/J37 -> 0.24242424 | M37: =P37/J37 -> 0.54545455 | N37: 0.38 | O37: 0.8 | P37: 1.8 | R37: 0 | S37: 0 | T37: 1 | V37: =R37*O37*V4/Y4 -> 0 | W37: =S37*O37*W4/Y4 -> 0 | X37: =T37*P37*X4/Y4 -> 0.21592448 | Y37: =V37+W37+X37 -> 0.21592448
U38: total power consumption | V38: =SUM(V5:V37)/0.9 -> 1.8578572 | W38: =SUM(W5:W37)/0.9 -> 1.2640613 | X38: =SUM(X5:X37)/0.9 -> 1.431122 | Y38: =SUM(Y5:Y37)/0.9 -> 4.5530405 | Z38: W | AA38: worst case
U39: Generated Energy(orbit average) | V39: =1.135*20*V4/3600 -> 18.747149 | W39: 0 | X39: 0 | Y39: =V39+W39+X39 -> 18.747149 | Z39: Wh
U40: Required Energy (orbit average) | V40: =V38*Y4/3600 -> 2.9297298 | W40: =W38*Y4/3600 -> 1.9933492 | X40: =X38*Y4/3600 -> 2.2567939 | Y40: =V40+W40+X40 -> 7.1798728 | Z40: Wh
U41: Power Margin Value | V41: =Y39-Y40 -> 11.567276 | Y41: =V41+W41+X41 -> 11.567276 | Z41: Wh
U42: Power Margin | V42: =100*(Y39/Y40-1) -> 161.10698 | Y42: =V42+W42+X42 -> 161.10698 | Z42: %
U43: Residual/Generation | V43: =V41/$V$39*100 -> 61.701522 | Y43: =V43+W43+X43 -> 61.701522 | Z43: % | AA43: >40%
...

Sheet ② 8주기(S-band)
B2: Subsystem | C2: Module | E2: Product | F2: Note | G2: Manufacturer | H2: channel | I2: Mode | J2: Voltage Input | K2: Current(A) | N2: Power | R2: Duty(%) | U2: Consumption Power (W) | AB2: Note
K3: Idle | L3: Nominal | M3: Peak | N3: Idel | O3: Nominal | P3: Peak | Q3: Mode | R3: Stand-by(D) | S3: Stand-by(N) | T3: S-band COM | V3: Stand-by(D) | W3: Stand-by(N) | X3: S-band COM | Y3: total | AB3: Orbit period | AC3: =parameter!C8 -> 5676.9849
Q4: Time | R4: =AC6 -> 3654.1162 | S4: =AC7-AC5 -> 1361.8687 | T4: =AC5 -> 661 | V4: =AC6 -> 3654.1162 | W4: =AC7-AC5 -> 1361.8687 | X4: =AC5 -> 661 | Y4: =V4+W4+X4 -> 5676.9849 | AB4: Missiond period | AC4: 681
B5: EPS | D5: Battery | E5: Optimus-40 | F5: When heater active | G5: AAC Clyde space | O5: 0.8 | R5: 1 | S5: 1 | T5: 1 | V5: =R5*O5*V4/Y4 -> 0.51493759 | W5: =O5*S5*W4/Y4 -> 0.19191437 | X5: =O5*T5*X4/Y4 -> 0.093148037 | Y5: =V5+W5+X5 -> 0.8 | AB5: S-band period | AC5: 661
D6: PCDU | E6: Starbuck-Nano-Plus | R6: 1 | S6: 1 | T6: 1 | V6: =R6*O6*V4/Y4 -> 0 | W6: =O6*S6*W4/Y4 -> 0 | X6: =O6*T6*X4/Y4 -> 0 | Y6: =V6+W6+X6 -> 0 | AB6: sunlight | AC6: =parameter!C10 -> 3654.1162
C7: MSP | D7: Solar cell | E7: 3G30C-Advanced | G7: AZURSPACE | R7: 1 | S7: 1 | T7: 1 | V7: =R7*O7*V4/Y4 -> 0 | W7: =O7*S7*W4/Y4 -> 0 | X7: =O7*T7*X4/Y4 -> 0 | Y7: =V7+W7+X7 -> 0 | AB7: Eclipse | AC7: =parameter!C11 -> 2022.8687
B8: GNC(ADCS) | D8: CSS(with Solar panel) | E8: Coarse Sun Sensors | G8: GOMSPACE | H8: 3.3V | J8: 3.3 | L8: 0.00093 | O8: =J8*L8 -> 0.003069 | R8: 1 | S8: 1 | T8: 1 | V8: =R8*O8*V4/Y4 -> 0.0019754293 | W8: =O8*S8*W4/Y4 -> 0.0007362315 | X8: =O8*T8*X4/Y4 -> 0.00035733916 | Y8: =V8+W8+X8 -> 0.003069 | AB8: solar panel efficiency | AC8: 0.3
C9: ADCS Module | D9: CSS(TBD) | E9: Coarse Sun Sensors | F9: Coarse Sun Sensor x 10 | G9: CUBESPACE | J9: 3.3 | L9: =O9/J9 -> 0.0015151515 | O9: 0.005 | R9: 1 | S9: 1 | T9: 1 | V9: =R9*O9*V4/Y4 -> 0.00321836 | W9: =O9*S9*W4/Y4 -> 0.0011994648 | X9: =O9*T9*X4/Y4 -> 0.00058217523 | Y9: =V9+W9+X9 -> 0.005 | AB9: Emppt | AC9: 0.6
D10: CUBECOM | E10: Cubecomputer | J10: 3.3 | L10: =O10/J10 -> 0.036363636 | M10: =P10/J10 -> 0.060606061 | O10: 0.12 | P10: 0.2 | R10: 1 | S10: 1 | T10: 1 | V10: =R10*O10*V4/Y4 -> 0.077240639 | W10: =O10*S10*W4/Y4 -> 0.028787155 | X10: =P10*T10*X4/Y4 -> 0.023287009 | Y10: =V10+W10+X10 -> 0.1293148 | AB10: Etmp | AC10: 0.8
D11: FSS | E11: Cubesense V3 x 2 | J11: 3.3 | L11: =O11/J11 -> 0.060606061 | M11: =P11/J11 -> 0.12121212 | O11: 0.2 | P11: 0.4 | R11: 1 | S11: 1 | T11: 1 | V11: =R11*O11*V4/Y4 -> 0.1287344 | W11: =O11*S11*W4/Y4 -> 0.047978592 | X11: =P11*T11*X4/Y4 -> 0.046574019 | Y11: =V11+W11+X11 -> 0.22328701 | AB11: Eman | AC11: 0.8
E12: Cubecontrol | I12: Typ | J12: 3.3 | L12: =O12/J12 -> 0.060606061 | O12: 0.2 | R12: =100%-R13 -> 0 | S12: =100%-S13 -> 0 | T12: =100%-T13 -> 0 | V12: =R12*O12*V4/Y4 -> 0 | W12: =O12*S12*W4/Y4 -> 0 | X12: =T12*P12*X4/Y4 -> 0 | Y12: =V12+W12+X12 -> 0 | AB12: Depth of Discharge | AC12: 0.2
F13: Include Momentum Wheel | I13: Momentum wheel | J13: 3.3 | L13: =O13/J13 -> 0.086363636 | M13: =P13/J13 -> 0.13333333 | O13: 0.285 | P13: 0.44 | R13: =R16 -> 1 | S13: =S16 -> 1 | T13: =T16 -> 1 | V13: =R13*O13*V4/Y4 -> 0.18344652 | W13: =O13*S13*W4/Y4 -> 0.068369494 | X13: =P13*T13*X4/Y4 -> 0.05123142 | Y13: =V13+W13+X13 -> 0.30304743 | AB13: Conversion Efficiency | AC13: 0.9
D14: MMT | E14: CubeMag | F14: Deployable Magnetometer | I14: Typ | J14: 3.3 | L14: =O14/J14 -> 0.010606061 | O14: 0.035 | R14: 1 | S14: 1 | T14: 1 | V14: =R14*O14*V4/Y4 -> 0.02252852 | W14: =O14*S14*W4/Y4 -> 0.0083962536 | X14: =T14*O14*X4/Y4 -> 0.0040752266 | Y14: =V14+W14+X14 -> 0.035 | AB14: required margin | AC14: 0.4
F15: Circuit activate for 5s (0.62Ax8V) | G15: CUBESPACE | H15: VBAT(1) | I15: Deployment mag | J15: 8 | L15: 0.62 | O15: =J15*L15 -> 4.96
D16: RWA | E16: Cube Wheel Medium x 3 | G16: CUBESPACE | H16: VBAT(2) | J16: 8.26 | K16: =0.065*3/J16 -> 0.023607748 | L16: =0.19*3/J16 -> 0.069007264 | M16: =2.3*3/J16 -> 0.83535109 | N16: 0.065 | O16: 0.19 | P16: 2.3 | R16: 1 | S16: 1 | T16: 1 | V16: =R16*O16*V4/Y4 -> 0.12229768 | W16: =O16*S16*W4/Y4 -> 0.045579662 | X16: =P16*T16*X4/Y4 -> 0.26780061 | Y16: =V16+W16+X16 -> 0.43567795
D19: MTQ | E19: CubeTorquers rod | F19: Small Rod x 2 | G19: CUBESPACE | H19: 5V | J19: 5 | L19: =0.07*2 -> 0.14 | M19: =0.167*2 -> 0.334 | O19: =L19*J19 -> 0.7 | P19: =M19*J19 -> 1.67 | R19: 0 | S19: 0 | T19: 1 | V19: =R19*O19*V4/Y4 -> 0 | W19: =S19*O19*W4/Y4 -> 0 | X19: =T19*O19*X4/Y4 -> 0.081504533 | Y19: =V19+W19+X19 -> 0.081504533
E20: CubeTorquers coil | F20: Coil x 1 | J20: 5 | L20: 0.064 | O20: =L20*J20 -> 0.32 | R20: 0 | S20: 0 | T20: 1 | V20: =R20*O20*V4/Y4 -> 0 | W20: =S20*O20*W4/Y4 -> 0 | X20: =T20*O20*X4/Y4 -> 0.037259215 | Y20: =V20+W20+X20 -> 0.037259215
D21: GPS ANT | E21: TW1829 | F21: Low Noise Amplifier | G21: TALLYSMAN | H21: 3.3V | J21: 3.3 | L21: =O21/J21 -> 0.0036363636 | O21: 0.012 | R21: 1 | S21: 1 | T21: 1 | V21: =R21*O21*V4/Y4 -> 0.0077240639 | W21: =S21*O21*W4/Y4 -> 0.0028787155 | X21: =T21*O21*X4/Y4 -> 0.0013972206 | Y21: =V21+W21+X21 -> 0.012
D22: GPS Rx | E22: OEM719 | G22: NovAtel | H22: 3.3V(1) | J22: 3.3 | L22: =O22/J22 -> 0.39393939 | O22: 1.3 | R22: 0.5 | S22: 0.5 | T22: 1 | V22: =R22*O22*V4/Y4 -> 0.4183868 | W22: =S22*O22*W4/Y4 -> 0.15593042 | X22: =T22*O22*X4/Y4 -> 0.15136556 | Y22: =V22+W22+X22 -> 0.72568278
B23: CNDH | D23: OBC | E23: HYVRID OBC | G23: NST | H23: 3.3V | J23: 3.3 | L23: =0.13 -> 0.13 | O23: =L23*J23 -> 0.429 | R23: 1 | S23: 1 | T23: 1 | V23: =R23*O23*V4/Y4 -> 0.27613529 | W23: =S23*O23*W4/Y4 -> 0.10291408 | X23: =T23*O23*X4/Y4 -> 0.049950635 | Y23: =V23+W23+X23 -> 0.429
B24: COMS | D24: UHF ANT | E24: Deployable Antenna System | G24: ISIS | H24: 3.3V | I24: stowed | J24: 3.3 | L24: 0.013 | O24: =L24*J24 -> 0.0429 | V24: =R24*O24*V4/Y4 -> 0 | W24: =S24*O24*W4/Y4 -> 0 | X24: =T24*O24*X4/Y4 -> 0 | Y24: =V24+W24+X24 -> 0
F25: Typical Deployment Duration < 3s | I25: deployed | J25: 3.3 | L25: 0.011 | O25: =L25*J25 -> 0.0363 | R25: 1 | S25: 1 | T25: 1 | V25: =R25*O25*V4/Y4 -> 0.023365293 | W25: =S25*O25*W4/Y4 -> 0.0087081145 | X25: =T25*O25*X4/Y4 -> 0.0042265922 | Y25: =V25+W25+X25 -> 0.0363
F26: During Deployment 2W Power Consumption | I26: deployment | J26: 3.3 | L26: 0.55 | O26: =L26*J26 -> 1.815 | V26: =R26*O26*V4/Y4 -> 0 | W26: =S26*O26*W4/Y4 -> 0 | X26: =T26*O26*X4/Y4 -> 0 | Y26: =V26+W26+X26 -> 0
D27: UHF TRx | E27: NanoCom AX100 | G27: GOMSPACE | I27: Rx | J27: 3.3 | K27: 0.045 | L27: 0.055 | M27: 0.12 | N27: =J27*K27 -> 0.1485 | O27: =L27*J27 -> 0.1815 | P27: =M27*J27 -> 0.396 | R27: 1 | S27: 1 | T27: 1 | V27: =R27*O27*V4/Y4 -> 0.11682647 | W27: =S27*O27*W4/Y4 -> 0.043540572 | X27: =T27*P27*X4/Y4 -> 0.046108278 | Y27: =V27+W27+X27 -> 0.20647532
F28: extreme temperature : -30℃~+85℃ | I28: Tx | J28: 3.3 | K28: 0.6 | L28: 0.8 | M28: 1 | N28: =J28*K28 -> 1.98 | O28: =L28*J28 -> 2.64 | P28: =M28*J28 -> 3.3 | R28: =100%-R27 -> 0 | S28: =100%-S27 -> 0 | T28: =100%-T27 -> 0 | V28: =R28*O28*V4/Y4 -> 0 | W28: =S28*O28*W4/Y4 -> 0 | X28: =T28*P28*X4/Y4 -> 0 | Y28: =V28+W28+X28 -> 0
F29: Transmitter with adjustable 24 to 30 dBm output power
D30: S-band ANT | E30: PULSAR-SANT | G30: AAC Clyde space | H30: 5V | J30: 5 | L30: 0 | O30: 0 | R30: 0 | S30: 0 | T30: 1 | V30: =R30*O30*V4/Y4 -> 0 | W30: =S30*O30*W4/Y4 -> 0 | X30: =T30*O30*X4/Y4 -> 0 | Y30: =V30+W30+X30 -> 0
D31: S-band Tx | E31: PULSAR-STX | I31: Idle(OFF) | J31: 5 | L31: =O31/5 -> 0.122 | O31: 0.61 | R31: 0 | S31: 0 | T31: 0 | V31: =R31*O31*V4/Y4 -> 0 | W31: =S31*O31*W4/Y4 -> 0 | X31: =T31*O31*X4/Y4 -> 0 | Y31: =V31+W31+X31 -> 0
I32: 24dBM RF | J32: 5 | L32: =O32/5 -> 0.54 | O32: 2.7 | R32: 0 | S32: 0 | T32: 0 | V32: =R32*O32*V4/Y4 -> 0 | W32: =S32*O32*W4/Y4 -> 0 | X32: =T32*O32*X4/Y4 -> 0 | Y32: =V32+W32+X32 -> 0
I33: 30dBM RF | J33: 5 | L33: =O33/5 -> 0.92 | M33: =P33/5 -> 1 | O33: 4.6 | P33: 5 | R33: 0 | S33: 0 | T33: 1 | V33: =R33*O33*V4/Y4 -> 0 | W33: =S33*O33*W4/Y4 -> 0 | X33: =T33*P33*X4/Y4 -> 0.58217523 | Y33: =V33+W33+X33 -> 0.58217523
B34: PAYS | C34: PAYS | D34: PAYS | E34: 레이저 감지기 | G34: Ophir | H34: 5V(2) | J34: 5 | L34: =O34/J34 -> 0.2 | O34: 1 | R34: 0 | S34: 0 | T34: 0 | V34: =R34*O34*V4/Y4 -> 0 | W34: =S34*O34*W4/Y4 -> 0 | X34: =T34*O34*X4/Y4 -> 0 | Y34: =V34+W34+X34 -> 0
C35: PAYR | D35: PAYR | E35: 박막전개장치 | G35: in-house | H35: 5V(1) | J35: 5 | L35: =O35/J35 -> 0.2 | O35: 1 | R35: 0 | S35: 0 | T35: 0 | V35: =R35*O35*V4/Y4 -> 0 | W35: =S35*O35*W4/Y4 -> 0 | X35: =T35*O35*X4/Y4 -> 0 | Y35: =V35+W35+X35 -> 0
D36: PAYR | E36: 박막전개장치 | G36: in-house | H36: 3.3V(3) | J36: 3.3 | M36: =P36/J36 -> 0.60606061 | P36: 2 | R36: 0 | S36: 0 | T36: 0 | V36: =R36*O36*V4/Y4 -> 0 | W36: =S36*O36*W4/Y4 -> 0 | X36: =T36*P36*X4/Y4 -> 0 | Y36: =V36+W36+X36 -> 0
C37: PAYC | D37: PAYC | E37: Nanocam C1U | F37: Peak Power = 3.6V x 500mA @ Max | G37: GOMSPACE | H37: 3.3V(2) | J37: 3.3 | K37: =N37/J37 -> 0.11515152 | L37: =O37/J37 -> 0.24242424 | M37: =P37/J37 -> 0.54545455 | N37: 0.38 | O37: 0.8 | P37: 1.8 | R37: 0 | S37: 0 | T37: 0 | V37: =R37*O37*V4/Y4 -> 0 | W37: =S37*O37*W4/Y4 -> 0 | X37: =T37*P37*X4/Y4 -> 0 | Y37: =V37+W37+X37 -> 0
U38: total power consumption | V38: =SUM(V5:V37)/0.9 -> 2.1075745 | W38: =SUM(W5:W37)/0.9 -> 0.78548125 | X38: =SUM(X5:X37)/0.9 -> 1.601159 | Y38: =SUM(Y5:Y37)/0.9 -> 4.4942147 | Z38: W | AA38: worst case
U39: Generated Energy(orbit average) | V39: =1.135*20*V4/3600 -> 23.041233 | W39: 0 | X39: 0 | Y39: =V39+W39+X39 -> 23.041233 | Z39: Wh
U40: Required Energy (orbit average) | V40: =V38*Y4/3600 -> 3.323519 | W40: =W38*Y4/3600 -> 1.238657 | X40: =X38*Y4/3600 -> 2.5249321 | Y40: =V40+W40+X40 -> 7.0871081 | Z40: Wh
U41: Power Margin Value | V41: =Y39-Y40 -> 15.954124 | Y41: =V41+W41+X41 -> 15.954124 | Z41: Wh
U42: Power Margin | V42: =100*(Y39/Y40-1) -> 225.11473 | Y42: =V42+W42+X42 -> 225.11473 | Z42: %
U43: Residual/Generation | V43: =V41/$V$39*100 -> 69.241628 | Y43: =V43+W43+X43 -> 69.241628 | Z43: % | AA43: >40%
...

Sheet ③ 2주기(S-band)
B2: Subsystem | C2: Module | E2: Product | F2: Note | G2: Manufacturer | H2: channel | I2: Mode | J2: Voltage Input | K2: Current(A) | N2: Power | R2: Duty(%) | U2: Consumption Power (W) | AB2: Note
K3: Idle | L3: Nominal | M3: Peak | N3: Idel | O3: Nominal | P3: Peak | Q3: Mode | R3: Stand-by(D) | S3: Stand-by(N) | T3: S-band COM | V3: Stand-by(D) | W3: Stand-by(N) | X3: S-band COM | Y3: total | AB3: Orbit period | AC3: =parameter!C8 -> 5676.9849
Q4: Time | R4: =AC6-AC4 -> 2973.1162 | S4: =AC7 -> 2022.8687 | T4: =AC4 -> 681 | V4: =AC6-AC4 -> 2973.1162 | W4: =AC7 -> 2022.8687 | X4: =AC4 -> 681 | Y4: =V4+W4+X4 -> 5676.9849 | AB4: Missiond period | AC4: 681
B5: EPS | D5: Battery | E5: Optimus-40 | F5: When heater active | G5: AAC Clyde space | O5: 0.8 | R5: 1 | S5: 1 | T5: 1 | V5: =R5*O5*V4/Y4 -> 0.41897116 | W5: =O5*S5*W4/Y4 -> 0.28506241 | X5: =O5*T5*X4/Y4 -> 0.095966435 | Y5: =V5+W5+X5 -> 0.8 | AB5: S-band period | AC5: 661
D6: PCDU | E6: Starbuck-Nano-Plus | R6: 1 | S6: 1 | T6: 1 | V6: =R6*O6*V4/Y4 -> 0 | W6: =O6*S6*W4/Y4 -> 0 | X6: =O6*T6*X4/Y4 -> 0 | Y6: =V6+W6+X6 -> 0 | AB6: sunlight | AC6: =parameter!C10 -> 3654.1162
C7: MSP | D7: Solar cell | E7: 3G30C-Advanced | G7: AZURSPACE | R7: 1 | S7: 1 | T7: 1 | V7: =R7*O7*V4/Y4 -> 0 | W7: =O7*S7*W4/Y4 -> 0 | X7: =O7*T7*X4/Y4 -> 0 | Y7: =V7+W7+X7 -> 0 | AB7: Eclipse | AC7: =parameter!C11 -> 2022.8687
B8: GNC(ADCS) | D8: CSS(with Solar panel) | E8: Coarse Sun Sensors | G8: GOMSPACE | H8: 3.3V | J8: 3.3 | L8: 0.00093 | O8: =J8*L8 -> 0.003069 | R8: 1 | S8: 1 | T8: 1 | V8: =R8*O8*V4/Y4 -> 0.0016072781 | W8: =O8*S8*W4/Y4 -> 0.0010935707 | X8: =O8*T8*X4/Y4 -> 0.00036815124 | Y8: =V8+W8+X8 -> 0.003069 | AB8: solar panel efficiency | AC8: 0.3
C9: ADCS Module | D9: CSS(TBD) | E9: Coarse Sun Sensors | F9: Coarse Sun Sensor x 10 | G9: CUBESPACE | J9: 3.3 | L9: =O9/J9 -> 0.0015151515 | O9: 0.005 | R9: 1 | S9: 1 | T9: 1 | V9: =R9*O9*V4/Y4 -> 0.0026185697 | W9: =O9*S9*W4/Y4 -> 0.00178164 | X9: =O9*T9*X4/Y4 -> 0.00059979022 | Y9: =V9+W9+X9 -> 0.005 | AB9: Emppt | AC9: 0.6
D10: CUBECOM | E10: Cubecomputer | J10: 3.3 | L10: =O10/J10 -> 0.036363636 | M10: =P10/J10 -> 0.060606061 | O10: 0.12 | P10: 0.2 | R10: 1 | S10: 1 | T10: 1 | V10: =R10*O10*V4/Y4 -> 0.062845674 | W10: =O10*S10*W4/Y4 -> 0.042759361 | X10: =P10*T10*X4/Y4 -> 0.023991609 | Y10: =V10+W10+X10 -> 0.12959664 | AB10: Etmp | AC10: 0.8
D11: FSS | E11: Cubesense V3 x 2 | J11: 3.3 | L11: =O11/J11 -> 0.060606061 | M11: =P11/J11 -> 0.12121212 | O11: 0.2 | P11: 0.4 | R11: 1 | S11: 1 | T11: 1 | V11: =R11*O11*V4/Y4 -> 0.10474279 | W11: =O11*S11*W4/Y4 -> 0.071265601 | X11: =P11*T11*X4/Y4 -> 0.047983217 | Y11: =V11+W11+X11 -> 0.22399161 | AB11: Eman | AC11: 0.8
E12: Cubecontrol | I12: Typ | J12: 3.3 | L12: =O12/J12 -> 0.060606061 | O12: 0.2 | R12: =100%-R13 -> 0 | S12: =100%-S13 -> 0 | T12: =100%-T13 -> 0 | V12: =R12*O12*V4/Y4 -> 0 | W12: =O12*S12*W4/Y4 -> 0 | X12: =T12*P12*X4/Y4 -> 0 | Y12: =V12+W12+X12 -> 0 | AB12: Depth of Discharge | AC12: 0.2
F13: Include Momentum Wheel | I13: Momentum wheel | J13: 3.3 | L13: =O13/J13 -> 0.086363636 | M13: =P13/J13 -> 0.13333333 | O13: 0.285 | P13: 0.44 | R13: =R16 -> 1 | S13: =S16 -> 1 | T13: =T16 -> 1 | V13: =R13*O13*V4/Y4 -> 0.14925848 | W13: =O13*S13*W4/Y4 -> 0.10155348 | X13: =P13*T13*X4/Y4 -> 0.052781539 | Y13: =V13+W13+X13 -> 0.3035935 | AB13: Conversion Efficiency | AC13: 0.9
D14: MMT | E14: CubeMag | F14: Deployable Magnetometer | I14: Typ | J14: 3.3 | L14: =O14/J14 -> 0.010606061 | O14: 0.035 | R14: 1 | S14: 1 | T14: 1 | V14: =R14*O14*V4/Y4 -> 0.018329988 | W14: =O14*S14*W4/Y4 -> 0.01247148 | X14: =T14*O14*X4/Y4 -> 0.0041985315 | Y14: =V14+W14+X14 -> 0.035 | AB14: required margin | AC14: 0.4
F15: Circuit activate for 5s (0.62Ax8V) | G15: CUBESPACE | H15: VBAT(1) | I15: Deployment mag | J15: 8 | L15: 0.62 | O15: =J15*L15 -> 4.96
D16: RWA | E16: Cube Wheel Medium x 3 | G16: CUBESPACE | H16: VBAT(2) | J16: 8.26 | K16: =0.065*3/J16 -> 0.023607748 | L16: =0.19*3/J16 -> 0.069007264 | M16: =2.3*3/J16 -> 0.83535109 | N16: 0.065 | O16: 0.19 | P16: 2.3 | R16: 1 | S16: 1 | T16: 1 | V16: =R16*O16*V4/Y4 -> 0.09950565 | W16: =O16*S16*W4/Y4 -> 0.067702321 | X16: =P16*T16*X4/Y4 -> 0.2759035 | Y16: =V16+W16+X16 -> 0.44311147
D19: MTQ | E19: CubeTorquers rod | F19: Small Rod x 2 | G19: CUBESPACE | H19: 5V | J19: 5 | L19: =0.07*2 -> 0.14 | M19: =0.167*2 -> 0.334 | O19: =L19*J19 -> 0.7 | P19: =M19*J19 -> 1.67 | R19: 0 | S19: 0 | T19: 1 | V19: =R19*O19*V4/Y4 -> 0 | W19: =S19*O19*W4/Y4 -> 0 | X19: =T19*O19*X4/Y4 -> 0.08397063 | Y19: =V19+W19+X19 -> 0.08397063
E20: CubeTorquers coil | F20: Coil x 1 | J20: 5 | L20: 0.064 | O20: =L20*J20 -> 0.32 | R20: 0 | S20: 0 | T20: 1 | V20: =R20*O20*V4/Y4 -> 0 | W20: =S20*O20*W4/Y4 -> 0 | X20: =T20*O20*X4/Y4 -> 0.038386574 | Y20: =V20+W20+X20 -> 0.038386574
D21: GPS ANT | E21: TW1829 | F21: Low Noise Amplifier | G21: TALLYSMAN | H21: 3.3V | J21: 3.3 | L21: =O21/J21 -> 0.0036363636 | O21: 0.012 | R21: 1 | S21: 1 | T21: 1 | V21: =R21*O21*V4/Y4 -> 0.0062845674 | W21: =S21*O21*W4/Y4 -> 0.0042759361 | X21: =T21*O21*X4/Y4 -> 0.0014394965 | Y21: =V21+W21+X21 -> 0.012
D22: GPS Rx | E22: OEM719 | G22: NovAtel | H22: 3.3V(1) | J22: 3.3 | L22: =O22/J22 -> 0.39393939 | O22: 1.3 | R22: 0.5 | S22: 0.5 | T22: 1 | V22: =R22*O22*V4/Y4 -> 0.34041407 | W22: =S22*O22*W4/Y4 -> 0.2316132 | X22: =T22*O22*X4/Y4 -> 0.15594546 | Y22: =V22+W22+X22 -> 0.72797273
B23: CNDH | D23: OBC | E23: HYVRID OBC | G23: NST | H23: 3.3V | J23: 3.3 | L23: =0.13 -> 0.13 | O23: =L23*J23 -> 0.429 | R23: 1 | S23: 1 | T23: 1 | V23: =R23*O23*V4/Y4 -> 0.22467328 | W23: =S23*O23*W4/Y4 -> 0.15286471 | X23: =T23*O23*X4/Y4 -> 0.051462001 | Y23: =V23+W23+X23 -> 0.429
B24: COMS | D24: UHF ANT | E24: Deployable Antenna System | G24: ISIS | H24: 3.3V | I24: stowed | J24: 3.3 | L24: 0.013 | O24: =L24*J24 -> 0.0429 | V24: =R24*O24*V4/Y4 -> 0 | W24: =S24*O24*W4/Y4 -> 0 | X24: =T24*O24*X4/Y4 -> 0 | Y24: =V24+W24+X24 -> 0
F25: Typical Deployment Duration < 3s | I25: deployed | J25: 3.3 | L25: 0.011 | O25: =L25*J25 -> 0.0363 | R25: 1 | S25: 1 | T25: 1 | V25: =R25*O25*V4/Y4 -> 0.019010816 | W25: =S25*O25*W4/Y4 -> 0.012934707 | X25: =T25*O25*X4/Y4 -> 0.004354477 | Y25: =V25+W25+X25 -> 0.0363
F26: During Deployment 2W Power Consumption | I26: deployment | J26: 3.3 | L26: 0.55 | O26: =L26*J26 -> 1.815 | V26: =R26*O26*V4/Y4 -> 0 | W26: =S26*O26*W4/Y4 -> 0 | X26: =T26*O26*X4/Y4 -> 0 | Y26: =V26+W26+X26 -> 0
D27: UHF TRx | E27: NanoCom AX100 | G27: GOMSPACE | I27: Rx | J27: 3.3 | K27: 0.045 | L27: 0.055 | M27: 0.12 | N27: =J27*K27 -> 0.1485 | O27: =L27*J27 -> 0.1815 | P27: =M27*J27 -> 0.396 | R27: 1 | S27: 1 | T27: 1 | V27: =R27*O27*V4/Y4 -> 0.095054082 | W27: =S27*O27*W4/Y4 -> 0.064673533 | X27: =T27*P27*X4/Y4 -> 0.047503385 | Y27: =V27+W27+X27 -> 0.207231
F28: extreme temperature : -30℃~+85℃ | I28: Tx | J28: 3.3 | K28: 0.6 | L28: 0.8 | M28: 1 | N28: =J28*K28 -> 1.98 | O28: =L28*J28 -> 2.64 | P28: =M28*J28 -> 3.3 | R28: =100%-R27 -> 0 | S28: =100%-S27 -> 0 | T28: =100%-T27 -> 0 | V28: =R28*O28*V4/Y4 -> 0 | W28: =S28*O28*W4/Y4 -> 0 | X28: =T28*P28*X4/Y4 -> 0 | Y28: =V28+W28+X28 -> 0
F29: Transmitter with adjustable 24 to 30 dBm output power
D30: S-band ANT | E30: PULSAR-SANT | G30: AAC Clyde space | H30: 5V | J30: 5 | L30: 0 | O30: 0 | R30: 0 | S30: 0 | T30: 1 | V30: =R30*O30*V4/Y4 -> 0 | W30: =S30*O30*W4/Y4 -> 0 | X30: =T30*O30*X4/Y4 -> 0 | Y30: =V30+W30+X30 -> 0
D31: S-band Tx | E31: PULSAR-STX | I31: Idle(OFF) | J31: 5 | L31: =O31/5 -> 0.122 | O31: 0.61 | R31: 0 | S31: 0 | T31: 0 | V31: =R31*O31*V4/Y4 -> 0 | W31: =S31*O31*W4/Y4 -> 0 | X31: =T31*O31*X4/Y4 -> 0 | Y31: =V31+W31+X31 -> 0
I32: 24dBM RF | J32: 5 | L32: =O32/5 -> 0.54 | O32: 2.7 | R32: 0 | S32: 0 | T32: 0 | V32: =R32*O32*V4/Y4 -> 0 | W32: =S32*O32*W4/Y4 -> 0 | X32: =T32*O32*X4/Y4 -> 0 | Y32: =V32+W32+X32 -> 0
I33: 30dBM RF | J33: 5 | L33: =O33/5 -> 0.92 | M33: =P33/5 -> 1 | O33: 4.6 | P33: 5 | R33: 0 | S33: 0 | T33: 1 | V33: =R33*O33*V4/Y4 -> 0 | W33: =S33*O33*W4/Y4 -> 0 | X33: =T33*P33*X4/Y4 -> 0.59979022 | Y33: =V33+W33+X33 -> 0.59979022
B34: PAYS | C34: PAYS | D34: PAYS | E34: 레이저 감지기 | G34: Ophir | H34: 5V(2) | J34: 5 | L34: =O34/J34 -> 0.2 | O34: 1 | R34: 0 | S34: 0 | T34: 0 | V34: =R34*O34*V4/Y4 -> 0 | W34: =S34*O34*W4/Y4 -> 0 | X34: =T34*O34*X4/Y4 -> 0 | Y34: =V34+W34+X34 -> 0
C35: PAYR | D35: PAYR | E35: 박막전개장치 | G35: in-house | H35: 5V(1) | J35: 5 | L35: =O35/J35 -> 0.2 | O35: 1 | R35: 0 | S35: 0 | T35: 0 | V35: =R35*O35*V4/Y4 -> 0 | W35: =S35*O35*W4/Y4 -> 0 | X35: =T35*O35*X4/Y4 -> 0 | Y35: =V35+W35+X35 -> 0
D36: PAYR | E36: 박막전개장치 | G36: in-house | H36: 3.3V(3) | J36: 3.3 | M36: =P36/J36 -> 0.60606061 | P36: 2 | R36: 0 | S36: 0 | T36: 0 | V36: =R36*O36*V4/Y4 -> 0 | W36: =S36*O36*W4/Y4 -> 0 | X36: =T36*P36*X4/Y4 -> 0 | Y36: =V36+W36+X36 -> 0
C37: PAYC | D37: PAYC | E37: Nanocam C1U | F37: Peak Power = 3.6V x 500mA @ Max | G37: GOMSPACE | H37: 3.3V(2) | J37: 3.3 | K37: =N37/J37 -> 0.11515152 | L37: =O37/J37 -> 0.24242424 | M37: =P37/J37 -> 0.54545455 | N37: 0.38 | O37: 0.8 | P37: 1.8 | R37: 0 | S37: 0 | T37: 0 | V37: =R37*O37*V4/Y4 -> 0 | W37: =S37*O37*W4/Y4 -> 0 | X37: =T37*P37*X4/Y4 -> 0 | Y37: =V37+W37+X37 -> 0
U38: total power consumption | V38: =SUM(V5:V37)/0.9 -> 1.714796 | W38: =SUM(W5:W37)/0.9 -> 1.1667244 | X38: =SUM(X5:X37)/0.9 -> 1.6496056 | Y38: =SUM(Y5:Y37)/0.9 -> 4.531126 | Z38: W | AA38: worst case
U39: Generated Energy(orbit average) | V39: =1.135*20*V4/3600 -> 18.747149 | W39: 0 | X39: 0 | Y39: =V39+W39+X39 -> 18.747149 | Z39: Wh
U40: Required Energy (orbit average) | V40: =V38*Y4/3600 -> 2.7041308 | W40: =W38*Y4/3600 -> 1.8398547 | X40: =X38*Y4/3600 -> 2.6013294 | Y40: =V40+W40+X40 -> 7.1453149 | Z40: Wh
U41: Power Margin Value | V41: =Y39-Y40 -> 11.601834 | Y41: =V41+W41+X41 -> 11.601834 | Z41: Wh
U42: Power Margin | V42: =100*(Y39/Y40-1) -> 162.36981 | Y42: =V42+W42+X42 -> 162.36981 | Z42: %
U43: Residual/Generation | V43: =V41/$V$39*100 -> 61.885859 | Y43: =V43+W43+X43 -> 61.885859 | Z43: % | AA43: >40%
...

Sheet ④ 그 외
B2: Subsystem | C2: Module | E2: Product | F2: Note | G2: Manufacturer | H2: channel | I2: Mode | J2: Voltage Input | K2: Current(A) | N2: Power | R2: Duty(%) | T2: Consumption Power (W) | Z2: Note
K3: Idle | L3: Nominal | M3: Peak | N3: Idel | O3: Nominal | P3: Peak | Q3: Mode | R3: Stand-by(D) | S3: Stand-by(N) | U3: Stand-by(D) | V3: Stand-by(N) | W3: total | Z3: Orbit period | AA3: =parameter!C8 -> 5676.9849
Q4: Time | R4: =AA6 -> 3654.1162 | S4: =AA7 -> 2022.8687 | U4: =AA6 -> 3654.1162 | V4: =AA7 -> 2022.8687 | W4: =U4+V4 -> 5676.9849 | Z4: Missiond period | AA4: 681
B5: EPS | D5: Battery | E5: Optimus-40 | F5: When heater active | G5: AAC Clyde space | O5: 0.8 | R5: 0 | S5: 1 | U5: =R5*O5*U4/W4 -> 0 | V5: =O5*S5*V4/W4 -> 0.28506241 | W5: =U5+V5 -> 0.28506241 | Z5: S-band period | AA5: 661
D6: PCDU | E6: Starbuck-Nano-Plus | R6: 1 | S6: 1 | U6: =R6*O6*U4/W4 -> 0 | V6: =O6*S6*V4/W4 -> 0 | W6: =U6+V6 -> 0 | Z6: sunlight | AA6: =parameter!C10 -> 3654.1162
C7: MSP | D7: Solar cell | E7: 3G30C-Advanced | G7: AZURSPACE | R7: 1 | S7: 1 | U7: =R7*O7*U4/W4 -> 0 | V7: =O7*S7*V4/W4 -> 0 | W7: =U7+V7 -> 0 | Z7: Eclipse | AA7: =parameter!C11 -> 2022.8687
B8: GNC(ADCS) | D8: CSS(with Solar panel) | E8: Coarse Sun Sensors | G8: GOMSPACE | H8: 3.3V | J8: 3.3 | L8: 0.00093 | O8: =J8*L8 -> 0.003069 | R8: 1 | S8: 1 | U8: =R8*O8*U4/W4 -> 0.0019754293 | V8: =O8*S8*V4/W4 -> 0.0010935707 | W8: =U8+V8 -> 0.003069 | Z8: solar panel efficiency | AA8: 0.3
C9: ADCS Module | D9: CSS(TBD) | E9: Coarse Sun Sensors | F9: Coarse Sun Sensor x 10 | G9: CUBESPACE | J9: 3.3 | L9: =O9/J9 -> 0.0015151515 | O9: 0.005 | R9: 1 | S9: 1 | U9: =R9*O9*U4/W4 -> 0.00321836 | V9: =O9*S9*V4/W4 -> 0.00178164 | W9: =U9+V9 -> 0.005 | Z9: Emppt | AA9: 0.6
D10: CUBECOM | E10: Cubecomputer | J10: 3.3 | L10: =O10/J10 -> 0.036363636 | M10: =P10/J10 -> 0.060606061 | O10: 0.12 | P10: 0.2 | R10: 1 | S10: 1 | U10: =R10*O10*U4/W4 -> 0.077240639 | V10: =O10*S10*V4/W4 -> 0.042759361 | W10: =U10+V10 -> 0.12 | Z10: Etmp | AA10: 0.8
D11: FSS | E11: Cubesense V3 x 2 | J11: 3.3 | L11: =O11/J11 -> 0.060606061 | M11: =P11/J11 -> 0.12121212 | O11: 0.2 | P11: 0.4 | R11: 1 | S11: 1 | U11: =R11*O11*U4/W4 -> 0.1287344 | V11: =O11*S11*V4/W4 -> 0.071265601 | W11: =U11+V11 -> 0.2 | Z11: Eman | AA11: 0.8
E12: Cubecontrol | I12: Typ | J12: 3.3 | L12: =O12/J12 -> 0.060606061 | O12: 0.2 | R12: 0 | S12: 0 | U12: =R12*O12*U4/W4 -> 0 | V12: =O12*S12*V4/W4 -> 0 | W12: =U12+V12 -> 0 | Z12: Depth of Discharge | AA12: 0.2
F13: Include Momentum Wheel | I13: Momentum wheel | J13: 3.3 | L13: =O13/J13 -> 0.086363636 | M13: =P13/J13 -> 0.13333333 | O13: 0.285 | P13: 0.44 | R13: 1 | S13: 1 | U13: =P13*R13 -> 0.44 | V13: =P13*S13 -> 0.44 | W13: =U13+V13 -> 0.88 | Z13: Conversion Efficiency | AA13: 0.9
D14: MMT | E14: CubeMag | F14: Deployable Magnetometer | I14: Typ | J14: 3.3 | L14: =O14/J14 -> 0.010606061 | O14: 0.035 | R14: 1 | S14: 1 | U14: =R14*O14*U4/W4 -> 0.02252852 | V14: =O14*S14*V4/W4 -> 0.01247148 | W14: =U14+V14 -> 0.035 | Z14: required margin | AA14: 0.4
F15: Circuit activate for 5s (0.62Ax8V) | G15: CUBESPACE | H15: VBAT(1) | I15: Deployment mag | J15: 8 | L15: 0.62 | O15: =J15*L15 -> 4.96 | W15: =U15+V15 -> 0
D16: RWA | E16: Cube Wheel Medium x 3 | G16: CUBESPACE | H16: VBAT(2) | J16: 8.26 | K16: =0.065*3/J16 -> 0.023607748 | L16: =0.19*3/J16 -> 0.069007264 | M16: =2.3*3/J16 -> 0.83535109 | N16: =0.065*3 -> 0.195 | O16: =0.19*3 -> 0.57 | P16: =2.3*3 -> 6.9 | R16: 1 | S16: 1 | U16: =R16*P16*U4/W4 -> 4.4413368 | V16: =P16*S16*V4/W4 -> 2.4586632 | W16: =U16+V16 -> 6.9
D19: MTQ | E19: CubeTorquers rod | F19: Small Rod x 2 | G19: CUBESPACE | H19: 5V | J19: 5 | L19: =0.07*2 -> 0.14 | M19: =0.167*2 -> 0.334 | O19: =L19*J19 -> 0.7 | P19: =M19*J19 -> 1.67 | R19: 0 | S19: 0 | U19: =R19*O19*U4/W4 -> 0 | V19: =S19*O19*V4/W4 -> 0 | W19: =U19+V19 -> 0
E20: CubeTorquers coil | F20: Coil x 1 | J20: 5 | L20: 0.064 | O20: =L20*J20 -> 0.32 | R20: 0 | S20: 0 | U20: =R20*O20*U4/W4 -> 0 | V20: =S20*O20*V4/W4 -> 0 | W20: =U20+V20 -> 0
D21: GPS ANT | E21: TW1829 | F21: Low Noise Amplifier | G21: TALLYSMAN | H21: 3.3V | J21: 3.3 | L21: =O21/J21 -> 0.0036363636 | O21: 0.012 | R21: 1 | S21: 1 | U21: =R21*O21*U4/W4 -> 0.0077240639 | V21: =S21*O21*V4/W4 -> 0.0042759361 | W21: =U21+V21 -> 0.012
D22: GPS Rx | E22: OEM719 | G22: NovAtel | H22: 3.3V(1) | J22: 3.3 | L22: =O22/J22 -> 0.39393939 | O22: 1.3 | R22: 1 | S22: 1 | U22: =R22*O22*U4/W4 -> 0.83677359 | V22: =S22*O22*V4/W4 -> 0.46322641 | W22: =U22+V22 -> 1.3
B23: CNDH | D23: OBC | E23: HYVRID OBC | G23: NST | H23: 3.3V | J23: 3.3 | L23: =0.13 -> 0.13 | O23: =L23*J23 -> 0.429 | R23: 1 | S23: 1 | U23: =R23*O23*U4/W4 -> 0.27613529 | V23: =S23*O23*V4/W4 -> 0.15286471 | W23: =U23+V23 -> 0.429
B24: COMS | D24: UHF ANT | E24: Deployable Antenna System | G24: ISIS | H24: 3.3V | I24: stowed | J24: 3.3 | L24: 0.013 | O24: =L24*J24 -> 0.0429 | U24: =R24*O24*U4/W4 -> 0 | V24: =S24*O24*V4/W4 -> 0 | W24: =U24+V24 -> 0
F25: Typical Deployment Duration < 3s | I25: deployed | J25: 3.3 | L25: 0.011 | O25: =L25*J25 -> 0.0363 | R25: 1 | S25: 1 | U25: =R25*O25*U4/W4 -> 0.023365293 | V25: =S25*O25*V4/W4 -> 0.012934707 | W25: =U25+V25 -> 0.0363
F26: During Deployment 2W Power Consumption | I26: deployment | J26: 3.3 | L26: 0.55 | O26: =L26*J26 -> 1.815 | U26: =R26*O26*U4/W4 -> 0 | V26: =S26*O26*V4/W4 -> 0 | W26: =U26+V26 -> 0
D27: UHF TRx | E27: NanoCom AX100 | G27: GOMSPACE | I27: Rx | J27: 3.3 | K27: 0.045 | L27: 0.055 | M27: 0.12 | N27: =J27*K27 -> 0.1485 | O27: =L27*J27 -> 0.1815 | P27: =M27*J27 -> 0.396 | R27: 0.9 | S27: 0.9 | U27: =R27*O27*U4/W4 -> 0.10514382 | V27: =S27*O27*V4/W4 -> 0.05820618 | W27: =U27+V27 -> 0.16335
F28: extreme temperature : -30℃~+85℃ | I28: Tx | J28: 3.3 | K28: 0.6 | L28: 0.8 | M28: 1 | N28: =J28*K28 -> 1.98 | O28: =L28*J28 -> 2.64 | P28: =M28*J28 -> 3.3 | R28: =100%-R27 -> 0.1 | S28: =100%-S27 -> 0.1 | U28: =R28*O28*U4/W4 -> 0.16992941 | V28: =S28*O28*V4/W4 -> 0.094070594 | W28: =U28+V28 -> 0.264
F29: Transmitter with adjustable 24 to 30 dBm output power
D30: S-band ANT | E30: PULSAR-SANT | G30: AAC Clyde space | H30: 5V | J30: 5 | L30: 0 | O30: 0 | R30: 0 | S30: 0 | U30: =R30*O30*U4/W4 -> 0 | V30: =S30*O30*V4/W4 -> 0 | W30: =U30+V30 -> 0
D31: S-band Tx | E31: PULSAR-STX | I31: Idle(OFF) | J31: 5 | L31: =O31/5 -> 0.122 | O31: 0.61 | R31: 0 | S31: 0 | U31: =R31*O31*U4/W4 -> 0 | V31: =S31*O31*V4/W4 -> 0 | W31: =U31+V31 -> 0
I32: 24dBM RF | J32: 5 | L32: =O32/5 -> 0.54 | O32: 2.7 | R32: 0 | S32: 0 | U32: =R32*O32*U4/W4 -> 0 | V32: =S32*O32*V4/W4 -> 0 | W32: =U32+V32 -> 0
I33: 30dBM RF | J33: 5 | L33: =O33/5 -> 0.92 | M33: =P33/5 -> 1 | O33: 4.6 | P33: 5 | R33: 0 | S33: 0 | U33: =R33*O33*U4/W4 -> 0 | V33: =S33*O33*V4/W4 -> 0 | W33: =U33+V33 -> 0
B34: PAYS | C34: PAYS | D34: PAYS | E34: 레이저 감지기 | G34: Ophir | H34: 5V(2) | J34: 5 | L34: =O34/J34 -> 0.2 | O34: 1 | R34: 0 | S34: 0 | U34: =R34*O34*U4/W4 -> 0 | V34: =S34*O34*V4/W4 -> 0 | W34: =U34+V34 -> 0
C35: PAYR | D35: PAYR | E35: 박막전개장치 | G35: in-house | H35: 5V(1) | J35: 5 | L35: =O35/J35 -> 0.2 | O35: 1 | R35: 0 | S35: 0 | U35: =R35*O35*U4/W4 -> 0 | V35: =S35*O35*V4/W4 -> 0 | W35: =U35+V35 -> 0
D36: PAYR | E36: 박막전개장치 | G36: in-house | H36: 3.3V(3) | J36: 3.3 | M36: =P36/J36 -> 0.60606061 | P36: 2 | R36: 0 | S36: 0 | U36: =R36*O36*U4/W4 -> 0 | V36: =S36*O36*V4/W4 -> 0 | W36: =U36+V36 -> 0
C37: PAYC | D37: PAYC | E37: Nanocam C1U | F37: Peak Power = 3.6V x 500mA @ Max | G37: GOMSPACE | H37: 3.3V(2) | J37: 3.3 | K37: =N37/J37 -> 0.11515152 | L37: =O37/J37 -> 0.24242424 | M37: =P37/J37 -> 0.54545455 | N37: 0.38 | O37: 0.8 | P37: 1.8 | R37: 0 | S37: 0 | U37: =R37*O37*U4/W4 -> 0 | V37: =S37*O37*V4/W4 -> 0 | W37: =U37+V37 -> 0
T38: total power consumption | U38: =SUM(U5:U37)/0.9 -> 7.2601173 | V38: =SUM(V5:V37)/0.9 -> 4.5540843 | W38: =SUM(W5:W37)/0.9 -> 11.814202 | X38: W | Y38: worst case
T39: Generated Energy(orbit average) | U39: =1.135*20*R4/3600 -> 23.041233 | V39: 0 | W39: =U39+V39 -> 23.041233 | X39: Wh
T40: Required Energy (orbit average) | U40: =U38*W4/3600 -> 11.448771 | V40: =V38*W4/3600 -> 7.1815188 | W40: =U40+V40 -> 18.63029 | X40: Wh
T41: Power Margin Value | U41: =W39-W40 -> 4.4109426 | W41: =U41+V41 -> 4.4109426 | X41: Wh
T42: Power Margin | U42: =100*(W39/W40-1) -> 23.676189 | W42: =U42+V42 -> 23.676189 | X42: %
T43: Residual/Generation | U43: =U41/$U$39*100 -> 19.143692 | W43: =U43+V43 -> 19.143692 | X43: % | Y43: >40%
...

Sheet commissioning
B2: Subsystem | C2: Module | E2: Product | F2: Note | G2: Manufacturer | H2: channel | I2: Mode | J2: Voltage Input | K2: Current(A) | N2: Power | R2: Duty(%) | S2: Consumption Power (W) | W2: Note
K3: Idle | L3: Nominal | M3: Peak | N3: Idel | O3: Nominal | P3: Peak | Q3: Mode | R3: Commissioning | T3: Commissioning | W3: Orbit period | X3: =parameter!C8 -> 5676.9849
Q4: Time | R4: =X3 -> 5676.9849 | T4: =X3 -> 5676.9849 | W4: Missiond period | X4: 681
B5: EPS | D5: Battery | E5: Optimus-40 | F5: When heater active | G5: AAC Clyde space | O5: 0.8 | R5: 1 | T5: =R5*O5 -> 0.8 | W5: S-band period | X5: 661
D6: PCDU | E6: Starbuck-Nano-Plus | R6: 1 | T6: =R6*O6 -> 0 | W6: sunlight | X6: =parameter!C10 -> 3654.1162
C7: MSP | D7: Solar cell | E7: 3G30C-Advanced | G7: AZURSPACE | R7: 1 | T7: =R7*O7 -> 0 | W7: Eclipse | X7: =parameter!C11 -> 2022.8687
B8: GNC(ADCS) | D8: CSS(with Solar panel) | E8: Coarse Sun Sensors | G8: GOMSPACE | H8: 3.3V | J8: 3.3 | L8: 0.00093 | O8: =J8*L8 -> 0.003069 | R8: 1 | T8: =R8*O8 -> 0.003069 | W8: solar panel efficiency | X8: 0.3
C9: ADCS Module | D9: CSS(TBD) | E9: Coarse Sun Sensors | F9: Coarse Sun Sensor x 10 | G9: CUBESPACE | J9: 3.3 | L9: =O9/J9 -> 0.0015151515 | O9: 0.005 | R9: 1 | T9: =R9*O9 -> 0.005 | W9: Emppt | X9: 0.6
D10: CUBECOM | E10: Cubecomputer | J10: 3.3 | L10: =O10/J10 -> 0.036363636 | M10: =P10/J10 -> 0.060606061 | O10: 0.12 | P10: 0.2 | R10: 1 | T10: =R10*P10 -> 0.2 | W10: Etmp | X10: 0.8
D11: FSS | E11: Cubesense V3 x 2 | J11: 3.3 | L11: =O11/J11 -> 0.060606061 | M11: =P11/J11 -> 0.12121212 | O11: 0.2 | P11: 0.4 | R11: 1 | T11: =R11*P11 -> 0.4 | W11: Eman | X11: 0.8
E12: Cubecontrol | I12: Typ | J12: 3.3 | L12: =O12/J12 -> 0.060606061 | O12: 0.2 | R12: =100%-R13 -> 0 | W12: Depth of Discharge | X12: 0.2
F13: Include Momentum Wheel | I13: Momentum wheel | J13: 3.3 | L13: =O13/J13 -> 0.086363636 | M13: =P13/J13 -> 0.13333333 | O13: 0.285 | P13: 0.44 | R13: 1 | T13: =R13*O13 -> 0.285 | W13: Conversion Efficiency | X13: 0.9
D14: MMT | E14: CubeMag | F14: Deployable Magnetometer | I14: Typ | J14: 3.3 | L14: =O14/J14 -> 0.010606061 | O14: 0.035 | R14: 1 | T14: =R14*O14 -> 0.035 | W14: required margin | X14: 0.4
F15: Circuit activate for 5s (0.62Ax8V) | G15: CUBESPACE | H15: VBAT(1) | I15: Deployment mag | J15: 8 | L15: 0.62 | O15: =J15*L15 -> 4.96 | R15: 1 | T15: =R15*O15 -> 4.96
D16: RWA | E16: Cube Wheel Medium x 3 | G16: CUBESPACE | H16: VBAT(2) | J16: 8.26 | K16: =0.065*3/J16 -> 0.023607748 | L16: =0.19*3/J16 -> 0.069007264 | M16: =2.3*3/J16 -> 0.83535109 | N16: 0.065 | O16: 0.19 | P16: 2.3 | R16: 1 | T16: =O16*P16 -> 0.437
D19: MTQ | E19: CubeTorquers rod | F19: Small Rod x 2 | G19: CUBESPACE | H19: 5V | J19: 5 | L19: =0.07*2 -> 0.14 | M19: =0.167*2 -> 0.334 | O19: =L19*J19 -> 0.7 | P19: =M19*J19 -> 1.67 | R19: 1 | T19: =R19*P19 -> 1.67
E20: CubeTorquers coil | F20: Coil x 1 | J20: 5 | L20: 0.064 | O20: =L20*J20 -> 0.32 | R20: 1 | T20: =R20*O20 -> 0.32
D21: GPS ANT | E21: TW1829 | F21: Low Noise Amplifier | G21: TALLYSMAN | H21: 3.3V | J21: 3.3 | L21: =O21/J21 -> 0.0036363636 | O21: 0.012 | R21: 1 | T21: =R21*O21 -> 0.012
D22: GPS Rx | E22: OEM719 | G22: NovAtel | H22: 3.3V(1) | J22: 3.3 | L22: =O22/J22 -> 0.39393939 | O22: 1.3 | R22: 0 | T22: =R22*O22 -> 0
B23: CNDH | D23: OBC | E23: HYVRID OBC | G23: NST | H23: 3.3V | J23: 3.3 | L23: =0.13 -> 0.13 | O23: =L23*J23 -> 0.429 | R23: 1 | T23: =R23*O23 -> 0.429
B24: COMS | D24: UHF ANT | E24: Deployable Antenna System | G24: ISIS | H24: 3.3V | I24: stowed | J24: 3.3 | L24: 0.013 | O24: =L24*J24 -> 0.0429 | T24: =R24*O24 -> 0
F25: Typical Deployment Duration < 3s | I25: deployed | J25: 3.3 | L25: 0.011 | O25: =L25*J25 -> 0.0363
F26: During Deployment 2W Power Consumption | I26: deployment | J26: 3.3 | L26: 0.55 | O26: =L26*J26 -> 1.815 | R26: 1 | T26: =R26*O26 -> 1.815
D27: UHF TRx | E27: NanoCom AX100 | G27: GOMSPACE | I27: Rx | J27: 3.3 | K27: 0.045 | L27: 0.055 | M27: 0.12 | N27: =J27*K27 -> 0.1485 | O27: =L27*J27 -> 0.1815 | P27: =M27*J27 -> 0.396 | R27: 1 | T27: =R27*O27 -> 0.1815
F28: extreme temperature : -30℃~+85℃ | I28: Tx | J28: 3.3 | K28: 0.6 | L28: 0.8 | M28: 1 | N28: =J28*K28 -> 1.98 | O28: =L28*J28 -> 2.64 | P28: =M28*J28 -> 3.3 | R28: =100%-R27 -> 0 | T28: =R28*O28 -> 0
F29: Transmitter with adjustable 24 to 30 dBm output power
D30: S-band ANT | E30: PULSAR-SANT | G30: AAC Clyde space | H30: 5V | J30: 5 | L30: 0 | O30: 0 | R30: 0 | T30: =R30*O30 -> 0
D31: S-band Tx | E31: PULSAR-STX | I31: Idle(OFF) | J31: 5 | L31: =O31/5 -> 0.122 | O31: 0.61 | R31: 0 | T31: =R31*O31 -> 0
I32: 24dBM RF | J32: 5 | L32: =O32/5 -> 0.54 | O32: 2.7 | R32: 0 | T32: =R32*O32 -> 0
I33: 30dBM RF | J33: 5 | L33: =O33/5 -> 0.92 | M33: =P33/5 -> 1 | O33: 4.6 | P33: 5 | R33: 1 | T33: =R33*P33 -> 5
B34: PAYS | C34: PAYS | D34: PAYS | E34: 레이저 감지기 | G34: Ophir | H34: 5V(2) | J34: 5 | L34: =O34/J34 -> 0.2 | O34: 1 | R34: 0 | T34: =R34*O34 -> 0
C35: PAYR | D35: PAYR | E35: 박막전개장치 | G35: in-house | H35: 5V(1) | J35: 5 | L35: =O35/J35 -> 0.2 | O35: 1 | R35: 0 | T35: =R35*O35 -> 0
D36: PAYR | E36: 박막전개장치 | G36: in-house | H36: 3.3V(3) | J36: 3.3 | M36: =P36/J36 -> 0.60606061 | P36: 2 | R36: 1 | T36: =R36*P36 -> 2
C37: PAYC | D37: PAYC | E37: Nanocam C1U | F37: Peak Power = 3.6V x 500mA @ Max | G37: GOMSPACE | H37: 3.3V(2) | J37: 3.3 | K37: =N37/J37 -> 0.11515152 | L37: =O37/J37 -> 0.24242424 | M37: =P37/J37 -> 0.54545455 | N37: 0.38 | O37: 0.8 | P37: 1.8 | R37: 0 | T37: =R37*O37 -> 0
S38: total power consumption | T38: =SUM(T5:T37)/X13 -> 20.613966 | U38: W | V38: worst case
S39: Generated Energy(orbit average) | T39: =1.135*(6*3+6*3+4*3+4*3)/(3+3+3+3+1+1)*X6/3600 -> 4.937407 | U39: Wh
S40: Required Energy (orbit average) | T40: =T38*X3/3600 -> 32.506992 | U40: Wh
S41: Power Margin Value | T41: =T39-T40 -> -27.569585 | U41: Wh
S42: Power Margin | T42: =100*($T$39/T40-1) -> -84.811246 | U42: %
S43: Residual/Generation | T43: =T41/$T$39*100 -> -558.38186 | U43: % | V43: >40%
...

Sheet parameter
B2: parameter
B4: attitdue (km) | C4: 500 | E4: LTAN | F4: 22 | G4: 0 | H4: 3.3343
B5: Beta angle(deg) | C5: =INDEX(G4:H28,MATCH(F4,G4:G28,0),2) -> 30.893332 | G5: 1 | H5: -10.271498
B6: Earth Gravitational Standard Cosntant (km3/sec2) | C6: 398600 | G6: 2 | H6: -23.52829
B7: Earth Effective Radius (km) | C7: 6378.14 | G7: 3 | H7: -36.118151
B8: orbital period (sec) | C8: =2*PI()*SQRT(($C$7+$C$4)^3/$C$6) -> 5676.9849 | G8: 4 | H8: -47.400155
G9: 5 | H9: -56.011314
B10: sunlight (sec) | C10: =IF(C5<ASIN(C7/(C7+C4))*180/PI(),(360-2*ASIN((((1/COS(C5*PI()/180))^2)*(((C7/(C7+C4))^2-(SIN(C5*PI()/180))^2)))^0.5)*180/PI())/360*C8,C8) -> 3654.1162 | G10: 6 | H10: -59.5711
B11: Eclipse (sec) | C11: =C8-C10 -> 2022.8687 | G11: 7 | H11: -56.42613
B12: conversion efficiency (%) | C12: =90 -> 90 | G12: 8 | H12: -48.06262
G13: 9 | H13: -36.902156
B14: DoD reference | C14: 0.2 | G14: 10 | H14: -24.372771
B15: Conversion Efficiency | C15: 0.9 | G15: 11 | H15: -11.147553
B16: required margin | C16: 0.4 | G16: 12 | H16: 2.4420052
G17: 13 | H17: 16.205457
G18: 14 | H18: 29.998123
G19: 15 | H19: 43.647692
G20: 16 | H20: 56.810927
G21: 17 | H21: 68.422001
G22: 18 | H22: 74.371379
G23: 19 | H23: 69.058097
G24: 20 | H24: 57.633973
G25: 21 | H25: 44.524976
G26: 22 | H26: 30.893332
G27: 23 | H27: 17.103945
G28: 24 | H28: 3.3343

Sheet Sheet1
A1: After sun-pointing, charging magnitude | E1: =#REF!-#REF! -> #REF! | H1: Wh
A2: SoC after sun-pointing | E2: =E1/40*100 -> #REF! | H2: %
A3: Need Orbit number for Full charge | E3: =100/E2 -> #REF! | H3: N
A4: SoC after sun-pointing 6 orbit | E4: =IF(E2*6>100,100,E2*6) -> #REF! | H4: %
A5: After mission or S-band COM,charging magnitude | F5: =40*$E$4/100-#REF! -> #REF! | G5: =40*$E$4/100-#REF! -> #REF! | H5: Wh
A6: SoC after mission or S-band COM | F6: =F5/40*100 -> #REF! | G6: =G5/40*100 -> #REF! | H6: % | I6: > 40 %
A7: SoC after mission or S-band COM except margin | F7: =F5/40*100-40 -> #REF! | G7: =G5/40*100-40 -> #REF! | H7: % | I7: > 40 %
A8: Peak load | C8: 3.3V | E8: =(#REF!+#REF!+#REF!+#REF!+#REF!+#REF!+#REF!+#REF!+#REF!+#REF!+#REF!+#REF!)/3.3 -> #REF! | F8: =(#REF!+#REF!+#REF!+#REF!+#REF!+#REF!+#REF!+#REF!+#REF!+#REF!+#REF!+#REF!)/3.3 -> #REF! | G8: =(#REF!+#REF!+#REF!+#REF!+#REF!+#REF!+#REF!+#REF!+#REF!+#REF!+#REF!+#REF!)/3.3 -> #REF! | I8: < 4.5 A
C9: 5.0V | E9: =(#REF!+#REF!+#REF!+#REF!+#REF!)/5 -> #REF! | F9: =(#REF!+#REF!+#REF!+#REF!+#REF!)/5 -> #REF! | G9: =(#REF!+#REF!+#REF!+#REF!+#REF!)/5 -> #REF! | I9: < 4.5 A
C10: Vbat | E10: =(#REF!+#REF!+#REF!)/8.26 -> #REF! | F10: =(#REF!+#REF!+#REF!)/8.26 -> #REF! | G10: =(#REF!+#REF!+#REF!)/8.26 -> #REF! | I10: < 4.7 A

Sheet Sheet2
B1: 1주기 | C1: 2주기 | D1: 3주기 | E1: 4주기 | F1: 5주기 | G1: 6주기 | H1: 7주기 | I1: 8주기 | J1: 9주기 | K1: 10주기 | L1: 11주기 | M1: 12주기 | N1: 13주기 | O1: 14주기 | P1: 15주기
B2: 0 (0s)
B3: 1367s
A5: Start Index(Time) | B5: 139 (1367s) | C5: 710 (7043s) | D5: 1279 (12713s) | E5: 1849 (18388s) | F5: 2416 (24055s) | G5: 2985 (29728s) | H5: 3556 (35403s) | I5: 4126 (41077s) | J5: 4696 (46750s) | K5: 5265 (52422s) | L5: 5834 (58093s) | M5: 6404 (63766s) | N5: 6972 (69435s) | O5: 7543 (75108s) | P5: 8114 (80782s)
B6: 3653s | C6: 510s | D6: 3652s | E6: 3649s | F6: 3653s | G6: 3654s | H6: 3649s | I6: 3650s | J6: 3646s | K6: 3650s | L6: 3651s | M6: 3649s | N6: 3654s | O6: 3652s | P6: 3650s
A7: Start Mission & ComD | C7: 761 (7552s)
C8: 681s
A9: End Mission & ComD | C9: 829 (8232s)
C10: 2458s
A11: Eclipse | B11: 507 (5019s) | C11: 1075 (10689s) | D11: 1646 (16364s) | E11: 2214 (22036s) | F11: 2782 (27707s) | G11: 3353 (33381s) | H11: 3922 (39051s) | I11: 4493 (44726s) | J11: 5061 (50395s) | K11: 5631 (56071s) | L11: 6201 (61743s) | M11: 6769 (67414s) | N11: 7340 (73088s) | O11: 7911 (78759s) | P11: 8482 (84431s)
B12: 2015s | C12: 2025s | D12: 2015s | E12: 2010s | F12: 2015s | G12: 2014s | H12: 2018s | I12: 935s | J12: 2018s | K12: 2014s | L12: 2024s | M12: 2016s | N12: 2014s | O12: 2014s | P12: 1970s
A13: Start ComN | I13: 4587 (45660s)
I14: 661s | P14: 8680 (86400s)
A15: End ComN | I15: 4653 (46320s)
I16: 421s
A17: End | B17: 709 (7033s) | C17: 1278 (12713s) | D17: 1848 (18378s) | E17: 2415 (24045s) | F17: 2984 (29721s) | G17: 3555 (35394s) | H17: 4125 (41068s) | I17: 4695 (46740s) | J17: 5264 (52412s) | K17: 5833 (58084s) | L17: 6403 (63766s) | M17: 6971 (69429s) | N17: 7542 (75101s) | O17: 8113 (80773s)
A18: Total Time(sec) | B18: 1367+5668 | C18: 5674 | D18: 5667 | E18: 5659 | F18: 5668 | G18: 5668 | H18: 5667 | I18: 5667 | J18: 5664 | K18: 5664 | L18: 5675 | M18: 5665 | N18: 5668 | O18: 5667 | P18: 5620
A19: Power Generation(Wh) | B19: 23.041 | C19: 18.747 | D19: 23.041 | E19: 23.041 | F19: 23.041 | G19: 23.041 | H19: 23.041 | I19: 23.041 | J19: 23.041 | K19: 23.041 | L19: 23.041 | M19: 23.041 | N19: 23.041 | O19: 23.041 | P19: 23.041
A20: Power Consumption(Wh) | B20: 6.596 | C20: 9.45 | D20: 6.596 | E20: 6.596 | F20: 6.596 | G20: 6.596 | H20: 6.596 | I20: 9.244 | J20: 6.596 | K20: 6.596 | L20: 6.596 | M20: 6.596 | N20: 6.596 | O20: 6.596 | P20: 8.3952
A21: Gen-Cons(Wh) | B21: =B19-B20 -> 16.445 | C21: =C19-C20 -> 9.297 | D21: =D19-D20 -> 16.445 | E21: =E19-E20 -> 16.445 | F21: =F19-F20 -> 16.445 | G21: =G19-G20 -> 16.445 | H21: =H19-H20 -> 16.445 | I21: =I19-I20 -> 13.797 | ... P21: =P19-P20 -> 14.6458
B26: 0 (0s)
B27: 1367s
A29: Start Index(Time) | B29: 139 (1367s) | C29: 710 (7043s) | D29: 1279 (12713s) | E29: 1849 (18388s) | F29: 2416 (24055s) | G29: 2985 (29728s) | H29: 3556 (35403s) | I29: 4126 (41077s) | J29: 4696 (46750s) | K29: 5265 (52422s) | L29: 5834 (58093s) | M29: 6404 (63766s) | N29: 6972 (69435s) | O29: 7543 (75108s) | P29: 8114 (80782s)
B30: 3653s | C30: 510s | D30: 3652s | E30: 3649s | F30: 3653s | G30: 3654s | H30: 3649s | I30: 3650s | J30: 3646s | K30: 3650s | L30: 3651s | M30: 3649s | N30: 3654s | O30: 3652s | P30: 3650s
A31: Start Mission & ComD | C31: 761 (7552s)
C32: 681s
A33: End Mission & ComD | C33: 829 (8232s)
C34: 2458s
A35: Eclipse | B35: 507 (5019s) | C35: 1075 (10689s) | D35: 1646 (16364s) | E35: 2214 (22036s) | F35: 2782 (27707s) | G35: 3353 (33381s) | H35: 3922 (39051s) | I35: 4493 (44726s) | J35: 5061 (50395s) | K35: 5631 (56071s) | L35: 6201 (61743s) | M35: 6769 (67414s) | N35: 7340 (73088s) | O35: 7911 (78759s) | P35: 8482 (84431s)
B36: 2015s | C36: 2025s | D36: 2015s | E36: 2010s | F36: 2015s | G36: 2014s | H36: 2018s | I36: 935s | J36: 2018s | K36: 2014s | L36: 2024s | M36: 2016s | N36: 2014s | O36: 2014s | P36: 1970s
A37: Start ComN | I37: 4587 (45660s)
I38: 661s | P38: 8680 (86400s)
A39: End ComN | I39: 4653 (46320s)
I40: 421s
A41: End | B41: 709 (7033s) | C41: 1278 (12713s) | D41: 1848 (18378s) | E41: 2415 (24045s) | F41: 2984 (29721s) | G41: 3555 (35394s) | H41: 4125 (41068s) | I41: 4695 (46740s) | J41: 5264 (52412s) | K41: 5833 (58084s) | L41: 6403 (63766s) | M41: 6971 (69429s) | N41: 7542 (75101s) | O41: 8113 (80773s)
A42: Total Time(sec) | B42: 1367+5668 | C42: 5674 | D42: 5667 | E42: 5659 | F42: 5668 | G42: 5668 | H42: 5667 | I42: 5667 | J42: 5664 | K42: 5664 | L42: 5675 | M42: 5665 | N42: 5668 | O42: 5667 | P42: 5620
A43: Power Generation(Wh) | B43: 23.041 | C43: 18.747 | D43: 23.041 | E43: 23.041 | F43: 23.041 | G43: 23.041 | H43: 23.041 | I43: 23.041 | J43: 23.041 | K43: 23.041 | L43: 23.041 | M43: 23.041 | N43: 23.041 | O43: 23.041 | P43: 23.041
A44: Power Consumption(Wh) | B44: 6.596 | C44: 9.45 | D44: 6.596 | E44: 6.596 | F44: 6.596 | G44: 6.596 | H44: 6.596 | I44: 9.244 | J44: 6.596 | K44: 6.596 | L44: 6.596 | M44: 6.596 | N44: 6.596 | O44: 6.596 | P44: 3.56
A45: Gen-Cons(Wh) | B45: =B43-B44 -> 16.445 | C45: =C43-C44 -> 9.297 | D45: =D43-D44 -> 16.445 | E45: =E43-E44 -> 16.445 | F45: =F43-F44 -> 16.445 | G45: =G43-G44 -> 16.445 | H45: =H43-H44 -> 16.445 | I45: =I43-I44 -> 13.797 | ... P45: =P43-P44 -> 19.481
A47: Dayside | B47: =B43*A48 -> 20.7369 | C47: =C43*A48 -> 16.8723 | D47: =D43*A48 -> 20.7369 | E47: =E43*A48 -> 20.7369 | F47: =F43*A48 -> 20.7369 | G47: =G43*A48 -> 20.7369 | H47: =H43*A48 -> 20.7369 | I47: =I43*A48 -> 20.7369 | J47: =J43*A48 -> 20.7369 | K47: =K43*A48 -> 20.7369 | L47: =L43*A48 -> 20.7369 | M47: =M43*A48 -> 20.7369 | N47: =N43*A48 -> 20.7369 | O47: =O43*A48 -> 20.7369 | P47: =P43*A48 -> 20.7369
...
