Workbook

Sheet Detumbling
A2: channel | B2: Subsystem | C2: Component | D2: Product | E2: Mode | F2: Voltage Input | G2: Current(A) | J2: Power | N2: Duty(%) | O2: Consumption Power (W) | S2: Note
G3: Idle | H3: Nominal | I3: Peak | J3: Idel | K3: Nominal | L3: Peak | M3: Mode | N3: Detumbling | P3: Detumbling | S3: Orbit period | T3: =parameter!C8 -> 5676.9849
M4: Time | N4: =T3 -> 5676.9849 | S4: Missiond period | T4: 681
A5: 5V(1) | B5: PAYS | F5: 5 | H5: =K5/F5 -> 0.04 | K5: 0.2 | N5: 0 | P5: =N5*K5 -> 0 | S5: S-band period | T5: 661
A6: 5V(2) | B6: PAYR | F6: 5 | H6: =K6/F6 -> 0.04 | I6: =L6/F6 -> 0.4 | K6: 0.2 | L6: 2 | N6: 0 | P6: =N6*K6 -> 0 | S6: sunlight | T6: =parameter!C10 -> 3654.1162
A7: 3.3V(3) | F7: 3.3 | H7: =K7/F7 -> 0.060606061 | I7: =L7/F7 -> 0.060606061 | K7: 0.2 | L7: 0.2 | N7: 0 | P7: =N7*K7 -> 0 | S7: Eclipse | T7: =parameter!C11 -> 2022.8687
A8: 3.3V(2) | B8: PAYC | C8: Cam | D8: NanoCam - 70 mm | F8: 3.3 | G8: 0.115 | H8: =K8/F8 -> 0.24242424 | I8: 0.394 | J8: =F8*G8 -> 0.3795 | K8: 0.8 | L8: =I8*F8 -> 1.3002 | N8: 0 | P8: =N8*K8 -> 0 | S8: solar panel efficiency | T8: 0.3
A9: 3.3V | B9: ADCS | C9: ADCS module | D9: Cubecomputer | F9: 3.3 | H9: =0.12/F9 -> 0.036363636 | I9: =0.2/F9 -> 0.060606061 | K9: =H9*F9 -> 0.12 | L9: =I9*F9 -> 0.2 | N9: 1 | P9: =N9*K9 -> 0.12 | S9: Emppt | T9: 0.6
D10: Cubesense V3 x 2 | F10: 3.3 | H10: =0.2/F10 -> 0.060606061 | I10: =0.4/F10 -> 0.12121212 | K10: =H10*F10 -> 0.2 | L10: =I10*F10 -> 0.4 | N10: 0 | P10: =N10*K10 -> 0 | S10: Etmp | T10: 0.8
A11: 5V | D11: CubeTorquers rod | F11: 5 | H11: =0.07*5/5 -> 0.07 | I11: =0.167*5/5 -> 0.167 | K11: =H11*F11 -> 0.35 | L11: =I11*F11 -> 0.835 | N11: 1 | P11: =N11*K11 -> 0.35 | S11: Eman | T11: 0.8
D12: CubeTorquers coil | F12: 5 | H12: 0.064 | K12: =H12*F12 -> 0.32 | N12: 1 | P12: =N12*K12 -> 0.32
A13: 3.3V | D13: Cubecontrol | F13: 3.3 | H13: =0.2/F13 -> 0.060606061 | K13: =H13*F13 -> 0.2 | N13: 1 | P13: =N13*K13 -> 0.2
D14: CubeMag | F14: 3.3 | H14: =0.035/F14 -> 0.010606061 | K14: =H14*F14 -> 0.035 | N14: 1 | P14: =N14*K14 -> 0.035 | S14: Depth of Discharge | T14: 0.2
A15: VBAT | D15: Wheel x 3 | F15: 8.26 | G15: =0.065*3/F15 -> 0.023607748 | H15: =0.19*3/F15 -> 0.069007264 | I15: =2.3*3/F15 -> 0.83535109 | J15: =F15*G15 -> 0.195 | K15: =H15*F15 -> 0.57 | L15: =I15*F15 -> 6.9 | N15: 0 | P15: =N15*K15 -> 0 | S15: Conversion Efficiency | T15: 0.9
A16: 3.3V | C16: GPS antenna | D16: TW1829 | F16: 3.3 | H16: 0 | K16: =H16*F16 -> 0 | N16: 0 | P16: =N16*K16 -> 0 | S16: required margin | T16: 0.4
A17: 3.3V(1) | C17: GPS Rx | D17: OEM719 | F17: 3.3 | H17: 0.394 | K17: 1.3 | N17: 0 | P17: =N17*K17 -> 0
B18: EPS | C18: Battery | D18: Optimus-40 | K18: 0.1 | N18: 1 | P18: =N18*K18 -> 0.1
C19: PCDU | D19: Starbuck-Nano-Plus | K19: 0.2 | N19: 1 | P19: =N19*K19 -> 0.2
C20: Solar cell | D20: GOMspace | K20: =H20*F20 -> 0 | N20: 1 | P20: =N20*K20 -> 0
A21: 3.3V | B21: CNDH | C21: OBC | D21: NST | F21: 3.3 | H21: =0.13 -> 0.13 | K21: =H21*F21 -> 0.429 | N21: 1 | P21: =N21*K21 -> 0.429
A22: 3.3V | B22: COMS | C22: UHF antenna | D22: ISIS | F22: 3.3 | H22: =0.04/F22 -> 0.012121212 | I22: =2/F22 -> 0.60606061 | K22: =H22*F22 -> 0.04 | L22: =I22*F22 -> 2 | N22: 0 | P22: =N22*K22 -> 0
C23: UHF TRx | D23: NanoCom AX100 | E23: Rx | F23: 3.3 | G23: 0.045 | H23: 0.055 | I23: 0.12 | J23: =F23*G23 -> 0.1485 | K23: =H23*F23 -> 0.1815 | L23: =I23*F23 -> 0.396 | N23: 0 | P23: =N23*K23 -> 0
E24: Tx | F24: 3.3 | G24: 0.6 | I24: 1 | J24: =F24*G24 -> 1.98 | L24: =I24*F24 -> 3.3 | N24: 1 | P24: =N24*K24 -> 0
A25: 5V | C25: S-band Tx | D25: PULSAR-STX | E25: Tx | F25: 5 | G25: =J25/5 -> 0.122 | H25: =K25/5 -> 0.54 | I25: =L25/5 -> 1 | J25: 0.61 | K25: 2.7 | L25: 5 | N25: 0 | P25: =N25*K25 -> 0
O26: total power consumption | P26: =SUM(P5:P25) -> 1.754 | Q26: W | R26: worst case
O27: Generated Energy(orbit average) | P27: =1.135*(6*3+6*3+4*3+4*3)/6*T6/3600 -> 11.520616 | Q27: Wh
O28: Required Energy (orbit average) | P28: =P26*T3/3600 -> 2.7659532 | Q28: Wh
O29: Power Margin Value | P29: =P27-P28 -> 8.7546631 | Q29: Wh
O30: Power Margin | P30: =100*($P$27/P28-1) -> 316.51523 | Q30: %
O31: Residual/Generation | P31: =P29/$P$27*100 -> 75.991274 | Q31: % | R31: >40%
O32: charging rate | P32: =(P27-P28)/40*100 -> 21.886658 | Q32: %

Sheet ① 2주기(Mission&UHF)
A2: channel | B2: Subsystem | C2: Component | D2: Product | E2: Mode | F2: Voltage Input | G2: Current(A) | J2: Power | N2: Duty(%) | Q2: Consumption Power (W) | X2: Note
G3: Idle | H3: Nominal | I3: Peak | J3: Idel | K3: Nominal | L3: Peak | M3: Mode | N3: Stand-by(D) | O3: Stand-by(N) | P3: Mission & UHF COM | R3: Stand-by(D) | S3: Stand-by(N) | T3: Mission & UHF COM | U3: Total | X3: Orbit period | Y3: =parameter!C8 -> 5676.9849
M4: Time | N4: =Y6-Y4 -> 2973.1162 | O4: =Y7 -> 2022.8687 | P4: =Y4 -> 681 | X4: Missiond period | Y4: 681
A5: 5V(1) | B5: PAYS | F5: 5 | H5: =K5/F5 -> 0.04 | K5: 0.2 | N5: 0 | O5: 0 | P5: 1 | R5: =N5*K5 -> 0 | S5: =O5*K5 -> 0 | T5: =P5*K5 -> 0.2 | U5: =SUM(R5+S5+T5) -> 0.2 | X5: S-band period | Y5: 661
A6: 5V(2) | B6: PAYR | F6: 5 | H6: =K6/F6 -> 0.04 | I6: =L6/F6 -> 0.4 | K6: 0.2 | L6: 2 | N6: 0 | O6: 0 | P6: 1 | R6: =N6*K6 -> 0 | S6: =O6*K6 -> 0 | T6: =P6*K6 -> 0.2 | U6: =SUM(R6+S6+T6) -> 0.2 | X6: sunlight | Y6: =parameter!C10 -> 3654.1162
A7: 3.3V(3) | F7: 3.3 | H7: =K7/F7 -> 0.060606061 | I7: =L7/F7 -> 0.60606061 | K7: 0.2 | L7: 2 | N7: 0 | O7: 0 | P7: 1 | R7: =N7*K7 -> 0 | S7: =O7*K7 -> 0 | T7: =P7*K7 -> 0.2 | U7: =SUM(R7+S7+T7) -> 0.2 | X7: Eclipse | Y7: =parameter!C11 -> 2022.8687
A8: 3.3V(2) | B8: PAYC | C8: Cam | D8: NanoCam - 70 mm | F8: 3.3 | G8: 0.115 | H8: 0.242 | I8: 0.394 | J8: =F8*G8 -> 0.3795 | K8: 0.8 | L8: =I8*F8 -> 1.3002 | N8: 0 | O8: 0 | P8: 1 | R8: =N8*K8 -> 0 | S8: =O8*K8 -> 0 | T8: =P8*L8 -> 1.3002 | U8: =SUM(R8+S8+T8) -> 1.3002 | X8: solar panel efficiency | Y8: 0.3
A9: 3.3V | B9: ADCS | C9: ADCS module | D9: Cubecomputer | F9: 3.3 | H9: =0.12/F9 -> 0.036363636 | I9: =0.2/F9 -> 0.060606061 | K9: =H9*F9 -> 0.12 | L9: =I9*F9 -> 0.2 | N9: 1 | O9: 1 | P9: 1 | R9: =N9*K9 -> 0.12 | S9: =O9*K9 -> 0.12 | T9: =P9*$L$9+(1-P9)*K9 -> 0.2 | U9: =SUM(R9+S9+T9) -> 0.44 | X9: Emppt | Y9: 0.6
D10: Cubesense V3 x 2 | F10: 3.3 | H10: =0.2/F10 -> 0.060606061 | I10: =0.4/F10 -> 0.12121212 | K10: =H10*F10 -> 0.2 | L10: =I10*F10 -> 0.4 | N10: 1 | O10: 0.5 | P10: 1 | R10: =N10*K10 -> 0.2 | S10: =O10*K10 -> 0.1 | T10: =P10*$L$10+(1-P10)*K10 -> 0.4 | U10: =SUM(R10+S10+T10) -> 0.7 | X10: Etmp | Y10: 0.8
A11: 5V | D11: CubeTorquers rod | F11: 5 | H11: =0.07*5/5 -> 0.07 | I11: =0.167*5/5 -> 0.167 | K11: =H11*F11 -> 0.35 | L11: =I11*F11 -> 0.835 | N11: 1 | O11: 1 | P11: 1 | R11: =N11*K11 -> 0.35 | S11: =O11*K11 -> 0.35 | T11: =P11*$L$11+(1-P11)*K11 -> 0.835 | U11: =SUM(R11+S11+T11) -> 1.535 | X11: Eman | Y11: 0.8
D12: CubeTorquers coil | F12: 5 | H12: 0.064 | K12: =H12*F12 -> 0.32 | N12: 1 | O12: 1 | P12: 1 | R12: =N12*K12 -> 0.32 | S12: =O12*K12 -> 0.32 | T12: =P12*$K$12 -> 0.32 | U12: =SUM(R12+S12+T12) -> 0.96
A13: 3.3V | D13: Cubecontrol | F13: 3.3 | H13: =0.2/F13 -> 0.060606061 | K13: =H13*F13 -> 0.2 | N13: 1 | O13: 1 | P13: 1 | R13: =N13*K13 -> 0.2 | S13: =O13*K13 -> 0.2 | T13: =P13*$K$13 -> 0.2 | U13: =SUM(R13+S13+T13) -> 0.6
D14: CubeMag | F14: 3.3 | H14: =0.035/F14 -> 0.010606061 | K14: =H14*F14 -> 0.035 | N14: 1 | O14: 1 | P14: 1 | R14: =N14*K14 -> 0.035 | S14: =O14*K14 -> 0.035 | T14: =P14*$K$14 -> 0.035 | U14: =SUM(R14+S14+T14) -> 0.105 | X14: Depth of Discharge | Y14: 0.2
A15: VBAT | D15: Wheel x 3 | F15: 8.26 | G15: =0.065*3/F15 -> 0.023607748 | H15: =0.19*3/F15 -> 0.069007264 | I15: =2.3*3/F15 -> 0.83535109 | J15: =F15*G15 -> 0.195 | K15: =H15*F15 -> 0.57 | L15: =I15*F15 -> 6.9 | N15: 1 | O15: 1 | P15: 1 | R15: =N15*K15 -> 0.57 | S15: =O15*K15 -> 0.57 | T15: =P15*$L$15+(1-P15)*K15 -> 6.9 | U15: =SUM(R15+S15+T15) -> 8.04 | X15: Conversion Efficiency | Y15: 0.9
A16: 3.3V | C16: GPS antenna | D16: TW1829 | F16: 3.3 | H16: 0 | K16: =H16*F16 -> 0 | N16: 1 | O16: 1 | P16: 1 | R16: =N16*K16 -> 0 | S16: =O16*K16 -> 0 | T16: =P16*K16 -> 0 | U16: =SUM(R16+S16+T16) -> 0 | X16: required margin | Y16: 0.4
A17: 3.3V(1) | C17: GPS Rx | D17: OEM719 | F17: 3.3 | H17: 0.394 | K17: 1.3 | N17: 1 | O17: 1 | P17: 1 | R17: =N17*K17 -> 1.3 | S17: =O17*K17 -> 1.3 | T17: =P17*K17 -> 1.3 | U17: =SUM(R17+S17+T17) -> 3.9
B18: EPS | C18: Battery | D18: Optimus-40 | K18: 0.1 | N18: 1 | O18: 1 | P18: 1 | R18: =N18*K18 -> 0.1 | S18: =O18*K18 -> 0.1 | T18: =P18*K18 -> 0.1 | U18: =SUM(R18+S18+T18) -> 0.3
C19: PCDU | D19: Starbuck-Nano-Plus | K19: 0.2 | N19: 1 | O19: 1 | P19: 1 | R19: =N19*K19 -> 0.2 | S19: =O19*K19 -> 0.2 | T19: =P19*K19 -> 0.2 | U19: =SUM(R19+S19+T19) -> 0.6
C20: Solar cell | D20: GOMspace | K20: =H20*F20 -> 0 | N20: 1 | O20: 1 | P20: 1 | R20: =N20*K20 -> 0 | S20: =O20*K20 -> 0 | T20: =P20*K20 -> 0 | U20: =SUM(R20+S20+T20) -> 0
A21: 3.3V | B21: CNDH | C21: OBC | D21: NST | F21: 3.3 | H21: =0.13 -> 0.13 | K21: =H21*F21 -> 0.429 | N21: 1 | O21: 1 | P21: 1 | R21: =N21*K21 -> 0.429 | S21: =O21*K21 -> 0.429 | T21: =P21*L21 -> 0 | U21: =SUM(R21+S21+T21) -> 0.858
A22: 3.3V | B22: COMS | C22: UHF antenna | D22: ISIS | F22: 3.3 | H22: =0.04/F22 -> 0.012121212 | I22: =2/F22 -> 0.60606061 | K22: =H22*F22 -> 0.04 | L22: =I22*F22 -> 2 | N22: 0 | O22: 0 | P22: 1 | R22: =N22*K22 -> 0 | S22: =O22*K22 -> 0 | T22: =P22*K22 -> 0.04 | U22: =SUM(R22+S22+T22) -> 0.04
C23: UHF TRx | D23: NanoCom AX100 | E23: Rx | F23: 3.3 | G23: 0.045 | H23: 0.055 | I23: 0.12 | J23: =F23*G23 -> 0.1485 | K23: =H23*F23 -> 0.1815 | L23: =I23*F23 -> 0.396 | N23: 0.9 | O23: 0.9 | P23: 0.8 | R23: =N23*L23 -> 0.3564 | S23: =O23*L23 -> 0.3564 | T23: =P23*L23 -> 0.3168 | U23: =SUM(R23+S23+T23) -> 1.0296
E24: Tx | F24: 3.3 | G24: 0.6 | I24: 1 | J24: =F24*G24 -> 1.98 | L24: =I24*F24 -> 3.3 | N24: =1-N23 -> 0.1 | O24: =1-O23 -> 0.1 | P24: =1-P23 -> 0.2 | R24: =N24*L24 -> 0.33 | S24: =O24*L24 -> 0.33 | T24: =P24*L24 -> 0.66 | U24: =SUM(R24+S24+T24) -> 1.32
A25: 5V | C25: S-band Tx | D25: PULSAR-STX | E25: Tx | F25: 5 | G25: =J25/5 -> 0.122 | H25: =K25/5 -> 0.54 | I25: =L25/5 -> 1 | J25: 0.61 | K25: 2.7 | L25: 5 | N25: 0 | O25: 0 | P25: 0 | R25: =N25*K25 -> 0 | S25: =O25*K25 -> 0 | T25: =P25*K25 -> 0 | U25: =SUM(R25+S25+T25) -> 0
Q26: total power consumption | R26: =SUM(R5:R25)/Y15 -> 5.0115556 | S26: =SUM(S5:S25)/Y15 -> 4.9004444 | T26: =SUM(T5:T25)/Y15 -> 14.896667 | U26: =SUM(R26+S26+T26) -> 24.808667 | V26: W | W26: worst case
Q27: Generated Energy(orbit average) | R27: =1.135*20*N4/3600 -> 18.747149 | S27: 0 | T27: 0 | U27: =SUM(R27+S27+T27) -> 18.747149 | V27: Wh
Q28: Required Energy (orbit average) | R28: =R26*N4/3600 -> 4.1388714 | S28: =S26*O4/3600 -> 2.7535988 | T28: =T26*P4/3600 -> 2.8179528 | U28: =SUM(R28+S28+T28) -> 9.710423 | V28: Wh
Q29: Power Margin Value (orbit average) | R29: =U27-U28 -> 9.0367263 | U29: =SUM(R29+S29+T29) -> 9.0367263 | V29: Wh
Q30: Power Margin (orbit average) | R30: =100*($U$27/U28-1) -> 93.062128 | U30: =SUM(R30+S30+T30) -> 93.062128 | V30: %
Q31: Residual/Generation | R31: =U29/$U$27*100 -> 48.203202 | U31: =SUM(R31+S31+T31) -> 48.203202 | V31: % | W31: >40%
Q32: charging rate | R32: =(R27-R28)/40*100 -> 36.520695 | S32: =(S27-S28)/40*100 -> -6.883997 | T32: =(T27-T28)/40*100 -> -7.0448819 | U32: =SUM(R32+S32+T32) -> 22.591816 | V32: %
X33: DET | Y33: Stand-by | Z33: sum
X34: 1 | Y34: 0
W35: GEN | X35: =1.135*(6*3+6*3+4*3+4*3)/(3+3+3+3+1+1)*N4/3600*X34 -> 4.0172463 | Y35: =R27*Y34 -> 0 | Z35: =X35+Y35 -> 4.0172463
W36: CON | X36: =1.498*X34 -> 1.498 | Y36: =U28*Y34 -> 0 | Z36: =X36+Y36 -> 1.498
W37: G-C | Z37: =Z35-Z36 -> 2.5192463

Sheet ② 8주기(S-band)
A2: channel | B2: Subsystem | C2: Component | D2: Product | E2: Mode | F2: Voltage Input | G2: Current(A) | J2: Power | N2: Duty(%) | Q2: Consumption Power (W) | X2: Note
G3: Idle | H3: Nominal | I3: Peak | J3: Idel | K3: Nominal | L3: Peak | M3: Mode | N3: Stand-by(D) | O3: Stand-by(N) | P3: S-band COM | R3: Stand-by(D) | S3: Stand-by(N) | T3: S-band COM | U3: Total | X3: Orbit period | Y3: =parameter!C8 -> 5676.9849
M4: Time | N4: =Y6 -> 3654.1162 | O4: =Y7-Y5 -> 1361.8687 | P4: =Y5 -> 661 | X4: Missiond period | Y4: 681
A5: 5V(1) | B5: PAYS | F5: 5 | H5: =K5/F5 -> 0.04 | K5: 0.2 | N5: 0 | O5: 0 | P5: 0 | R5: =N5*K5 -> 0 | S5: =O5*K5 -> 0 | T5: =P5*K5 -> 0 | U5: =SUM(R5+S5+T5) -> 0 | X5: S-band period | Y5: 661
A6: 5V(2) | B6: PAYR | F6: 5 | H6: =K6/F6 -> 0.04 | I6: =L6/F6 -> 0.4 | K6: 0.2 | L6: 2 | N6: 0 | O6: 0 | P6: =N6*K6 -> 0 | R6: =N6*K6 -> 0 | S6: =O6*K6 -> 0 | T6: =P6*K6 -> 0 | U6: =SUM(R6+S6+T6) -> 0 | X6: sunlight | Y6: =parameter!C10 -> 3654.1162
A7: 3.3V(3) | F7: 3.3 | H7: =K7/F7 -> 0.060606061 | I7: =L7/F7 -> 0.60606061 | K7: 0.2 | L7: 2 | N7: 0 | O7: 0 | P7: =N7*K7 -> 0 | R7: =N7*K7 -> 0 | S7: =O7*K7 -> 0 | T7: =P7*K7 -> 0 | U7: =SUM(R7+S7+T7) -> 0 | X7: Eclipse | Y7: =parameter!C11 -> 2022.8687
A8: 3.3V(2) | B8: PAYC | C8: Cam | D8: NanoCam - 70 mm | F8: 3.3 | G8: 0.115 | H8: 0.242 | I8: 0.394 | J8: =F8*G8 -> 0.3795 | K8: 0.8 | L8: =I8*F8 -> 1.3002 | N8: 0 | O8: 0 | P8: 0 | R8: =N8*K8 -> 0 | S8: =O8*K8 -> 0 | T8: =P8*L8 -> 0 | U8: =SUM(R8+S8+T8) -> 0 | X8: solar panel efficiency | Y8: 0.3
A9: 3.3V | B9: ADCS | C9: ADCS module | D9: Cubecomputer | F9: 3.3 | H9: =0.12/F9 -> 0.036363636 | I9: =0.2/F9 -> 0.060606061 | K9: =H9*F9 -> 0.12 | L9: =I9*F9 -> 0.2 | N9: 1 | O9: 1 | P9: 1 | R9: =N9*K9 -> 0.12 | S9: =O9*K9 -> 0.12 | T9: =P9*$L$9+(1-P9)*K9 -> 0.2 | U9: =SUM(R9+S9+T9) -> 0.44 | X9: Emppt | Y9: 0.6
D10: Cubesense V3 x 2 | F10: 3.3 | H10: =0.2/F10 -> 0.060606061 | I10: =0.4/F10 -> 0.12121212 | K10: =H10*F10 -> 0.2 | L10: =I10*F10 -> 0.4 | N10: 1 | O10: 0.5 | P10: 1 | R10: =N10*K10 -> 0.2 | S10: =O10*K10 -> 0.1 | T10: =P10*$L$10+(1-P10)*K10 -> 0.4 | U10: =SUM(R10+S10+T10) -> 0.7 | X10: Etmp | Y10: 0.8
A11: 5V | D11: CubeTorquers rod | F11: 5 | H11: =0.07*5/5 -> 0.07 | I11: =0.167*5/5 -> 0.167 | K11: =H11*F11 -> 0.35 | L11: =I11*F11 -> 0.835 | N11: 1 | O11: 1 | P11: 1 | R11: =N11*K11 -> 0.35 | S11: =O11*K11 -> 0.35 | T11: =P11*$L$11+(1-P11)*K11 -> 0.835 | U11: =SUM(R11+S11+T11) -> 1.535 | X11: Eman | Y11: 0.8
D12: CubeTorquers coil | F12: 5 | H12: 0.064 | K12: =H12*F12 -> 0.32 | N12: 1 | O12: 1 | P12: 1 | R12: =N12*K12 -> 0.32 | S12: =O12*K12 -> 0.32 | T12: =P12*$K$12 -> 0.32 | U12: =SUM(R12+S12+T12) -> 0.96
A13: 3.3V | D13: Cubecontrol | F13: 3.3 | H13: =0.2/F13 -> 0.060606061 | K13: =H13*F13 -> 0.2 | N13: 1 | O13: 1 | P13: 1 | R13: =N13*K13 -> 0.2 | S13: =O13*K13 -> 0.2 | T13: =P13*$K$13 -> 0.2 | U13: =SUM(R13+S13+T13) -> 0.6
D14: CubeMag | F14: 3.3 | H14: =0.035/F14 -> 0.010606061 | K14: =H14*F14 -> 0.035 | N14: 1 | O14: 1 | P14: 1 | R14: =N14*K14 -> 0.035 | S14: =O14*K14 -> 0.035 | T14: =P14*$K$14 -> 0.035 | U14: =SUM(R14+S14+T14) -> 0.105 | X14: Depth of Discharge | Y14: 0.2
A15: VBAT | D15: Wheel x 3 | F15: 8.26 | G15: =0.065*3/F15 -> 0.023607748 | H15: =0.19*3/F15 -> 0.069007264 | I15: =2.3*3/F15 -> 0.83535109 | J15: =F15*G15 -> 0.195 | K15: =H15*F15 -> 0.57 | L15: =I15*F15 -> 6.9 | N15: 1 | O15: 1 | P15: 1 | R15: =N15*K15 -> 0.57 | S15: =O15*K15 -> 0.57 | T15: =P15*$L$15+(1-P15)*K15 -> 6.9 | U15: =SUM(R15+S15+T15) -> 8.04 | X15: Conversion Efficiency | Y15: 0.9
A16: 3.3V | C16: GPS antenna | D16: TW1829 | F16: 3.3 | H16: 0 | K16: =H16*F16 -> 0 | N16: 1 | O16: 1 | P16: 1 | R16: =N16*K16 -> 0 | S16: =O16*K16 -> 0 | T16: =P16*K16 -> 0 | U16: =SUM(R16+S16+T16) -> 0 | X16: required margin | Y16: 0.4
A17: 3.3V(1) | C17: GPS Rx | D17: OEM719 | F17: 3.3 | H17: 0.394 | K17: 1.3 | N17: 1 | O17: 1 | P17: 1 | R17: =N17*K17 -> 1.3 | S17: =O17*K17 -> 1.3 | T17: =P17*K17 -> 1.3 | U17: =SUM(R17+S17+T17) -> 3.9
B18: EPS | C18: Battery | D18: Optimus-40 | K18: 0.1 | N18: 1 | O18: 1 | P18: 1 | R18: =N18*K18 -> 0.1 | S18: =O18*K18 -> 0.1 | T18: =P18*K18 -> 0.1 | U18: =SUM(R18+S18+T18) -> 0.3
C19: PCDU | D19: Starbuck-Nano-Plus | K19: 0.2 | N19: 1 | O19: 1 | P19: 1 | R19: =N19*K19 -> 0.2 | S19: =O19*K19 -> 0.2 | T19: =P19*K19 -> 0.2 | U19: =SUM(R19+S19+T19) -> 0.6
C20: Solar cell | D20: GOMspace | K20: =H20*F20 -> 0 | N20: 1 | O20: 1 | P20: 1 | R20: =N20*K20 -> 0 | S20: =O20*K20 -> 0 | T20: =P20*K20 -> 0 | U20: =SUM(R20+S20+T20) -> 0
A21: 3.3V | B21: CNDH | C21: OBC | D21: NST | F21: 3.3 | H21: =0.13 -> 0.13 | K21: =H21*F21 -> 0.429 | N21: 1 | O21: 1 | P21: 1 | R21: =N21*K21 -> 0.429 | S21: =O21*K21 -> 0.429 | T21: =P21*L21 -> 0 | U21: =SUM(R21+S21+T21) -> 0.858
A22: 3.3V | B22: COMS | C22: UHF antenna | D22: ISIS | F22: 3.3 | H22: =0.04/F22 -> 0.012121212 | I22: =2/F22 -> 0.60606061 | K22: =H22*F22 -> 0.04 | L22: =I22*F22 -> 2 | N22: 0 | O22: 0 | P22: 0 | R22: =N22*K22 -> 0 | S22: =O22*K22 -> 0 | T22: =P22*K22 -> 0 | U22: =SUM(R22+S22+T22) -> 0
C23: UHF TRx | D23: NanoCom AX100 | E23: Rx | F23: 3.3 | G23: 0.045 | H23: 0.055 | I23: 0.12 | J23: =F23*G23 -> 0.1485 | K23: =H23*F23 -> 0.1815 | L23: =I23*F23 -> 0.396 | N23: 1 | O23: 1 | P23: 1 | R23: =N23*K23 -> 0.1815 | S23: =O23*L23 -> 0.396 | T23: =P23*K23 -> 0.1815 | U23: =SUM(R23+S23+T23) -> 0.759
E24: Tx | F24: 3.3 | G24: 0.6 | I24: 1 | J24: =F24*G24 -> 1.98 | L24: =I24*F24 -> 3.3 | N24: =1-N23 -> 0 | O24: =1-O23 -> 0 | P24: =1-P23 -> 0 | R24: =N24*K24 -> 0 | S24: =O24*K24 -> 0 | T24: =P24*K24 -> 0 | U24: =SUM(R24+S24+T24) -> 0
A25: 5V | C25: S-band Tx | D25: PULSAR-STX | E25: Tx | F25: 5 | G25: =J25/5 -> 0.122 | H25: =K25/5 -> 0.54 | I25: =L25/5 -> 1 | J25: 0.61 | K25: 2.7 | L25: 5 | N25: 0 | O25: 0 | P25: 1 | R25: =N25*K25 -> 0 | S25: =O25*K25 -> 0 | T25: =P25*L25 -> 5 | U25: =SUM(R25+S25+T25) -> 5
Q26: total power consumption | R26: =SUM(R5:R25)/Y15 -> 4.4505556 | S26: =SUM(S5:S25)/Y15 -> 4.5777778 | T26: =SUM(T5:T25)/Y15 -> 17.412778 | U26: =SUM(R26+S26+T26) -> 26.441111 | V26: W | W26: worst case
Q27: Generated Energy(orbit average) | R27: =1.135*20*N4/3600 -> 23.041233 | S27: 0 | T27: 0 | U27: =SUM(R27+S27+T27) -> 23.041233 | V27: Wh
Q28: Required Energy (orbit average) | R28: =R26*N4/3600 -> 4.5174575 | S28: =S26*O4/3600 -> 1.731759 | T28: =T26*P4/3600 -> 3.1971795 | U28: =SUM(R28+S28+T28) -> 9.446396 | V28: Wh
Q29: Power Margin Value (orbit average) | R29: =U27-U28 -> 13.594837 | U29: =SUM(R29+S29+T29) -> 13.594837 | V29: Wh
Q30: Power Margin (orbit average) | R30: =100*($U$27/U28-1) -> 143.91559 | U30: =SUM(R30+S30+T30) -> 143.91559 | V30: %
Q31: Residual/Generation | R31: =U29/$U$27*100 -> 59.002211 | U31: =SUM(R31+S31+T31) -> 59.002211 | V31: % | W31: >40%
Q32: charging rate | R32: =(R27-R28)/40*100 -> 46.309438 | S32: =(S27-S28)/40*100 -> -4.3293974 | T32: =(T27-T28)/40*100 -> -7.9929487 | U32: =SUM(R32+S32+T32) -> 33.987091 | V32: %
X33: DET | Y33: Stand-by | Z33: sum
X34: 1 | Y34: 0
W35: GEN | X35: =1.135*(6*3+6*3+4*3+4*3)/(3+3+3+3+1+1)*N4/3600*X34 -> 4.937407 | Y35: =R27*Y34 -> 0 | Z35: =X35+Y35 -> 4.937407
W36: CON | X36: =1.498*X34 -> 1.498 | Y36: =U28*Y34 -> 0 | Z36: =X36+Y36 -> 1.498
W37: G-C | Z37: =Z35-Z36 -> 3.439407

Sheet ③ 2주기(S-band)
A2: channel | B2: Subsystem | C2: Component | D2: Product | E2: Mode | F2: Voltage Input | G2: Current(A) | J2: Power | N2: Duty(%) | Q2: Consumption Power (W) | X2: Note
G3: Idle | H3: Nominal | I3: Peak | J3: Idel | K3: Nominal | L3: Peak | M3: Mode | N3: Stand-by(D) | O3: Stand-by(N) | P3: S-band COM | R3: Stand-by(D) | S3: Stand-by(N) | T3: S-band COM | U3: Total | X3: Orbit period | Y3: =parameter!C8 -> 5676.9849
M4: Time | N4: =Y6-Y4 -> 2973.1162 | O4: =Y7 -> 2022.8687 | P4: =Y4 -> 681 | X4: Missiond period | Y4: 681
A5: 5V(1) | B5: PAYS | F5: 5 | H5: =K5/F5 -> 0.04 | K5: 0.2 | N5: 0 | O5: 0 | P5: 0 | R5: =N5*K5 -> 0 | S5: =O5*K5 -> 0 | T5: =P5*K5 -> 0 | U5: =SUM(R5+S5+T5) -> 0 | X5: S-band period | Y5: 661
A6: 5V(2) | B6: PAYR | F6: 5 | H6: =K6/F6 -> 0.04 | I6: =L6/F6 -> 0.4 | K6: 0.2 | L6: 2 | N6: 0 | O6: 0 | P6: =N6*K6 -> 0 | R6: =N6*K6 -> 0 | S6: =O6*K6 -> 0 | T6: =P6*K6 -> 0 | U6: =SUM(R6+S6+T6) -> 0 | X6: sunlight | Y6: =parameter!C10 -> 3654.1162
A7: 3.3V(3) | F7: 3.3 | H7: =K7/F7 -> 0.060606061 | I7: =L7/F7 -> 0.60606061 | K7: 0.2 | L7: 2 | N7: 0 | O7: 0 | P7: =N7*K7 -> 0 | R7: =N7*K7 -> 0 | S7: =O7*K7 -> 0 | T7: =P7*K7 -> 0 | U7: =SUM(R7+S7+T7) -> 0 | X7: Eclipse | Y7: =parameter!C11 -> 2022.8687
A8: 3.3V(2) | B8: PAYC | C8: Cam | D8: NanoCam - 70 mm | F8: 3.3 | G8: 0.115 | H8: 0.242 | I8: 0.394 | J8: =F8*G8 -> 0.3795 | K8: 0.8 | L8: =I8*F8 -> 1.3002 | N8: 0 | O8: 0 | P8: 0 | R8: =N8*K8 -> 0 | S8: =O8*K8 -> 0 | T8: =P8*L8 -> 0 | U8: =SUM(R8+S8+T8) -> 0 | X8: solar panel efficiency | Y8: 0.3
A9: 3.3V | B9: ADCS | C9: ADCS module | D9: Cubecomputer | F9: 3.3 | H9: =0.12/F9 -> 0.036363636 | I9: =0.2/F9 -> 0.060606061 | K9: =H9*F9 -> 0.12 | L9: =I9*F9 -> 0.2 | N9: 1 | O9: 1 | P9: 1 | R9: =N9*K9 -> 0.12 | S9: =O9*K9 -> 0.12 | T9: =P9*$L$9+(1-P9)*K9 -> 0.2 | U9: =SUM(R9+S9+T9) -> 0.44 | X9: Emppt | Y9: 0.6
D10: Cubesense V3 x 2 | F10: 3.3 | H10: =0.2/F10 -> 0.060606061 | I10: =0.4/F10 -> 0.12121212 | K10: =H10*F10 -> 0.2 | L10: =I10*F10 -> 0.4 | N10: 1 | O10: 0.5 | P10: 1 | R10: =N10*K10 -> 0.2 | S10: =O10*K10 -> 0.1 | T10: =P10*$L$10+(1-P10)*K10 -> 0.4 | U10: =SUM(R10+S10+T10) -> 0.7 | X10: Etmp | Y10: 0.8
A11: 5V | D11: CubeTorquers rod | F11: 5 | H11: =0.07*5/5 -> 0.07 | I11: =0.167*5/5 -> 0.167 | K11: =H11*F11 -> 0.35 | L11: =I11*F11 -> 0.835 | N11: 1 | O11: 1 | P11: 1 | R11: =N11*K11 -> 0.35 | S11: =O11*K11 -> 0.35 | T11: =P11*$L$11+(1-P11)*K11 -> 0.835 | U11: =SUM(R11+S11+T11) -> 1.535 | X11: Eman | Y11: 0.8
D12: CubeTorquers coil | F12: 5 | H12: 0.064 | K12: =H12*F12 -> 0.32 | N12: 1 | O12: 1 | P12: 1 | R12: =N12*K12 -> 0.32 | S12: =O12*K12 -> 0.32 | T12: =P12*$K$12 -> 0.32 | U12: =SUM(R12+S12+T12) -> 0.96
A13: 3.3V | D13: Cubecontrol | F13: 3.3 | H13: =0.2/F13 -> 0.060606061 | K13: =H13*F13 -> 0.2 | N13: 1 | O13: 1 | P13: 1 | R13: =N13*K13 -> 0.2 | S13: =O13*K13 -> 0.2 | T13: =P13*$K$13 -> 0.2 | U13: =SUM(R13+S13+T13) -> 0.6
D14: CubeMag | F14: 3.3 | H14: =0.035/F14 -> 0.010606061 | K14: =H14*F14 -> 0.035 | N14: 1 | O14: 1 | P14: 1 | R14: =N14*K14 -> 0.035 | S14: =O14*K14 -> 0.035 | T14: =P14*$K$14 -> 0.035 | U14: =SUM(R14+S14+T14) -> 0.105 | X14: Depth of Discharge | Y14: 0.2
A15: VBAT | D15: Wheel x 3 | F15: 8.26 | G15: =0.065*3/F15 -> 0.023607748 | H15: =0.19*3/F15 -> 0.069007264 | I15: =2.3*3/F15 -> 0.83535109 | J15: =F15*G15 -> 0.195 | K15: =H15*F15 -> 0.57 | L15: =I15*F15 -> 6.9 | N15: 1 | O15: 1 | P15: 1 | R15: =N15*K15 -> 0.57 | S15: =O15*K15 -> 0.57 | T15: =P15*$L$15+(1-P15)*K15 -> 6.9 | U15: =SUM(R15+S15+T15) -> 8.04 | X15: Conversion Efficiency | Y15: 0.9
A16: 3.3V | C16: GPS antenna | D16: TW1829 | F16: 3.3 | H16: 0 | K16: 0 | N16: 1 | O16: 1 | P16: 1 | R16: =N16*K16 -> 0 | S16: =O16*K16 -> 0 | T16: =P16*K16 -> 0 | U16: =SUM(R16+S16+T16) -> 0 | X16: required margin | Y16: 0.4
A17: 3.3V(1) | C17: GPS Rx | D17: OEM719 | F17: 3.3 | H17: 0.394 | K17: 1.3 | N17: 1 | O17: 1 | P17: 1 | R17: =N17*K17 -> 1.3 | S17: =O17*K17 -> 1.3 | T17: =P17*K17 -> 1.3 | U17: =SUM(R17+S17+T17) -> 3.9
B18: EPS | C18: Battery | D18: Optimus-40 | K18: 0.1 | N18: 1 | O18: 1 | P18: 1 | R18: =N18*K18 -> 0.1 | S18: =O18*K18 -> 0.1 | T18: =P18*K18 -> 0.1 | U18: =SUM(R18+S18+T18) -> 0.3
C19: PCDU | D19: Starbuck-Nano-Plus | K19: 0.2 | N19: 1 | O19: 1 | P19: 1 | R19: =N19*K19 -> 0.2 | S19: =O19*K19 -> 0.2 | T19: =P19*K19 -> 0.2 | U19: =SUM(R19+S19+T19) -> 0.6
C20: Solar cell | D20: GOMspace | K20: =H20*F20 -> 0 | N20: 1 | O20: 1 | P20: 1 | R20: =N20*K20 -> 0 | S20: =O20*K20 -> 0 | T20: =P20*K20 -> 0 | U20: =SUM(R20+S20+T20) -> 0
A21: 3.3V | B21: CNDH | C21: OBC | D21: NST | F21: 3.3 | H21: =0.13 -> 0.13 | K21: =H21*F21 -> 0.429 | N21: 1 | O21: 1 | P21: 1 | R21: =N21*K21 -> 0.429 | S21: =O21*K21 -> 0.429 | T21: =P21*L21 -> 0 | U21: =SUM(R21+S21+T21) -> 0.858
A22: 3.3V | B22: COMS | C22: UHF antenna | D22: ISIS | F22: 3.3 | H22: =0.04/F22 -> 0.012121212 | I22: =2/F22 -> 0.60606061 | K22: =H22*F22 -> 0.04 | L22: =I22*F22 -> 2 | N22: 0 | O22: 0 | P22: 0 | R22: =N22*K22 -> 0 | S22: =O22*K22 -> 0 | T22: =P22*K22 -> 0 | U22: =SUM(R22+S22+T22) -> 0
C23: UHF TRx | D23: NanoCom AX100 | E23: Rx | F23: 3.3 | G23: 0.045 | H23: 0.055 | I23: 0.12 | J23: =F23*G23 -> 0.1485 | K23: =H23*F23 -> 0.1815 | L23: =I23*F23 -> 0.396 | N23: 1 | O23: 1 | P23: 1 | R23: =N23*K23 -> 0.1815 | S23: =O23*L23 -> 0.396 | T23: =P23*K23 -> 0.1815 | U23: =SUM(R23+S23+T23) -> 0.759
E24: Tx | F24: 3.3 | G24: 0.6 | I24: 1 | J24: =F24*G24 -> 1.98 | L24: =I24*F24 -> 3.3 | N24: =1-N23 -> 0 | O24: =1-O23 -> 0 | P24: =1-P23 -> 0 | R24: =N24*K24 -> 0 | S24: =O24*K24 -> 0 | T24: =P24*K24 -> 0 | U24: =SUM(R24+S24+T24) -> 0
A25: 5V | C25: S-band Tx | D25: PULSAR-STX | E25: Tx | F25: 5 | G25: =J25/5 -> 0.122 | H25: =K25/5 -> 0.54 | I25: =L25/5 -> 1 | J25: 0.61 | K25: 2.7 | L25: 5 | N25: 0 | O25: 0 | P25: 1 | R25: =N25*K25 -> 0 | S25: =O25*K25 -> 0 | T25: =P25*L25 -> 5 | U25: =SUM(R25+S25+T25) -> 5
Q26: total power consumption | R26: =SUM(R5:R25)/Y15 -> 4.4505556 | S26: =SUM(S5:S25)/Y15 -> 4.5777778 | T26: =SUM(T5:T25)/Y15 -> 17.412778 | U26: =SUM(R26+S26+T26) -> 26.441111 | V26: W | W26: worst case
Q27: Generated Energy(orbit average) | R27: =1.135*20*N4/3600 -> 18.747149 | S27: 0 | T27: 0 | U27: =SUM(R27+S27+T27) -> 18.747149 | V27: Wh
Q28: Required Energy (orbit average) | R28: =R26*N4/3600 -> 3.6755608 | S28: =S26*O4/3600 -> 2.5722898 | T28: =T26*P4/3600 -> 3.2939171 | U28: =SUM(R28+S28+T28) -> 9.5417677 | V28: Wh
Q29: Power Margin Value (orbit average) | R29: =U27-U28 -> 9.2053815 | U29: =SUM(R29+S29+T29) -> 9.2053815 | V29: Wh
Q30: Power Margin (orbit average) | R30: =100*($U$27/U28-1) -> 96.474592 | U30: =SUM(R30+S30+T30) -> 96.474592 | V30: %
Q31: Residual/Generation | R31: =U29/$U$27*100 -> 49.102834 | U31: =SUM(R31+S31+T31) -> 49.102834 | V31: % | W31: >40%
Q32: charging rate | R32: =(R27-R28)/40*100 -> 37.678971 | S32: =(S27-S28)/40*100 -> -6.4307246 | T32: =(T27-T28)/40*100 -> -8.2347928 | U32: =SUM(R32+S32+T32) -> 23.013454 | V32: %
X33: DET | Y33: Stand-by | Z33: sum
X34: 0.1 | Y34: 0.9
W35: GEN | X35: =1.135*(6*3+6*3+4*3+4*3)/(3+3+3+3+1+1)*N4/3600*X34 -> 0.40172463 | Y35: =R27*Y34 -> 16.872434 | Z35: =X35+Y35 -> 17.274159
W36: CON | X36: =1.498*X34 -> 0.1498 | Y36: =U28*Y34 -> 8.587591 | Z36: =X36+Y36 -> 8.737391
W37: G-C | Z37: =Z35-Z36 -> 8.536768

Sheet ④ 그 외
A2: channel | B2: Subsystem | C2: Component | D2: Product | E2: Mode | F2: Voltage Input | G2: Current(A) | J2: Power | N2: Duty(%) | Q2: Consumption Power (W) | X2: Note
G3: Idle | H3: Nominal | I3: Peak | J3: Idel | K3: Nominal | L3: Peak | M3: Mode | N3: Stand-by(D) | O3: Stand-by(N) | R3: Stand-by(D) | S3: Stand-by(N) | T3: Total | X3: Orbit period | Y3: =parameter!C8 -> 5676.9849
M4: Time | N4: =Y6 -> 3654.1162 | O4: =Y7 -> 2022.8687 | X4: Missiond period | Y4: 681
A5: 5V(1) | B5: PAYS | F5: 5 | H5: =K5/F5 -> 0.04 | K5: 0.2 | N5: 0 | O5: 0 | R5: =N5*K5 -> 0 | S5: =O5*K5 -> 0 | T5: =SUM(Q5+R5+S5) -> 0 | X5: S-band period | Y5: 661
A6: 5V(2) | B6: PAYR | F6: 5 | H6: =K6/F6 -> 0.04 | I6: =L6/F6 -> 0.4 | K6: 0.2 | L6: 2 | N6: 0 | O6: 0 | R6: =N6*K6 -> 0 | S6: =O6*K6 -> 0 | T6: =SUM(Q6+R6+S6) -> 0 | X6: sunlight | Y6: =parameter!C10 -> 3654.1162
A7: 3.3V(3) | F7: 3.3 | H7: =K7/F7 -> 0.060606061 | I7: =L7/F7 -> 0.60606061 | K7: 0.2 | L7: 2 | N7: 0 | O7: 0 | R7: =N7*K7 -> 0 | S7: =O7*K7 -> 0 | T7: =SUM(Q7+R7+S7) -> 0 | X7: Eclipse | Y7: =parameter!C11 -> 2022.8687
A8: 3.3V(2) | B8: PAYC | C8: Cam | D8: NanoCam - 70 mm | F8: 3.3 | G8: 0.115 | H8: 0.242 | I8: 0.394 | J8: =F8*G8 -> 0.3795 | K8: 0.8 | L8: =I8*F8 -> 1.3002 | N8: 0 | O8: 0 | R8: =N8*K8 -> 0 | S8: =O8*K8 -> 0 | T8: =SUM(Q8+R8+S8) -> 0 | X8: solar panel efficiency | Y8: 0.3
A9: 3.3V | B9: ADCS | C9: ADCS module | D9: Cubecomputer | F9: 3.3 | H9: =0.12/F9 -> 0.036363636 | I9: =0.2/F9 -> 0.060606061 | K9: =H9*F9 -> 0.12 | L9: =I9*F9 -> 0.2 | N9: 1 | O9: 1 | R9: =N9*K9 -> 0.12 | S9: =O9*K9 -> 0.12 | T9: =SUM(Q9+R9+S9) -> 0.24 | X9: Emppt | Y9: 0.6
D10: Cubesense V3 x 2 | F10: 3.3 | H10: =0.2/F10 -> 0.060606061 | I10: =0.4/F10 -> 0.12121212 | K10: =H10*F10 -> 0.2 | L10: =I10*F10 -> 0.4 | N10: 1 | O10: 0.5 | R10: =N10*K10 -> 0.2 | S10: =O10*K10 -> 0.1 | T10: =SUM(Q10+R10+S10) -> 0.3 | X10: Etmp | Y10: 0.8
A11: 5V | D11: CubeTorquers rod | F11: 5 | H11: =0.07*5/5 -> 0.07 | I11: =0.167*5/5 -> 0.167 | K11: =H11*F11 -> 0.35 | L11: =I11*F11 -> 0.835 | N11: 1 | O11: 1 | R11: =N11*K11 -> 0.35 | S11: =O11*K11 -> 0.35 | T11: =SUM(Q11+R11+S11) -> 0.7 | X11: Eman | Y11: 0.8
D12: CubeTorquers coil | F12: 5 | H12: 0.064 | K12: =H12*F12 -> 0.32 | N12: 1 | O12: 1 | R12: =N12*K12 -> 0.32 | S12: =O12*K12 -> 0.32 | T12: =SUM(Q12+R12+S12) -> 0.64
A13: 3.3V | D13: Cubecontrol | F13: 3.3 | H13: =0.2/F13 -> 0.060606061 | K13: =H13*F13 -> 0.2 | N13: 1 | O13: 1 | R13: =N13*K13 -> 0.2 | S13: =O13*K13 -> 0.2 | T13: =SUM(Q13+R13+S13) -> 0.4
D14: CubeMag | F14: 3.3 | H14: =0.035/F14 -> 0.010606061 | K14: =H14*F14 -> 0.035 | N14: 1 | O14: 1 | R14: =N14*K14 -> 0.035 | S14: =O14*K14 -> 0.035 | T14: =SUM(Q14+R14+S14) -> 0.07 | X14: Depth of Discharge | Y14: 0.2
A15: VBAT | D15: Wheel x 3 | F15: 8.26 | G15: =0.065*3/F15 -> 0.023607748 | H15: =0.19*3/F15 -> 0.069007264 | I15: =2.3*3/F15 -> 0.83535109 | J15: =F15*G15 -> 0.195 | K15: =H15*F15 -> 0.57 | L15: =I15*F15 -> 6.9 | N15: 1 | O15: 1 | R15: =N15*K15 -> 0.57 | S15: =O15*K15 -> 0.57 | T15: =SUM(Q15+R15+S15) -> 1.14 | X15: Conversion Efficiency | Y15: 0.9
A16: 3.3V | C16: GPS antenna | D16: TW1829 | F16: 3.3 | H16: 0 | K16: =H16*F16 -> 0 | N16: 1 | O16: 1 | R16: =N16*K16 -> 0 | S16: =O16*K16 -> 0 | T16: =SUM(Q16+R16+S16) -> 0 | X16: required margin | Y16: 0.4
A17: 3.3V(1) | C17: GPS Rx | D17: OEM719 | F17: 3.3 | H17: 0.394 | K17: 1.3 | N17: 1 | O17: 1 | R17: =N17*K17 -> 1.3 | S17: =O17*K17 -> 1.3 | T17: =SUM(Q17+R17+S17) -> 2.6
B18: EPS | C18: Battery | D18: Optimus-40 | K18: 0.1 | N18: 1 | O18: 1 | R18: =N18*K18 -> 0.1 | S18: =O18*K18 -> 0.1 | T18: =SUM(Q18+R18+S18) -> 0.2
C19: PCDU | D19: Starbuck-Nano-Plus | K19: 0.2 | N19: 1 | O19: 1 | R19: =N19*K19 -> 0.2 | S19: =O19*K19 -> 0.2 | T19: =SUM(Q19+R19+S19) -> 0.4
C20: Solar cell | D20: GOMspace | K20: =H20*F20 -> 0 | N20: 1 | O20: 1 | R20: =N20*K20 -> 0 | S20: =O20*K20 -> 0 | T20: =SUM(Q20+R20+S20) -> 0
A21: 3.3V | B21: CNDH | C21: OBC | D21: NST | F21: 3.3 | H21: =0.13 -> 0.13 | K21: =H21*F21 -> 0.429 | N21: 1 | O21: 1 | R21: =N21*K21 -> 0.429 | S21: =O21*K21 -> 0.429 | T21: =SUM(Q21+R21+S21) -> 0.858
A22: 3.3V | B22: COMS | C22: UHF antenna | D22: ISIS | F22: 3.3 | H22: =0.04/F22 -> 0.012121212 | I22: =2/F22 -> 0.60606061 | K22: =H22*F22 -> 0.04 | L22: =I22*F22 -> 2 | N22: 0 | O22: 0 | R22: =N22*K22 -> 0 | S22: =O22*K22 -> 0 | T22: =SUM(Q22+R22+S22) -> 0
C23: UHF TRx | D23: NanoCom AX100 | E23: Rx | F23: 3.3 | G23: 0.045 | H23: 0.055 | I23: 0.12 | J23: =F23*G23 -> 0.1485 | K23: =H23*F23 -> 0.1815 | L23: =I23*F23 -> 0.396 | N23: 0.9 | O23: 0.9 | R23: =N23*K23 -> 0.16335 | S23: =O23*L23 -> 0.3564 | T23: =SUM(Q23+R23+S23) -> 0.51975
E24: Tx | F24: 3.3 | G24: 0.6 | I24: 1 | J24: =F24*G24 -> 1.98 | L24: =I24*F24 -> 3.3 | N24: =1-N23 -> 0.1 | O24: =1-O23 -> 0.1 | R24: =N24*K24 -> 0 | S24: =O24*K24 -> 0 | T24: =SUM(Q24+R24+S24) -> 0
A25: 5V | C25: S-band Tx | D25: PULSAR-STX | E25: Tx | F25: 5 | G25: =J25/5 -> 0.122 | H25: =K25/5 -> 0.54 | I25: =L25/5 -> 1 | J25: 0.61 | K25: 2.7 | L25: 5 | N25: 0 | O25: 0 | R25: =N25*K25 -> 0 | S25: =O25*K25 -> 0 | T25: =SUM(Q25+R25+S25) -> 0
Q26: total power consumption | R26: =SUM(R5:R24)/Y15 -> 4.4303889 | S26: =SUM(S5:S24)/Y15 -> 4.5337778 | T26: =SUM(R26+S26) -> 8.9641667 | U26: W | V26: worst case
Q27: Generated Energy(orbit average) | R27: =1.135*20*N4/3600 -> 23.041233 | S27: 0 | T27: =SUM(R27+S27) -> 23.041233 | U27: Wh
Q28: Required Energy (orbit average) | R28: =R26*N4/3600 -> 4.4969877 | S28: =S26*O4/3600 -> 2.5475659 | T28: =SUM(R28+S28) -> 7.0445536 | U28: Wh
Q29: Power Margin Value (orbit average) | R29: =T27-T28 -> 15.996679 | T29: =SUM(R29+S29) -> 15.996679 | U29: Wh
Q30: Power Margin (orbit average) | R30: =100*($T$27/T28-1) -> 227.07868 | T30: =SUM(R30+S30) -> 227.07868 | U30: %
Q31: Residual/Generation | R31: =T29/$T$27*100 -> 69.426316 | T31: =SUM(R31+S31) -> 69.426316 | U31: % | V31: >40%
Q32: charging rate | R32: =(R27-R28)/40*100 -> 46.360612 | S32: =(S27-S28)/40*100 -> -6.3689147 | T32: =SUM(R32+S32) -> 39.991697 | U32: %
W33: DET | X33: Stand-by | Y33: sum
W34: 1 | X34: 0
V35: GEN | W35: =1.135*(6*3+6*3+4*3+4*3)/(3+3+3+3+1+1)*N4/3600*W34 -> 4.937407 | X35: =R27*X34 -> 0 | Y35: =W35+X35 -> 4.937407
V36: CON | W36: =1.498*W34 -> 1.498 | X36: =T28*X34 -> 0 | Y36: =W36+X36 -> 1.498
V37: G-C | Y37: =Y35-Y36 -> 3.439407

Sheet parameter
B2: parameter
B4: attitdue (km) | C4: 500 | E4: LTAN | F4: 22 | G4: 0 | H4: 3.3343
B5: Beta angle(deg) | C5: =INDEX(G4:H28,MATCH(F4,G4:G28,0),2) -> 30.893332 | G5: 1 | H5: -10.271498
B6: Earth Gravitational Standard Cosntant (km3/sec2) | C6: 398600 | G6: 2 | H6: -23.52829
B7: Earth Effective Radius (km) | C7: 6378.14 | G7: 3 | H7: -36.118151
B8: orbital period (sec) | C8: =2*PI()*SQRT(($C$7+$C$4)^3/$C$6) -> 5676.9849 | G8: 4 | H8: -47.400155
G9: 5 | H9: -56.011314
B10: sunlight (sec) | C10: =IF(C5<ASIN(C7/(C7+C4))*180/PI(),(360-2*ASIN((((1/COS(C5*PI()/180))^2)*(((C7/(C7+C4))^2-(SIN(C5*PI()/180))^2)))^0.5)*180/PI())/360*C8,C8) -> 3654.1162 | G10: 6 | H10: -59.5711
B11: Eclipse (sec) | C11: =C8-C10 -> 2022.8687 | G11: 7 | H11: -56.42613
B12: conversion efficiency (%) | C12: =90 -> 90 | G12: 8 | H12: -48.06262
G13: 9 | H13: -36.902156
B14: DoD reference | C14: 0.2 | G14: 10 | H14: -24.372771
B15: Conversion Efficiency | C15: 0.9 | G15: 11 | H15: -11.147553
B16: required margin | C16: 0.4 | G16: 12 | H16: 2.4420052
G17: 13 | H17: 16.205457
G18: 14 | H18: 29.998123
G19: 15 | H19: 43.647692
G20: 16 | H20: 56.810927
G21: 17 | H21: 68.422001
G22: 18 | H22: 74.371379
G23: 19 | H23: 69.058097
G24: 20 | H24: 57.633973
G25: 21 | H25: 44.524976
G26: 22 | H26: 30.893332
G27: 23 | H27: 17.103945
G28: 24 | H28: 3.3343

Sheet Sheet1
A1: After sun-pointing, charging magnitude | E1: =Detumbling!#REF!-Detumbling!#REF! -> #REF! | H1: Wh
A2: SoC after sun-pointing | E2: =E1/40*100 -> #REF! | H2: %
A3: Need Orbit number for Full charge | E3: =100/E2 -> #REF! | H3: N
A4: SoC after sun-pointing 6 orbit | E4: =IF(E2*6>100,100,E2*6) -> #REF! | H4: %
A5: After mission or S-band COM,charging magnitude | F5: =40*$E$4/100-Detumbling!#REF! -> #REF! | G5: =40*$E$4/100-Detumbling!#REF! -> #REF! | H5: Wh
A6: SoC after mission or S-band COM | F6: =F5/40*100 -> #REF! | G6: =G5/40*100 -> #REF! | H6: % | I6: > 40 %
A7: SoC after mission or S-band COM except margin | F7: =F5/40*100-40 -> #REF! | G7: =G5/40*100-40 -> #REF! | H7: % | I7: > 40 %
A8: Peak load | C8: 3.3V | E8: =(Detumbling!#REF!+Detumbling!#REF!+Detumbling!#REF!+Detumbling!#REF!+Detumbling!#REF!+Detumbling!#REF!+Detumbling!#REF!+Detumbling!#REF!+Detumbling!#REF!+Detumbling!#REF!+Detumbling!#REF!+Detumbling!#REF!)/3.3 -> #REF! | F8: =(Detumbling!#REF!+Detumbling!#REF!+Detumbling!#REF!+Detumbling!#REF!+Detumbling!#REF!+Detumbling!#REF!+Detumbling!#REF!+Detumbling!#REF!+Detumbling!#REF!+Detumbling!#REF!+Detumbling!#REF!+Detumbling!#REF!)/3.3 -> #REF! | G8: =(Detumbling!#REF!+Detumbling!#REF!+Detumbling!#REF!+Detumbling!#REF!+Detumbling!#REF!+Detumbling!#REF!+Detumbling!#REF!+Detumbling!#REF!+Detumbling!#REF!+Detumbling!#REF!+Detumbling!#REF!+Detumbling!#REF!)/3.3 -> #REF! | I8: < 4.5 A
C9: 5.0V | E9: =(Detumbling!#REF!+Detumbling!#REF!+Detumbling!#REF!+Detumbling!#REF!+Detumbling!#REF!)/5 -> #REF! | F9: =(Detumbling!#REF!+Detumbling!#REF!+Detumbling!#REF!+Detumbling!#REF!+Detumbling!#REF!)/5 -> #REF! | G9: =(Detumbling!#REF!+Detumbling!#REF!+Detumbling!#REF!+Detumbling!#REF!+Detumbling!#REF!)/5 -> #REF! | I9: < 4.5 A
C10: Vbat | E10: =(Detumbling!#REF!+Detumbling!#REF!+Detumbling!#REF!)/8.26 -> #REF! | F10: =(Detumbling!#REF!+Detumbling!#REF!+Detumbling!#REF!)/8.26 -> #REF! | G10: =(Detumbling!#REF!+Detumbling!#REF!+Detumbling!#REF!)/8.26 -> #REF! | I10: < 4.7 A

Sheet Sheet2
B1: 1주기 | C1: 2주기 | D1: 3주기 | E1: 4주기 | F1: 5주기 | G1: 6주기 | H1: 7주기 | I1: 8주기 | J1: 9주기 | K1: 10주기 | L1: 11주기 | M1: 12주기 | N1: 13주기 | O1: 14주기 | P1: 15주기
B2: 0 (0s)
B3: 1367s
A5: Start Index(Time) | B5: 139 (1367s) | C5: 710 (7043s) | D5: 1279 (12713s) | E5: 1849 (18388s) | F5: 2416 (24055s) | G5: 2985 (29728s) | H5: 3556 (35403s) | I5: 4126 (41077s) | J5: 4696 (46750s) | K5: 5265 (52422s) | L5: 5834 (58093s) | M5: 6404 (63766s) | N5: 6972 (69435s) | O5: 7543 (75108s) | P5: 8114 (80782s)
B6: 3653s | C6: 510s | D6: 3652s | E6: 3649s | F6: 3653s | G6: 3654s | H6: 3649s | I6: 3650s | J6: 3646s | K6: 3650s | L6: 3651s | M6: 3649s | N6: 3654s | O6: 3652s | P6: 3650s
A7: Start Mission & ComD | C7: 761 (7552s)
C8: 681s
A9: End Mission & ComD | C9: 829 (8232s)
C10: 2458s
A11: Eclipse | B11: 507 (5019s) | C11: 1075 (10689s) | D11: 1646 (16364s) | E11: 2214 (22036s) | F11: 2782 (27707s) | G11: 3353 (33381s) | H11: 3922 (39051s) | I11: 4493 (44726s) | J11: 5061 (50395s) | K11: 5631 (56071s) | L11: 6201 (61743s) | M11: 6769 (67414s) | N11: 7340 (73088s) | O11: 7911 (78759s) | P11: 8482 (84431s)
B12: 2015s | C12: 2025s | D12: 2015s | E12: 2010s | F12: 2015s | G12: 2014s | H12: 2018s | I12: 935s | J12: 2018s | K12: 2014s | L12: 2024s | M12: 2016s | N12: 2014s | O12: 2014s | P12: 1970s
A13: Start ComN | I13: 4587 (45660s)
I14: 661s | P14: 8680 (86400s)
A15: End ComN | I15: 4653 (46320s)
I16: 421s
A17: End | B17: 709 (7033s) | C17: 1278 (12713s) | D17: 1848 (18378s) | E17: 2415 (24045s) | F17: 2984 (29721s) | G17: 3555 (35394s) | H17: 4125 (41068s) | I17: 4695 (46740s) | J17: 5264 (52412s) | K17: 5833 (58084s) | L17: 6403 (63766s) | M17: 6971 (69429s) | N17: 7542 (75101s) | O17: 8113 (80773s)
A18: Total Time(sec) | B18: 1367+5668 | C18: 5674 | D18: 5667 | E18: 5659 | F18: 5668 | G18: 5668 | H18: 5667 | I18: 5667 | J18: 5664 | K18: 5664 | L18: 5675 | M18: 5665 | N18: 5668 | O18: 5667 | P18: 5620
A19: Power Generation(Wh) | B19: 23.041 | C19: 18.747 | D19: 23.041 | E19: 23.041 | F19: 23.041 | G19: 23.041 | H19: 23.041 | I19: 23.041 | J19: 23.041 | K19: 23.041 | L19: 23.041 | M19: 23.041 | N19: 23.041 | O19: 23.041 | P19: 23.041
A20: Power Consumption(Wh) | B20: 6.596 | C20: 9.45 | D20: 6.596 | E20: 6.596 | F20: 6.596 | G20: 6.596 | H20: 6.596 | I20: 9.244 | J20: 6.596 | K20: 6.596 | L20: 6.596 | M20: 6.596 | N20: 6.596 | O20: 6.596 | P20: 8.3952
A21: Gen-Cons(Wh) | B21: =B19-B20 -> 16.445 | C21: =C19-C20 -> 9.297 | D21: =D19-D20 -> 16.445 | E21: =E19-E20 -> 16.445 | F21: =F19-F20 -> 16.445 | G21: =G19-G20 -> 16.445 | H21: =H19-H20 -> 16.445 | I21: =I19-I20 -> 13.797 | ... P21: =P19-P20 -> 14.6458
B26: 0 (0s)
B27: 1367s
A29: Start Index(Time) | B29: 139 (1367s) | C29: 710 (7043s) | D29: 1279 (12713s) | E29: 1849 (18388s) | F29: 2416 (24055s) | G29: 2985 (29728s) | H29: 3556 (35403s) | I29: 4126 (41077s) | J29: 4696 (46750s) | K29: 5265 (52422s) | L29: 5834 (58093s) | M29: 6404 (63766s) | N29: 6972 (69435s) | O29: 7543 (75108s) | P29: 8114 (80782s)
B30: 3653s | C30: 510s | D30: 3652s | E30: 3649s | F30: 3653s | G30: 3654s | H30: 3649s | I30: 3650s | J30: 3646s | K30: 3650s | L30: 3651s | M30: 3649s | N30: 3654s | O30: 3652s | P30: 3650s
A31: Start Mission & ComD | C31: 761 (7552s)
C32: 681s
A33: End Mission & ComD | C33: 829 (8232s)
C34: 2458s
A35: Eclipse | B35: 507 (5019s) | C35: 1075 (10689s) | D35: 1646 (16364s) | E35: 2214 (22036s) | F35: 2782 (27707s) | G35: 3353 (33381s) | H35: 3922 (39051s) | I35: 4493 (44726s) | J35: 5061 (50395s) | K35: 5631 (56071s) | L35: 6201 (61743s) | M35: 6769 (67414s) | N35: 7340 (73088s) | O35: 7911 (78759s) | P35: 8482 (84431s)
B36: 2015s | C36: 2025s | D36: 2015s | E36: 2010s | F36: 2015s | G36: 2014s | H36: 2018s | I36: 935s | J36: 2018s | K36: 2014s | L36: 2024s | M36: 2016s | N36: 2014s | O36: 2014s | P36: 1970s
A37: Start ComN | I37: 4587 (45660s)
I38: 661s | P38: 8680 (86400s)
A39: End ComN | I39: 4653 (46320s)
I40: 421s
A41: End | B41: 709 (7033s) | C41: 1278 (12713s) | D41: 1848 (18378s) | E41: 2415 (24045s) | F41: 2984 (29721s) | G41: 3555 (35394s) | H41: 4125 (41068s) | I41: 4695 (46740s) | J41: 5264 (52412s) | K41: 5833 (58084s) | L41: 6403 (63766s) | M41: 6971 (69429s) | N41: 7542 (75101s) | O41: 8113 (80773s)
A42: Total Time(sec) | B42: 1367+5668 | C42: 5674 | D42: 5667 | E42: 5659 | F42: 5668 | G42: 5668 | H42: 5667 | I42: 5667 | J42: 5664 | K42: 5664 | L42: 5675 | M42: 5665 | N42: 5668 | O42: 5667 | P42: 5620
A43: Power Generation(Wh) | B43: 23.041 | C43: 18.747 | D43: 23.041 | E43: 23.041 | F43: 23.041 | G43: 23.041 | H43: 23.041 | I43: 23.041 | J43: 23.041 | K43: 23.041 | L43: 23.041 | M43: 23.041 | N43: 23.041 | O43: 23.041 | P43: 23.041
A44: Power Consumption(Wh) | B44: 6.596 | C44: 9.45 | D44: 6.596 | E44: 6.596 | F44: 6.596 | G44: 6.596 | H44: 6.596 | I44: 9.244 | J44: 6.596 | K44: 6.596 | L44: 6.596 | M44: 6.596 | N44: 6.596 | O44: 6.596 | P44: 3.56
A45: Gen-Cons(Wh) | B45: =B43-B44 -> 16.445 | C45: =C43-C44 -> 9.297 | D45: =D43-D44 -> 16.445 | E45: =E43-E44 -> 16.445 | F45: =F43-F44 -> 16.445 | G45: =G43-G44 -> 16.445 | H45: =H43-H44 -> 16.445 | I45: =I43-I44 -> 13.797 | ... P45: =P43-P44 -> 19.481
A47: Dayside | B47: =B43*A48 -> 20.7369 | C47: =C43*A48 -> 16.8723 | D47: =D43*A48 -> 20.7369 | E47: =E43*A48 -> 20.7369 | F47: =F43*A48 -> 20.7369 | G47: =G43*A48 -> 20.7369 | H47: =H43*A48 -> 20.7369 | I47: =I43*A48 -> 20.7369 | J47: =J43*A48 -> 20.7369 | K47: =K43*A48 -> 20.7369 | L47: =L43*A48 -> 20.7369 | M47: =M43*A48 -> 20.7369 | N47: =N43*A48 -> 20.7369 | O47: =O43*A48 -> 20.7369 | P47: =P43*A48 -> 20.7369
...

Sheet 0(new)
B2: Subsystem | C2: Module | E2: Product | F2: Note | G2: Manufacturer | H2: channel | I2: Mode | J2: Voltage Input | K2: Current(A) | N2: Power | R2: Duty(%) | S2: Consumption Power (W) | W2: Note
K3: Idle | L3: Nominal | M3: Peak | N3: Idel | O3: Nominal | P3: Peak | Q3: Mode | R3: Detumbling | T3: Detumbling | W3: Orbit period | X3: =parameter!C8 -> 5676.9849
Q4: Time | R4: =X3 -> 5676.9849 | T4: =X3 -> 5676.9849 | W4: Missiond period | X4: 681
B5: EPS | D5: Battery | E5: Optimus-40 | F5: When heater active | G5: AAC Clyde space | O5: 0.8 | R5: 1 | T5: =R5*O5 -> 0.8 | W5: S-band period | X5: 661
D6: PCDU | E6: Starbuck-Nano-Plus | R6: 1 | T6: =R6*O6 -> 0 | W6: sunlight | X6: =parameter!C10 -> 3654.1162
C7: MSP | D7: Solar cell | E7: 3G30C-Advanced | G7: AZURSPACE | R7: 1 | T7: =R7*O7 -> 0 | W7: Eclipse | X7: =parameter!C11 -> 2022.8687
B8: GNC(ADCS) | D8: CSS(with Solar panel) | E8: Coarse Sun Sensors | G8: GOMSPACE | H8: 3.3V | J8: 3.3 | L8: 0.00093 | O8: =J8*L8 -> 0.003069 | R8: 1 | T8: =R8*O8 -> 0.003069 | W8: solar panel efficiency | X8: 0.3
C9: ADCS Module | D9: CSS(TBD) | E9: Coarse Sun Sensors | F9: Coarse Sun Sensor x 10 | G9: CUBESPACE | J9: 3.3 | L9: =O9/J9 -> 0.0015151515 | O9: 0.005 | R9: 1 | T9: =R9*O9 -> 0.005 | W9: Emppt | X9: 0.6
D10: CUBECOM | E10: Cubecomputer | J10: 3.3 | L10: =O10/J10 -> 0.036363636 | M10: =P10/J10 -> 0.060606061 | O10: 0.12 | P10: 0.2 | R10: 1 | T10: =R10*O10 -> 0.12 | W10: Etmp | X10: 0.8
D11: FSS | E11: Cubesense V3 x 2 | J11: 3.3 | L11: =O11/J11 -> 0.060606061 | M11: =P11/J11 -> 0.12121212 | O11: 0.2 | P11: 0.4 | R11: 1 | T11: =R11*O11 -> 0.2 | W11: Eman | X11: 0.8
E12: Cubecontrol | I12: Typ | J12: 3.3 | L12: =O12/J12 -> 0.060606061 | O12: 0.2 | R12: =100%-R13 -> 1 | T12: =R12*O12 -> 0.2 | W12: Depth of Discharge | X12: 0.2
F13: Include Momentum Wheel | I13: Momentum wheel | J13: 3.3 | L13: =O13/J13 -> 0.086363636 | M13: =P13/J13 -> 0.13333333 | O13: 0.285 | P13: 0.44 | R13: =R16 -> 0 | W13: Conversion Efficiency | X13: 0.9
D14: MMT | E14: CubeMag | F14: Deployable Magnetometer | I14: Typ | J14: 3.3 | L14: =O14/J14 -> 0.010606061 | O14: 0.035 | R14: 1 | T14: =R14*O14 -> 0.035 | W14: required margin | X14: 0.4
F15: Circuit activate for 5s (0.62Ax8V) | G15: CUBESPACE | H15: VBAT(1) | I15: Deployment mag | J15: 8 | L15: 0.62 | O15: =J15*L15 -> 4.96
D16: RWA | E16: Cube Wheel Medium x 3 | G16: CUBESPACE | H16: VBAT(2) | J16: 8.26 | K16: =0.065*3/J16 -> 0.023607748 | L16: =0.19*3/J16 -> 0.069007264 | M16: =2.3*3/J16 -> 0.83535109 | N16: 0.065 | O16: 0.19 | P16: 2.3 | R16: 0 | T16: =O16*R16 -> 0
D19: MTQ | E19: CubeTorquers rod | F19: Small Rod x 2 | G19: CUBESPACE | H19: 5V | J19: 5 | L19: =0.07*2 -> 0.14 | M19: =0.167*2 -> 0.334 | O19: =L19*J19 -> 0.7 | P19: =M19*J19 -> 1.67 | R19: 0 | T19: =R19*O19 -> 0
E20: CubeTorquers coil | F20: Coil x 1 | J20: 5 | L20: 0.064 | O20: =L20*J20 -> 0.32 | R20: 0 | T20: =R20*O20 -> 0
D21: GPS ANT | E21: TW1829 | F21: Low Noise Amplifier | G21: TALLYSMAN | H21: 3.3V | J21: 3.3 | L21: =O21/J21 -> 0.0036363636 | O21: 0.012 | R21: 1 | T21: =R21*O21 -> 0.012
D22: GPS Rx | E22: OEM719 | G22: NovAtel | H22: 3.3V(1) | J22: 3.3 | L22: =O22/J22 -> 0.39393939 | O22: 1.3 | R22: 0 | T22: =R22*O22 -> 0
B23: CNDH | D23: OBC | E23: HYVRID OBC | G23: NST | H23: 3.3V | J23: 3.3 | L23: =0.13 -> 0.13 | O23: =L23*J23 -> 0.429 | R23: 1 | T23: =R23*O23 -> 0.429
B24: COMS | D24: UHF ANT | E24: Deployable Antenna System | G24: ISIS | H24: 3.3V | I24: stowed | J24: 3.3 | L24: 0.013 | O24: =L24*J24 -> 0.0429 | R24: 1 | T24: =R24*O24 -> 0.0429
F25: Typical Deployment Duration < 3s | I25: deployed | J25: 3.3 | L25: 0.011 | O25: =L25*J25 -> 0.0363
F26: During Deployment 2W Power Consumption | I26: deployment | J26: 3.3 | L26: 0.55 | O26: =L26*J26 -> 1.815
D27: UHF TRx | E27: NanoCom AX100 | G27: GOMSPACE | I27: Rx | J27: 3.3 | K27: 0.045 | L27: 0.055 | M27: 0.12 | N27: =J27*K27 -> 0.1485 | O27: =L27*J27 -> 0.1815 | P27: =M27*J27 -> 0.396 | R27: 1 | T27: =R27*O27 -> 0.1815
F28: extreme temperature : -30℃~+85℃ | I28: Tx | J28: 3.3 | K28: 0.6 | L28: 0.8 | M28: 1 | N28: =J28*K28 -> 1.98 | O28: =L28*J28 -> 2.64 | P28: =M28*J28 -> 3.3 | R28: =100%-R27 -> 0 | T28: =R28*O28 -> 0
F29: Transmitter with adjustable 24 to 30 dBm output power
D30: S-band ANT | E30: PULSAR-SANT | G30: AAC Clyde space | H30: 5V | J30: 5 | L30: 0 | O30: 0 | R30: 0 | T30: =R30*O30 -> 0
D31: S-band Tx | E31: PULSAR-STX | I31: Idle(OFF) | J31: 5 | L31: =O31/5 -> 0.122 | O31: 0.61 | R31: 0 | T31: =R31*O31 -> 0
I32: 24dBM RF | J32: 5 | L32: =O32/5 -> 0.54 | O32: 2.7 | R32: 0 | T32: =R32*O32 -> 0
I33: 30dBM RF | J33: 5 | L33: =O33/5 -> 0.92 | M33: =P33/5 -> 1 | O33: 4.6 | P33: 5 | R33: 0 | T33: =R33*O33 -> 0
B34: PAYS | C34: PAYS | D34: PAYS | E34: 레이저 감지기 | G34: Ophir | H34: 5V(2) | J34: 5 | L34: =O34/J34 -> 0.2 | O34: 1 | R34: 0 | T34: =R34*O34 -> 0
C35: PAYR | D35: PAYR | E35: 박막전개장치 | G35: in-house | H35: 5V(1) | J35: 5 | L35: =O35/J35 -> 0.2 | O35: 1 | R35: 0 | T35: =R35*O35 -> 0
D36: PAYR | E36: 박막전개장치 | G36: in-house | H36: 3.3V(3) | J36: 3.3 | M36: =P36/J36 -> 0.60606061 | P36: 2 | R36: 0 | T36: =R36*O36 -> 0
C37: PAYC | D37: PAYC | E37: Nanocam C1U | F37: Peak Power = 3.6V x 500mA @ Max | G37: GOMSPACE | H37: 3.3V(2) | J37: 3.3 | K37: =N37/J37 -> 0.11515152 | L37: =O37/J37 -> 0.24242424 | M37: =P37/J37 -> 0.54545455 | N37: 0.38 | O37: 0.8 | P37: 1.8 | R37: 0 | T37: =R37*O37 -> 0
S38: total power consumption | T38: =SUM(T5:T37)/X13 -> 2.2538544 | U38: W | V38: worst case
S39: Generated Energy(orbit average) | T39: =1.135*(6*3+6*3+4*3+4*3)/(3+3+3+3+1+1)*X6/3600 -> 4.937407 | U39: Wh
S40: Required Energy (orbit average) | T40: =T38*X3/3600 -> 3.5541938 | U40: Wh
S41: Power Margin Value | T41: =T39-T40 -> 1.3832132 | U41: Wh
S42: Power Margin | T42: =100*($T$39/T40-1) -> 38.917777 | U42: %
S43: Residual/Generation | T43: =T41/$T$39*100 -> 28.014972 | U43: % | V43: >40%
...

Sheet 1(new)
B2: Subsystem | C2: Module | E2: Product | F2: Note | G2: Manufacturer | H2: channel | I2: Mode | J2: Voltage Input | K2: Current(A) | N2: Power | R2: Duty(%) | U2: Consumption Power (W) | AB2: Note
K3: Idle | L3: Nominal | M3: Peak | N3: Idel | O3: Nominal | P3: Peak | Q3: Mode | R3: Stand-by(D) | S3: Stand-by(N) | T3: Mission & UHF COM | V3: Stand-by(D) | W3: Stand-by(N) | X3: Mission & UHF COM | Y3: total (time rate) | AB3: Orbit period | AC3: =parameter!C8 -> 5676.9849
Q4: Time | R4: =AC6-AC4 -> 2973.1162 | S4: =AC7 -> 2022.8687 | T4: =AC4 -> 681 | V4: =AC6-AC4 -> 2973.1162 | W4: =AC7 -> 2022.8687 | X4: =AC4 -> 681 | Y4: =V4+W4+X4 -> 5676.9849 | AB4: Missiond period | AC4: 681
B5: EPS | D5: Battery | E5: Optimus-40 | F5: When heater active | G5: AAC Clyde space | O5: 0.8 | R5: 1 | S5: 1 | T5: 1 | V5: =R5*O5 -> 0.8 | W5: =O5*S5 -> 0.8 | X5: =O5*T5 -> 0.8 | Y5: =(V5*2973.11618+W5*2022.86871+X5*681)/5676.98489 -> 0.8 | AB5: S-band period | AC5: 661
D6: PCDU | E6: Starbuck-Nano-Plus | R6: 1 | S6: 1 | T6: 1 | V6: =R6*O6 -> 0 | W6: =O6*S6 -> 0 | X6: =O6*T6 -> 0 | Y6: =(V6*2973.11618+W6*2022.86871+X6*681)/5676.98489 -> 0 | AB6: sunlight | AC6: =parameter!C10 -> 3654.1162
C7: MSP | D7: Solar cell | E7: 3G30C-Advanced | G7: AZURSPACE | R7: 1 | S7: 1 | T7: 1 | V7: =R7*O7 -> 0 | W7: =O7*S7 -> 0 | X7: =O7*T7 -> 0 | Y7: =(V7*2973.11618+W7*2022.86871+X7*681)/5676.98489 -> 0 | AB7: Eclipse | AC7: =parameter!C11 -> 2022.8687
B8: GNC(ADCS) | D8: CSS(with Solar panel) | E8: Coarse Sun Sensors | G8: GOMSPACE | H8: 3.3V | J8: 3.3 | L8: 0.00093 | O8: =J8*L8 -> 0.003069 | R8: 1 | S8: 1 | T8: 1 | V8: =R8*O8 -> 0.003069 | W8: =O8*S8 -> 0.003069 | X8: =O8*T8 -> 0.003069 | Y8: =(V8*2973.11618+W8*2022.86871+X8*681)/5676.98489 -> 0.003069 | AB8: solar panel efficiency | AC8: 0.3
C9: ADCS Module | D9: CSS(TBD) | E9: Coarse Sun Sensors | F9: Coarse Sun Sensor x 10 | G9: CUBESPACE | J9: 3.3 | L9: =O9/J9 -> 0.0015151515 | O9: 0.005 | R9: 1 | S9: 1 | T9: 1 | V9: =R9*O9 -> 0.005 | W9: =O9*S9 -> 0.005 | X9: =O9*T9 -> 0.005 | Y9: =(V9*2973.11618+W9*2022.86871+X9*681)/5676.98489 -> 0.005 | AB9: Emppt | AC9: 0.6
D10: CUBECOM | E10: Cubecomputer | J10: 3.3 | L10: =O10/J10 -> 0.036363636 | M10: =P10/J10 -> 0.060606061 | O10: 0.12 | P10: 0.2 | R10: 1 | S10: 1 | T10: 1 | V10: =R10*O10 -> 0.12 | W10: =O10*S10 -> 0.12 | X10: =P10*T10 -> 0.2 | Y10: =(V10*2973.11618+W10*2022.86871+X10*681)/5676.98489 -> 0.12959664 | AB10: Etmp | AC10: 0.8
D11: FSS | E11: Cubesense V3 x 2 | J11: 3.3 | L11: =O11/J11 -> 0.060606061 | M11: =P11/J11 -> 0.12121212 | O11: 0.2 | P11: 0.4 | R11: 1 | S11: 1 | T11: 1 | V11: =R11*O11 -> 0.2 | W11: =O11*S11 -> 0.2 | X11: =P11*T11 -> 0.4 | Y11: =(V11*2973.11618+W11*2022.86871+X11*681)/5676.98489 -> 0.22399161 | AB11: Eman | AC11: 0.8
E12: Cubecontrol | I12: Typ | J12: 3.3 | L12: =O12/J12 -> 0.060606061 | O12: 0.2 | R12: =100%-R13 -> 0 | S12: =100%-S13 -> 0 | T12: =100%-T13 -> 0 | V12: =R12*O12 -> 0 | W12: =O12*S12 -> 0 | X12: =T12*P12 -> 0 | Y12: =(V12*2973.11618+W12*2022.86871+X12*681)/5676.98489 -> 0 | AB12: Depth of Discharge | AC12: 0.2
F13: Include Momentum Wheel | I13: Momentum wheel | J13: 3.3 | L13: =O13/J13 -> 0.086363636 | M13: =P13/J13 -> 0.13333333 | O13: 0.285 | P13: 0.44 | R13: =R16 -> 1 | S13: =S16 -> 1 | T13: =T16 -> 1 | V13: =R13*O13 -> 0.285 | W13: =O13*S13 -> 0.285 | X13: =P13*T13 -> 0.44 | Y13: =(V13*2973.11618+W13*2022.86871+X13*681)/5676.98489 -> 0.3035935 | AB13: Conversion Efficiency | AC13: 0.9
D14: MMT | E14: CubeMag | F14: Deployable Magnetometer | I14: Typ | J14: 3.3 | L14: =O14/J14 -> 0.010606061 | O14: 0.035 | R14: 1 | S14: 1 | T14: 1 | V14: =R14*O14 -> 0.035 | W14: =O14*S14 -> 0.035 | X14: =T14*O14 -> 0.035 | Y14: =(V14*2973.11618+W14*2022.86871+X14*681)/5676.98489 -> 0.035 | AB14: required margin | AC14: 0.4
F15: Circuit activate for 5s (0.62Ax8V) | G15: CUBESPACE | H15: VBAT(1) | I15: Deployment mag | J15: 8 | L15: 0.62 | O15: =J15*L15 -> 4.96
D16: RWA | E16: Cube Wheel Medium x 3 | G16: CUBESPACE | H16: VBAT(2) | J16: 8.26 | K16: =0.065*3/J16 -> 0.023607748 | L16: =0.19*3/J16 -> 0.069007264 | M16: =2.3*3/J16 -> 0.83535109 | N16: 0.065 | O16: 0.19 | P16: 2.3 | R16: 1 | S16: 1 | T16: 1 | V16: =R16*O16 -> 0.19 | W16: =O16*S16 -> 0.19 | X16: =P16*T16 -> 2.3 | Y16: =(V16*2973.11618+W16*2022.86871+X16*681)/5676.98489 -> 0.44311147
D19: MTQ | E19: CubeTorquers rod | F19: Small Rod x 2 | G19: CUBESPACE | H19: 5V | J19: 5 | L19: =0.07*2 -> 0.14 | M19: =0.167*2 -> 0.334 | O19: =L19*J19 -> 0.7 | P19: =M19*J19 -> 1.67 | R19: 0 | S19: 0 | T19: 0 | V19: =R19*O19 -> 0 | W19: =S19*O19 -> 0 | X19: =T19*O19 -> 0 | Y19: =(V19*2973.11618+W19*2022.86871+X19*681)/5676.98489 -> 0
E20: CubeTorquers coil | F20: Coil x 1 | J20: 5 | L20: 0.064 | O20: =L20*J20 -> 0.32 | R20: 0 | S20: 0 | T20: 0 | V20: =R20*O20 -> 0 | W20: =S20*O20 -> 0 | X20: =T20*O20 -> 0 | Y20: =(V20*2973.11618+W20*2022.86871+X20*681)/5676.98489 -> 0
D21: GPS ANT | E21: TW1829 | F21: Low Noise Amplifier | G21: TALLYSMAN | H21: 3.3V | J21: 3.3 | L21: =O21/J21 -> 0.0036363636 | O21: 0.012 | R21: 1 | S21: 1 | T21: 1 | V21: =R21*O21 -> 0.012 | W21: =S21*O21 -> 0.012 | X21: =T21*O21 -> 0.012 | Y21: =(V21*2973.11618+W21*2022.86871+X21*681)/5676.98489 -> 0.012
D22: GPS Rx | E22: OEM719 | G22: NovAtel | H22: 3.3V(1) | J22: 3.3 | L22: =O22/J22 -> 0.39393939 | O22: 1.3 | R22: 0.5 | S22: 0.5 | T22: 1 | V22: =R22*O22 -> 0.65 | W22: =S22*O22 -> 0.65 | X22: =T22*O22 -> 1.3 | Y22: =(V22*2973.11618+W22*2022.86871+X22*681)/5676.98489 -> 0.72797273
B23: CNDH | D23: OBC | E23: HYVRID OBC | G23: NST | H23: 3.3V | J23: 3.3 | L23: =0.13 -> 0.13 | O23: =L23*J23 -> 0.429 | R23: 1 | S23: 1 | T23: 1 | V23: =R23*O23 -> 0.429 | W23: =S23*O23 -> 0.429 | X23: =T23*O23 -> 0.429 | Y23: =(V23*2973.11618+W23*2022.86871+X23*681)/5676.98489 -> 0.429
B24: COMS | D24: UHF ANT | E24: Deployable Antenna System | G24: ISIS | H24: 3.3V | I24: stowed | J24: 3.3 | L24: 0.013 | O24: =L24*J24 -> 0.0429 | V24: =R24*O24 -> 0 | W24: =S24*O24 -> 0 | X24: =T24*O24 -> 0 | Y24: =(V24*2973.11618+W24*2022.86871+X24*681)/5676.98489 -> 0
F25: Typical Deployment Duration < 3s | I25: deployed | J25: 3.3 | L25: 0.011 | O25: =L25*J25 -> 0.0363 | R25: 1 | S25: 1 | T25: 1 | V25: =R25*O25 -> 0.0363 | W25: =S25*O25 -> 0.0363 | X25: =T25*O25 -> 0.0363 | Y25: =(V25*2973.11618+W25*2022.86871+X25*681)/5676.98489 -> 0.0363
F26: During Deployment 2W Power Consumption | I26: deployment | J26: 3.3 | L26: 0.55 | O26: =L26*J26 -> 1.815 | V26: =R26*O26 -> 0 | W26: =S26*O26 -> 0 | X26: =T26*O26 -> 0 | Y26: =(V26*2973.11618+W26*2022.86871+X26*681)/5676.98489 -> 0
D27: UHF TRx | E27: NanoCom AX100 | G27: GOMSPACE | I27: Rx | J27: 3.3 | K27: 0.045 | L27: 0.055 | M27: 0.12 | N27: =J27*K27 -> 0.1485 | O27: =L27*J27 -> 0.1815 | P27: =M27*J27 -> 0.396 | R27: 0.9 | S27: 0.9 | T27: 0.8 | V27: =R27*O27 -> 0.16335 | W27: =S27*O27 -> 0.16335 | X27: =T27*P27 -> 0.3168 | Y27: =(V27*2973.11618+W27*2022.86871+X27*681)/5676.98489 -> 0.18175756
F28: extreme temperature : -30℃~+85℃ | I28: Tx | J28: 3.3 | K28: 0.6 | L28: 0.8 | M28: 1 | N28: =J28*K28 -> 1.98 | O28: =L28*J28 -> 2.64 | P28: =M28*J28 -> 3.3 | R28: =100%-R27 -> 0.1 | S28: =100%-S27 -> 0.1 | T28: =100%-T27 -> 0.2 | V28: =R28*O28 -> 0.264 | W28: =S28*O28 -> 0.264 | X28: =T28*P28 -> 0.66 | Y28: =(V28*2973.11618+W28*2022.86871+X28*681)/5676.98489 -> 0.31150339
F29: Transmitter with adjustable 24 to 30 dBm output power
D30: S-band ANT | E30: PULSAR-SANT | G30: AAC Clyde space | H30: 5V | J30: 5 | L30: 0 | O30: 0 | R30: 0 | S30: 0 | T30: 0 | V30: =R30*O30 -> 0 | W30: =S30*O30 -> 0 | X30: =T30*O30 -> 0 | Y30: =(V30*2973.11618+W30*2022.86871+X30*681)/5676.98489 -> 0
D31: S-band Tx | E31: PULSAR-STX | I31: Idle(OFF) | J31: 5 | L31: =O31/5 -> 0.122 | O31: 0.61 | R31: 0 | S31: 0 | T31: 0 | V31: =R31*O31 -> 0 | W31: =S31*O31 -> 0 | X31: =T31*O31 -> 0 | Y31: =(V31*2973.11618+W31*2022.86871+X31*681)/5676.98489 -> 0
I32: 24dBM RF | J32: 5 | L32: =O32/5 -> 0.54 | O32: 2.7 | R32: 0 | S32: 0 | T32: 0 | V32: =R32*O32 -> 0 | W32: =S32*O32 -> 0 | X32: =T32*O32 -> 0 | Y32: =(V32*2973.11618+W32*2022.86871+X32*681)/5676.98489 -> 0
I33: 30dBM RF | J33: 5 | L33: =O33/5 -> 0.92 | M33: =P33/5 -> 1 | O33: 4.6 | P33: 5 | R33: 0 | S33: 0 | T33: 0 | V33: =R33*O33 -> 0 | W33: =S33*O33 -> 0 | X33: =T33*P33 -> 0 | Y33: =(V33*2973.11618+W33*2022.86871+X33*681)/5676.98489 -> 0
B34: PAYS | C34: PAYS | D34: PAYS | E34: 레이저 감지기 | G34: Ophir | H34: 5V(2) | J34: 5 | L34: =O34/J34 -> 0.2 | O34: 1 | R34: 0 | S34: 0 | T34: 1 | V34: =R34*O34 -> 0 | W34: =S34*O34 -> 0 | X34: =T34*O34 -> 1 | Y34: =(V34*2973.11618+W34*2022.86871+X34*681)/5676.98489 -> 0.11995804
C35: PAYR | D35: PAYR | E35: 박막전개장치 | G35: in-house | H35: 5V(1) | J35: 5 | L35: =O35/J35 -> 0.2 | O35: 1 | R35: 0 | S35: 0 | T35: 1 | V35: =R35*O35 -> 0 | W35: =S35*O35 -> 0 | X35: =T35*O35 -> 1 | Y35: =(V35*2973.11618+W35*2022.86871+X35*681)/5676.98489 -> 0.11995804
D36: PAYR | E36: 박막전개장치 | G36: in-house | H36: 3.3V(3) | J36: 3.3 | M36: =P36/J36 -> 0.60606061 | P36: 2 | R36: 0 | S36: 0 | T36: 0 | V36: =R36*O36 -> 0 | W36: =S36*O36 -> 0 | X36: =T36*P36 -> 0 | Y36: =(V36*2973.11618+W36*2022.86871+X36*681)/5676.98489 -> 0
C37: PAYC | D37: PAYC | E37: Nanocam C1U | F37: Peak Power = 3.6V x 500mA @ Max | G37: GOMSPACE | H37: 3.3V(2) | J37: 3.3 | K37: =N37/J37 -> 0.11515152 | L37: =O37/J37 -> 0.24242424 | M37: =P37/J37 -> 0.54545455 | N37: 0.38 | O37: 0.8 | P37: 1.8 | R37: 0 | S37: 0 | T37: 1 | V37: =R37*O37 -> 0 | W37: =S37*O37 -> 0 | X37: =T37*P37 -> 1.8 | Y37: =(V37*2973.11618+W37*2022.86871+X37*681)/5676.98489 -> 0.21592448
U38: total power consumption | V38: =SUM(V5:V37)/0.9 -> 3.5474656 | W38: =SUM(W5:W37)/0.9 -> 3.5474656 | X38: =SUM(X5:X37)/0.9 -> 11.930188 | Y38: =SUM(Y5:Y37)/0.9 -> 4.5530405 | Z38: W | AA38: worst case
U39: Generated Energy(orbit average) | V39: =1.135*20*R4/3600 -> 18.747149 | W39: 0 | X39: 0 | Y39: =V39+W39+X39 -> 18.747149 | Z39: Wh
U40: Required Energy (orbit average) | V40: =V38*R4/3600 -> 2.9297298 | W40: =W38*S4/3600 -> 1.9933492 | X40: =X38*T4/3600 -> 2.2567939 | Y40: =V40+W40+X40 -> 7.1798728 | Z40: Wh
U41: Power Margin Value | V41: =Y39-Y40 -> 11.567276 | Y41: =V41+W41+X41 -> 11.567276 | Z41: Wh
U42: Power Margin | V42: =100*(Y39/Y40-1) -> 161.10698 | Y42: =V42+W42+X42 -> 161.10698 | Z42: %
U43: Residual/Generation | V43: =V41/$V$39*100 -> 61.701522 | Y43: =V43+W43+X43 -> 61.701522 | Z43: % | AA43: >40%
...

Sheet 2(new)
B2: Subsystem | C2: Module | E2: Product | F2: Note | G2: Manufacturer | H2: channel | I2: Mode | J2: Voltage Input | K2: Current(A) | N2: Power | R2: Duty(%) | U2: Consumption Power (W) | AB2: Note
K3: Idle | L3: Nominal | M3: Peak | N3: Idel | O3: Nominal | P3: Peak | Q3: Mode | R3: Stand-by(D) | S3: Stand-by(N) | T3: S-band COM | V3: Stand-by(D) | W3: Stand-by(N) | X3: S-band COM | Y3: total | AB3: Orbit period | AC3: =parameter!C8 -> 5676.9849
Q4: Time | R4: =AC6 -> 3654.1162 | S4: =AC7-AC5 -> 1361.8687 | T4: =AC5 -> 661 | V4: =AC6 -> 3654.1162 | W4: =AC7-AC5 -> 1361.8687 | X4: =AC5 -> 661 | Y4: =V4+W4+X4 -> 5676.9849 | AB4: Missiond period | AC4: 681
B5: EPS | D5: Battery | E5: Optimus-40 | F5: When heater active | G5: AAC Clyde space | O5: 0.8 | R5: 1 | S5: 1 | T5: 1 | V5: =R5*O5 -> 0.8 | W5: =O5*S5 -> 0.8 | X5: =O5*T5 -> 0.8 | Y5: =(V5*3654.116178+W5*1361.868711+X5*661)/5676.98489 -> 0.8 | AB5: S-band period | AC5: 661
D6: PCDU | E6: Starbuck-Nano-Plus | R6: 1 | S6: 1 | T6: 1 | V6: =R6*O6 -> 0 | W6: =O6*S6 -> 0 | X6: =O6*T6 -> 0 | Y6: =(V6*3654.116178+W6*1361.868711+X6*661)/5676.98489 -> 0 | AB6: sunlight | AC6: =parameter!C10 -> 3654.1162
C7: MSP | D7: Solar cell | E7: 3G30C-Advanced | G7: AZURSPACE | R7: 1 | S7: 1 | T7: 1 | V7: =R7*O7 -> 0 | W7: =O7*S7 -> 0 | X7: =O7*T7 -> 0 | Y7: =(V7*3654.116178+W7*1361.868711+X7*661)/5676.98489 -> 0 | AB7: Eclipse | AC7: =parameter!C11 -> 2022.8687
B8: GNC(ADCS) | D8: CSS(with Solar panel) | E8: Coarse Sun Sensors | G8: GOMSPACE | H8: 3.3V | J8: 3.3 | L8: 0.00093 | O8: =J8*L8 -> 0.003069 | R8: 1 | S8: 1 | T8: 1 | V8: =R8*O8 -> 0.003069 | W8: =O8*S8 -> 0.003069 | X8: =O8*T8 -> 0.003069 | Y8: =(V8*3654.116178+W8*1361.868711+X8*661)/5676.98489 -> 0.003069 | AB8: solar panel efficiency | AC8: 0.3
C9: ADCS Module | D9: CSS(TBD) | E9: Coarse Sun Sensors | F9: Coarse Sun Sensor x 10 | G9: CUBESPACE | J9: 3.3 | L9: =O9/J9 -> 0.0015151515 | O9: 0.005 | R9: 1 | S9: 1 | T9: 1 | V9: =R9*O9 -> 0.005 | W9: =O9*S9 -> 0.005 | X9: =O9*T9 -> 0.005 | Y9: =(V9*3654.116178+W9*1361.868711+X9*661)/5676.98489 -> 0.005 | AB9: Emppt | AC9: 0.6
