Workbook

Sheet Requirements Description
B2: HSLD : Requirement Description
B4: I | C4: Requirement Summary
B5: Lv0 | C5: 전체 임무 목적
B6: Lv1 | C6: 기술적 임무 목적
B7: Lv2-1 | C7: 기술적 임무 목적 달성을 위한 임무요구조건
B8: Lv2-2 | C8: 큐브위성경연대회 과제 수행에 필요한 일반적인 임무요구조건
B9: Lv3 | C9: 모든 서브시스템에 요구되는 조건이나 관리자레벨에서 결정이 필요한 사항(지상국 등록 여부 등) 시스템 요구조건
B10: Lv4 | C10: 각 서브시스템 요구조건 (하드웨어 제외, 미션 요구조건, 시스템 요구조건에서 임무, 제어 등 소프트웨어상 내용위주, 예: RWA 3개 필요-제어알고리즘을 위해)
B11: Lv5 | C11: 각 서브시스템 의 파트별 요구조건 (하드웨어 위주, Lv3의 모든 부품에 해당하는 내용이 하위 항목으로 들어감, 예: RWA 전력소모는 ~W 이하여야 함)
B13: II | C13: 작성요령
B14: ID | C14: 각 요구조건에 고유 ID 부여, SE가 부여 후, 숫자만 추후 변경
B15: Title | C15: 각 요구조건 내용을 요약하는 영어 (키워드)
B16: Reqirement | C16: 요구조건을 정확한 내용 및 수치로 입력 (예: 2U 엄폐위성은 각 축 5 deg 이하의 절대자세제어 정밀도를 가진다)
... B25: III | C25: 유의사항
B26: 형식
B27: 내용 | C27: 각 요구조건의 모든항목을 작성해야함
B28: 수정 | C28: 각 서브시스템 수정사항은 통합 시 내용 반영을 위해 빨간글씨로 표시
B30: IV | C30: 기초 참고문헌
B31: REF. 1 | C31: 기술제안문서
B32: REF. 2
B33: REF. 3
B34: REF. 4
B35: REF. 5
B36: REF. 6

Sheet Revision
B2: Revision # | C2: Date | D2: Author | E2: Description
B3: 1 | C3: 44427 | D3: Soyoun Won | E3: Draft mission and system requirements
B4: 2 | C4: 44428 | D4: DaeEun Kang | E4: Edit mission and system requirements
B5: 3 | C5: 44444 | D5: Soyoun Won | E5: Update Level 3 system requirement and Level 4 subsystem requirement
B6: 4 | C6: 44445 | D6: DaeEun Kang | E6: Edit Level 3 system requirement and Level 4 subsystem requirement
B7: 5 | C7: 44469 | D7: Soyoung Won | E7: Add Requirements TMO-003
B8: 6 | C8: 44494 | D8: Soyoung Won | E8: Edit Payload requirement
B9: 7
B10: 8
B11: 9
B12: 10

Sheet Mission
B1: width 10 | C1: width 30 | E1: width 10 | F1: width 30 | G1: width5 | H1: width5 | I1: width5 | J1: width5 | K1: width5
A2: height25 | B2: LEVEL 0 | C2: 전체 임무 목적 (Entire Mission Objective, EMO) | F2: Verification 내용 | G2: Verification Method | K2: 확인
B3: ID | C3: Title | D3: Requirement | E3: Rationale | G3: A | H3: I | I3: T | J3: D
B4: EMO-001 | C4: 기술검증 | D4: 차세대 우주물체 정밀 추적 및 능동대응 체계의 운용성 확인을 위한 검증용 큐브위성을 설계 및 제작하고 큐브위성 운영 기술을 개발하여야 함 | E4: ='Requirements Description'!B31 -> REF. 1 | F4: - | G4: O
B7: LEVEL 1 | C7: 시험지원장비 참고시험 방안 (Special Test Plan, STP) | F7: Verification 내용 | G7: Verification Method | K7: 확인
B8: ID | C8: Title | D8: Requirement | E8: Rationale | G8: A | H8: I | I8: T | J8: D
B9: STP-001 | C9: Tracking ability test | D9: 큐브위성 추적을 통해 획득한 거리정보와 위성 탑재 GNSS 데이터를 통해 획득한 거리 정보간의 차이를 확인함 | E9: ='Requirements Description'!B31 -> REF. 1
B10: STP-002 | C10: Traceable Object test | D10: 큐브위성에 탑재한 태양돛을 통해 위성 추적 가능 여부 확인 (참고기준 : 1m x 1m 이하 @ 500km) | E10: ='Requirements Description'!B31 -> REF. 1
B11: STP-003 | C11: Orbit prediction precision test | D11: 큐브위성 추적을 통해 획득한 거리 정보를 사용한 궤도 예측치와 실측치를 비교함 | E11: ='Requirements Description'!B31 -> REF. 1
B12: STP-004 | C12: Laser Dazzling active Defense test | D12: 저궤도에서 운용 중인 큐브위성을 대즐링하여 획득한 결과를 영상으로 수신, 분석하여 능동대응 여부 확인 | E12: REF. 1
B15: LEVEL 2 | C15: 시험지원장비 요구조건 (Test support equipment, TSE) | F15: Verification 내용 | G15: Verification Method | K15: 확인
B16: ID | C16: Title | D16: Requirement | E16: Rationale | G16: A | H16: I | I16: T | J16: D
B17: TSE-001 | C17: Safe Operation | D17: 큐브위성시스템은 차세대 우주물체 정밀 추적시스템 및 레이저 대즐링 능동방어 시스템의 성능검증 시험이 안정적으로 시행될 수 있도록 설계되어야 함 | E17: =B4 -> EMO-001
B18: TSE-002 | C18: Link | D18: 큐브위성시스템은 차세대 우주물체 정밀 추적시스템 및 레이저 대즐링 능동방어 시스템과 연동되어야 함 | E18: =B4 -> EMO-001
B19: TSE-003 | C19: Misstion Life time | D19: 큐브위성시스템의 임무 수명은 6개월 이상이어야 함 | E19: =B4 -> EMO-001
B20: TSE-004 | C20: Altitude | D20: 큐브위성시스템은 고도 500km 전후에서 운용되어야 함 | E20: =B10 -> STP-002
B21: TSE-005 | C21: Deployment Size | D21: 큐브위성시스템은 최소 1m x 1m 박막을 궤도상에서 전개가 가능하여야 함 | E21: =B10 -> STP-002
B22: TSE-006 | C22: GNSS Raw Data | D22: 큐브위성시스템은 GNSS 원시데이터를 지상으로 송신할 수 있어야 함 | E22: =B9 -> STP-001
B23: TSE-007 | C23: On-board Navigation | D23: 큐브위성시스템의 항법정확도는 10m [TBC] (3σ, 각축) 이내이어야 함 | E23: =B11 -> STP-003
B24: TSE-008 | C24: Dazzling Verification | D24: 큐브위성시스템은 파장대역 520nm - 590nm 와 630 nm - 690nm [TBC]의 대즐링 상황식별을 위한 영상 촬영이 가능하여야 함 | E24: =B12 -> STP-004
B25: TSE-009 | C25: SLR Laser Detection | D25: 큐브위성시스템은 파장대역 532nm 와 1064nm [TBC]의 SLR레이저 검출이 가능하여야 함 | E25: =B11 -> STP-003
B26: TSE-010 | C26: Storage Duration | D26: 큐브위성시스템은 개발 완료 후 최소 12개월 [TBD] 동안 지상 보관 후에도 정상 작동하여야 함 | E26: =B4 -> EMO-001
B27: TSE-011 | C27: Development Cleanness | D27: 큐브위성시스템의 개발장소는 청정도 10000 class 이하를 유지하여야 함 | E27: =B4 -> EMO-001
B28: TSE-012 | C28: CubeSat Design Spec. | D28: 큐브위성시스템은 3U 큐브위성 규격을 따라야 함 | E28: =B4 -> EMO-001
B29: TSE-013 | C29: Autononmous Operation | D29: 큐브위성시스템은 임무일정동안 임무를 자율적으로 수행하여야 함 | E29: =B4 -> EMO-001
B30: TSE-014 | C30: Ground Station | D30: 큐브위성시스템 운용을 위한 지상국은 큐브위성의 상태정보와 임무 정보를 내려받고, 명령을 올릴 수 있어야 함 | E30: =B4 -> EMO-001
B31: TSE-015 | C31: Launch System | D31: 큐브위성시스템은 발사체의 요구조건을 만족하여야 함 | E31: =B4 -> EMO-001

Sheet PAYS
B1: width 10 | C1: width 30 | D1: width 100 | E1: width 10 | F1: width 30 | G1: width5 | H1: width5 | I1: width5 | J1: width5 | K1: width20 | L1: width5 | N1: width 10 | O1: width 30 | P1: width 100 | Q1: width 10 | R1: width 30 | S1: width5 | T1: width5 | U1: width5 | V1: width5 | W1: width20 | X1: width5 | Z1: width 10 | AA1: width 30 | AB1: width 100 | AC1: width 10 | AD1: width 30 | AE1: width5 | AF1: width5 | AG1: width5 | AH1: width5 | AI1: width20 | AJ1: width5
B2: LEVEL 3 | C2: 레이저 검출기 탑재체 (Laser detector Payload requirement) | F2: Verification 내용 | G2: Verification Method | K2: 기술문서 | L2: 확인 | N2: LEVEL 4 | O2: 레이저 감지 서브시스템 (Laser detecting Subsystem) | R2: Verification 내용 | S2: Verification Method | W2: 기술문서 | X2: 확인 | Z2: LEVEL 5 | AA2: Photodiode (PD) | AD2: Verification 내용 | AE2: Verification Method | AI2: 기술문서 | AJ2: 확인
B3: ID | C3: Title | D3: Requirement | E3: Rationale | G3: A | H3: I | I3: T | J3: D | N3: ID | O3: Title | P3: Requirement | Q3: Rationale | S3: A | T3: I | U3: T | V3: D | Z3: ID | AA3: Title | AB3: Requirement | AC3: Rationale | AE3: A | AF3: I | AG3: T | AH3: D
B4: PAYS-001 | C4: Wavelength | D4: 레이저 감지기 탑재체는 532nm와 1064nm 파장을 감지함 | E4: =Mission!B25 -> TSE-009 | F4: 레이저 감지 시험 | N4: LDS-001 | O4: Wavelength | P4: 레이저 검출기는 532nm와 1064nm 파장을 감지함 | Q4: =B4 -> PAYS-001 | R4: 데이터 시트 확인 및 레이저 검출 시험 | T4: ○ | U4: ○ | Z4: PD-002 | AA4: thermal condition | AB4: 포토다이오드는 -40°C에서 +85°C 사이(TBD)에 작동 가능함 | AC4: =N40 -> LST-001 | AD4: 데이터 시트 확인 | AF4: O
B5: PAYS-002 | C5: Sensitivity | D5: 레이저 감지기 탑재체는 TBD이상의 민감도로 레이저를 감지함 | E5: =Mission!B25 -> TSE-009 | F5: 레이저 감지 시험 | N5: LDS-002 | O5: Min. Responsivity | P5: 레이저 검출기는 532nm와 1064nm 파장에 대해 응답도(출력/광전력)가 TBD 이상 | Q5: =B5 -> PAYS-002 | R5: 시뮬레이션 및 레이저 검출 시험 | S5: ○ | U5: ○ | Z5: PD-003 | AA5: radiation condition | AB5: 포토다이오드는 임무 궤도의 방사선 환경을 견딤 | AC5: =N21 -> LSE-004 | AD5: 데이터 시트 확인 및 양자 노출 시험 | AF5: O | AG5: O
B6: PAYS-003 | C6: Thermal and Radiation condtion | D6: 레이저 감지기 탑재체는 임무 궤도의 열 및 방사선 환경을 견딤 | E6: =Mission!B17 -> TSE-001 | F6: 열 해석 및 열진공 시험, 양자 노출 시험 | G6: O | I6: O | N6: LDS-003 | O6: Sensing Power Range | P6: 레이저 검출기의 감지할 수 있는 광전력은 TBD 범위임 | Q6: =B5 -> PAYS-002 | R6: 시뮬레이션 및 레이저 검출 시험 | S6: ○ | U6: ○ | Z6: PD-004 | AA6: size | AB6: 포토다이오드 크기는 TBD 임 | AC6: =N6 -> LDS-003 | AD6: 포토다이오드 크기 측정 | AF6: O
B7: PAYS-004 | C7: Integration | D7: 레이저 감지기 탑재체는 발사, 궤도 진입, 운용관점에서 본체와 구조적/전기적으로 결합됨 | E7: =Mission!B17 -> TSE-001 | F7: 시뮬레이션 및 조립 확인 | G7: O | H7: O | N7: LDS-004 | O7: Max. Response time | P7: 레이저 검출기의 반응속도는 TBD 이하 | Q7: =B5 -> PAYS-002 | R7: 시뮬레이션 및 레이저 검출 시험 | S7: ○ | U7: ○ | Z7: PD-005 | AA7: Photodiode Responsivity | AB7: 포토다이오드는 레이저 파장 532nm에 대해 응답도가 TBD 이상 | AC7: =N5 -> LDS-002 | AD7: 데이터시트 확인 | AF7: O
B8: PAYS-005 | C8: Max. Mass | D8: 레이저 감지기 탑재체의 무게는 TBD kg 이하 | E8: =Mission!B31 -> TSE-015 | F8: 3차원 모델링 및 위성 질량 측정 | G8: O | H8: O | N8: LDS-005 | O8: Max. Absolute Dark current | P8: 레이저 검출기의 암전류는 광전력보다 낮아야 함 | Q8: =B5 -> PAYS-002 | R8: 시뮬레이션 및 레이저 검출 시험 | S8: ○ | U8: ○ | Z8: PD-005 | AA8: Photodiode Responsivity | AB8: 포토다이오드는 레이저 파장 1064nm에 대해 응답도가 TBD 이상 | AC8: =N5 -> LDS-002 | AD8: 데이터시트 확인 | AF8: O
B9: PAYS-006 | C9: Max. Size | D9: 레이저 감지기 탑재체의 크기는 TBD 이하 | E9: =Mission!B28 -> TSE-012 | F9: 3차원 모델링 및 위성 질량 측정 | G9: O | H9: O | Z9: PD-006 | AA9: Number of Photodiode | AB9: 포토다이오드의 개수는 최소 TBD개 이상 | AC9: =N6 -> LDS-003 | AD9: 시뮬레이션 | AE9: O
B10: PAYS-007 | C10: Max. Power Consumption | D10: 레이저 감지기 탑재체의 전력 소모는 TBD 이하 | E10: =Mission!B17 -> TSE-001 | F10: 시뮬레이션 및 소모 전력 시험 | G10: O | I10: O
B11: PAYS-008 | C11: Data Interface Standard | D11: 레이저 감지기 탑재체의 데이터 인터페이스는 CAN-bus를 1순위로 사용 | E11: =Mission!B17 -> TSE-001 | F11: 서브 시스템 HW 및 MCU 핀 검토 | H11: O | I11: O
N16: LEVEL 4 | O16: 레이저 감지 시스템 전자계 (Laser sening ES) | R16: Verification 내용 | S16: Verification Method | W16: 기술문서 | X16: 확인 | Z16: LEVEL 5 | AA16: Laser detecting unit (LDU) | AD16: Verification 내용 | AE16: Verification Method | AI16: 기술문서 | AJ16: 확인
N17: ID | O17: Title | P17: Requirement | Q17: Rationale | S17: A | T17: I | U17: T | V17: D | Z17: ID | AA17: Title | AB17: Requirement | AC17: Rationale | AE17: A | AF17: I | AG17: T | AH17: D
N18: LSE-001 | O18: Power Consumption | P18: 레이저 감지기의 전력 소모는 TBD 이하 | Q18: =B10 -> PAYS-007 | R18: MATLAB/SMULINK 시뮬레이션, 전력 시험 | S18: ○ | U18: ○ | Z18: LDU-001 | AA18: thermal condition | AB18: LDU 회로 내의 모든 소자는 -40°C에서 +85°C 사이(TBD)에 작동 가능함 | AC18: =N40 -> LST-001 | AD18: 데이터 시트 확인 및 열 해석, 열진공시험 | AE18: O | AF18: O | AG18: O
N19: LSE-002 | O19: Power interface | P19: 레이저 감지기는 본체로 부터 TBDV의 전압을 공급받아 운용됨 | Q19: =B10 -> PAYS-007 | R19: MATLAB/SMULINK 시뮬레이션, 전력 시험 | S19: ○ | U19: ○ | Z19: LDU-002 | AA19: radiation condition | AB19: LDU 회로는 임무 궤도의 방사선 환경을 견딤 | AC19: =N21 -> LSE-004 | AD19: 데이터 시트 확인 및 양자노출검사 | AF19: O | AG19: O
N20: LSE-003 | O20: Interface | P20: 레이저 감지기의 인터페이스 버스는 CAN-bus와 보조용 인터페이스를 사용함 | Q20: =B11 -> PAYS-008 | R20: 데이터 시트 확인 및 OBC 연동 시험 | T20: ○ | U20: ○ | Z20: LDU-003 | AA20: Resistance | AB20: LDU 회로의 부하 저항은 TBD 이하 | AC20: =N7 -> LDS-004 | AD20: 데이터 시트 확인 | AF20: O
N21: LSE-004 | O21: Radiation condition | P21: 레이저 감지기의 모든 부품은 임무 궤도의 방사선 환경을 견딤 | Q21: =B6 -> PAYS-003 | R21: 데이터 시트 확인 및 양자노출 검사 | S21: ○ | U21: ○ | Z21: LDU-004 | AA21: reverse voltage | AB21: LDU 회로의 역전압은 TBD 임 | AC21: =N8 -> LDS-005 | AD21: 데이터 시트 확인 | AF21: O
N22: LSE-005 | O22: Checking Device | P22: 레이저 감지기의 상태 정보를 본체에 전달함 | Q22: =B7 -> PAYS-004 | R22: 데이터 시트 확인 및 OBC 연동 시험 | T22: ○ | U22: ○ | Z22: LDU-005 | AA22: Output data | AB22: LDU 회로의 출력값은 TBD 범위의 Voltage 값으로 변환함 | AC22: =N23 -> LSE-006 | AD22: 시뮬레이션 및 레이저 검출 시험 | AE22: O | AG22: O
N23: LSE-006 | O23: Data handling | P23: 레이저 감지기의 임무 수행 데이터를 본체에 전달함 | Q23: =B7 -> PAYS-004 | R23: 데이터 시트 확인 및 OBC 연동 시험 | T23: ○ | U23: ○
A27: blank
N28: LEVEL 4 | O28: 레이저 감지 시스템 구조계 (Laser sensing SMS) | R28: Verification 내용 | S28: Verification Method | W28: 기술문서 | X28: 확인
N29: ID | O29: Title | P29: Requirement | Q29: Rationale | S29: A | T29: I | U29: T | V29: D
N30: LSS-001 | O30: Mass | P30: 레이저 감지기의 무게는 TBDkg ± TBD이하 | Q30: =B8 -> PAYS-005 | R30: 질량 측정 | T30: ○
N31: LSS-002 | O31: Size | P31: 레이저 감지기의 크기는 TBD 이하 | Q31: =B9 -> PAYS-006 | R31: 3차원 모델링 및 육안 확인 | S31: ○ | T31: ○
N32: LSS-003 | O32: Launch Vehicle Requirement | P32: 레이저 감지기는 본체와 구조적으로 결합되어 발사체 요구조건을 만족함 | Q32: =B7 -> PAYS-004 | R32: 구조해석 및 진동시험, 충격시험 | S32: ○ | U32: ○
N38: LEVEL 4 | O38: 레이저 감지 시스템 열제어계 (Laser sensing TCS) | R38: Verification 내용 | S38: Verification Method | W38: 기술문서 | X38: 확인
N39: ID | O39: Title | P39: Requirement | Q39: Rationale | S39: A | T39: I | U39: T | V39: D
N40: LST-001 | O40: Thermal condition | P40: 레이저 감지기는 -40°C에서 +85°C 사이에 작동 가능함 | Q40: =B6 -> PAYS-003 | R40: 데이터 시트 확인, 열해석 및 열 진공 시험 | S40: ○ | T40: ○ | U40: ○
N41: LST-002 | O41: Thermal Modely analysis | P41: 레이저 감지기는 작동 온도 범위에서 적어도 TBD의 uncertainty을 가짐 | Q41: =B6 -> PAYS-003 | R41: 열해석 | S41: ○
AB45: `

Sheet PAYC
B1: width 10 | C1: width 30 | D1: width 100 | E1: width 10 | F1: width 30 | G1: width5 | H1: width5 | I1: width5 | J1: width5 | K1: width20 | L1: width5 | N1: width 10 | O1: width 30 | P1: width 100 | Q1: width 10 | R1: width 30 | S1: width5 | T1: width5 | U1: width5 | V1: width5 | W1: width20 | X1: width5 | Z1: width 10 | AA1: width 30 | AB1: width 100 | AC1: width 10 | AD1: width 30 | AE1: width5 | AF1: width5 | AG1: width5 | AH1: width5 | AI1: width20 | AJ1: width5
B2: LEVEL 3 | C2: 대즐링 카메라 탑재체 요구조건 (Dazzling camera Payload requirement) | F2: Verification 내용 | G2: Verification Method | K2: 기술문서 | L2: 확인 | N2: LEVEL 4 | O2: 큐브위성용 카메라 (CubeSat camera Subsystem) | R2: Verification 내용 | S2: Verification Method | W2: 기술문서 | X2: 확인
B3: ID | C3: Title | D3: Requirement | E3: Rationale | G3: A | H3: I | I3: T | J3: D | N3: ID | O3: Title | P3: Requirement | Q3: Rationale | S3: A | T3: I | U3: T | V3: D
B4: PAYC-001 | C4: Wavelength | D4: 대즐링 카메라 탑재체는 520 - 590 nm 와 630 - 690 nm의 파장을 감지함 | E4: =Mission!B24 -> TSE-008 | N4: CAM-001 | O4: Wavelength | P4: 큐브위성용 카메라 시스템은 520 - 590 nm 와 630 - 690 nm의 파장을 감지함 | Q4: =B4 -> PAYC-001 | R4: 데이터 시트 확인 | T4: ○
B5: PAYC-002 | C5: Imaging Duration | D5: 대즐링 카메라 탑재체는 TBD sec 동안 지상 촬영을 진행함 | E5: =Mission!B24 -> TSE-008 | N5: CAM-002 | O5: Imaging Sampling Rate | P5: 큐브위성용 카메라 시스템은 TBD sec 당 한번 이상 촬영 | Q5: =B6 -> PAYC-003 | R5: 데이터 시트 확인 | T5: ○
B6: PAYC-003 | C6: Imaging Sampling Rate | D6: 대즐링 카메라 탑재체는 TBD sec 당 한번 이상 촬영 | E6: =Mission!B24 -> TSE-008 | F6: 데이터 시트 확인 | H6: ○ | N6: CAM-003 | O6: Storage | P6: 큐브위성용 카메라 시스템은 TBD Bytes 저장용량을 가짐 | Q6: =B5 -> PAYC-002
B7: PAYC-004 | C7: Thermal and Radiation condtion | D7: 대즐링 카메라 탑재체는 임무 궤도의 열 및 방사선 환경을 견딤 | E7: =Mission!B17 -> TSE-001 | F7: 열 해석 및 열 진공 시험, 양자 노출 시험 | G7: O | I7: O | N7: CAM-004 | O7: Data Interface | P7: 큐브위성용 카메라 시스템의 데이터 인터페이스는 CAN-bus[TBD]를 사용 | Q7: =B12 -> PAYC-009
B8: PAYC-005 | C8: Integration | D8: 대즐링 카메라 탑재체는 발사, 궤도 진입, 운용관점에서 본체와 구조적/전기적으로 결함됨 | E8: =Mission!B17 -> TSE-001 | F8: 시뮬레이션 및 조립 확인 | G8: O | H8: O
B9: PAYC-006 | C9: Max. Size | D9: 대즐링 카메라 탑재체의 크기는 TBD mm 이하 | E9: =Mission!B28 -> TSE-012 | F9: 3차원 모델링 및 위성 크기 측정 | G9: O | H9: O
B10: PAYC-007 | C10: Max. Mass | D10: 대즐링 카메라 탑자체의 무게는 TBD kg 이하 | E10: =Mission!B31 -> TSE-015 | F10: 질량 계산 및 조립 후 질량 측정 | G10: O | H10: O | N10: LEVEL 4 | O10: 큐브위성용 카메라 시스템 구조계 (CubeSat camera SMS) | R10: Verification 내용 | S10: Verification Method | W10: 기술문서 | X10: 확인
B11: PAYC-008 | C11: Max. Power consumption | D11: 대즐링 카메라 탑재체의 소모 전력은 TBD 이하 | E11: =Mission!B17 -> TSE-001 | F11: 시뮬레이션 및 소모 전력 시험 | G11: O | I11: O | N11: ID | O11: Title | P11: Requirement | Q11: Rationale | S11: A | T11: I | U11: T | V11: D
A12: blank | B12: PAYC-009 | C12: Data Interface | D12: 대즐링 카메라 탑재체의 데이터 인터페이스는 CAN-bus를 1순위로 사용 | E12: =Mission!B17 -> TSE-001 | N12: LSS-001 | O12: Mass | P12: 큐브위성용 카메라 시스템 무게는 TBDkg ± TBD이하여야 함 | Q12: =B10 -> PAYC-007 | R12: 질량 측정 | T12: ○
N13: LSS-002 | O13: Size | P13: 큐브위성용 카메라 시스템 전체 크기는 TBD 이하여야 함 | Q13: =B9 -> PAYC-006 | R13: 3차원 모델링 및 육안 확인 | S13: ○ | T13: ○
N14: LSS-003 | O14: Launch Vehicle Requirement | P14: 큐브위성용 카메라 시스템은 본체와 구조적으로 결합되어 발사체 요구조건을 만족해야 함 | Q14: =B8 -> PAYC-005 | R14: 구조해석 및 진동시험, 충격시험 | S14: ○ | U14: ○
N20: LEVEL 4 | O20: 큐브위성용 카메라 시스템 열제어계 (CubeSat camera TCS) | R20: Verification 내용 | S20: Verification Method | W20: 기술문서 | X20: 확인 | AB20: `
N21: ID | O21: Title | P21: Requirement | Q21: Rationale | S21: A | T21: I | U21: T | V21: D
N22: LST-001 | O22: Thermal condition | P22: 큐브위성용 카메라 시스템은 -40°C에서 +85°C 사이에 작동 가능해야 함 | Q22: =B7 -> PAYC-004 | R22: 데이터 시트 확인, 열해석 및 열 진공 시험 | S22: ○ | T22: ○ | U22: ○
N23: LST-002 | O23: Thermal Modely analysis | P23: 큐브위성용 카메라 시스템은 작동 온도 범위에서 적어도 TBD의 uncertainty을 가져야 함 | Q23: =B7 -> PAYC-004 | R23: 열해석 | S23: ○

Sheet PAYR
B1: width 10 | C1: width 30 | D1: width 100 | E1: width 10 | F1: width 30 | G1: width5 | H1: width5 | I1: width5 | J1: width5 | K1: width20 | L1: width5 | N1: width 10 | O1: width 30 | P1: width 100 | Q1: width 10 | R1: width 30 | S1: width5 | T1: width5 | U1: width5 | V1: width5 | W1: width20 | X1: width5 | Z1: width 10 | AA1: width 30 | AB1: width 100 | AC1: width 10 | AD1: width 30 | AE1: width5 | AF1: width5 | AG1: width5 | AH1: width5 | AI1: width20 | AJ1: width5
B2: LEVEL 3 | C2: 전개형 반사 탑재체 요구조건 (Deployment reflection Payload requirement) | F2: Verification 내용 | G2: Verification Method | K2: 기술문서 | L2: 확인 | N2: LEVEL 4 | O2: 박막 전개장치 구조계 (Membrane Deployment Structure and Mechanism Subsystem , MDS) | R2: Verification 내용 | S2: Verification Method | W2: 기술문서 | X2: 확인 | Z2: LEVEL 5 | AA2: 전개부(DEP) | AD2: Verification 내용 | AE2: Verification Method | AI2: 기술문서 | AJ2: 확인
B3: ID | C3: Title | D3: Requirement | E3: Rationale | G3: A | H3: I | I3: T | J3: D | N3: ID | O3: Title | P3: Requirement | Q3: Rationale | S3: A | T3: I | U3: T | V3: D | Z3: ID | AA3: Title | AB3: Requirement | AC3: Rationale | AE3: A | AF3: I | AG3: T | AH3: D
B4: PAYR-001 | C4: Min. Deployed size | D4: 전개형반사탑재체는 전개시 1 m x 1 m 이상 | E4: =Mission!B21 -> TSE-005 | F4: 3D 모델링 및 전개 시험 | G4: O | I4: O | J4: O | N4: MDS-001 | O4: Deployed size | P4: 박막 전개장치는 전개시 1m x 1m 이상 | Q4: =B4 -> PAYR-001 | R4: 3D 모델링 | S4: O | Z4: DEP-001 | AA4: Deployment Size | AB4: 전개부의 크기는 0.25U 이내로 한다. | AC4: MDS-006 | AD4: 3D 모델링
B5: PAYR-002 | C5: Reflectivity | D5: 전개형반사탑재체의 박막은 1064nm의 파장에 대해 16%의 반사도를 가짐 | E5: =Mission!B25 -> TSE-009 | N5: MDS-002 | O5: Reflectivity | P5: 박막 전개장치의 박막은 1064nm 파장에 대해 16%이상의 반사도를 가짐 | Q5: =B4 -> PAYR-001 | R5: 데이터 시트 확인 | T5: O | Z5: DEP-002 | AA5: Deploy Method | AB5: 전개 방식은 테이프 스프링은 굽힘에 대한 복원력을 통해 진행 | AC5: MDS-003 | AD5: 시뮬레이션 및 전개 실험
B6: PAYR-003 | C6: Stability of Mechanism | D6: 전개형반사탑재체는 궤도상에서 박막이 안전하게 전개될 수 있어야 함 | E6: =Mission!B21 -> TSE-005 | F6: 시뮬레이션 및 전개 시험 | G6: O | I6: O | N6: MDS-003 | O6: Motion of deployemt | P6: 박막 전개장치의 테이프 스프링은 굽힘에 대한 복원력으로 | Q6: =B6 -> PAYR-003 | R6: 시뮬레이션 및 전개 실험 | S6: O | U6: O | Z6: DEP-003 | AA6: Deploy Material | AB6: 전개부 부품을 구성하는 재료는 Al6061, CFRP로 구성한다. | AC6: MDS-005 | AD6: 3D 모델링
B7: PAYR-004 | C7: Checking deployment | D7: 전개형반사탑재체의 전개를 확인할 수 있는 시스템이 필요함 | E7: =Mission!B21 -> TSE-005 | F7: 3D 모델링 및 전개 시험 | G7: O | I7: O | N7: MDS-005 | O7: Mass | P7: 박막 전개장치의 무게는 0.6kg 이하 | Q7: =B10 -> PAYR-007 | R7: 3D 모델링 및 조립 확인 | S7: O | T7: O | Z7: DEP-004 | AA7: Tape Spring Material | AB7: Tape Spring을 구성하는 재료는 SK85 혹은 Stainless Steel로 구성한다. | AC7: MDS-003 | AD7: 3D 모델링
B8: PAYR-005 | C8: Thermal and radiation condition | D8: 전개형반사탑재체는 임무 궤도의 열 및 방사선 환경을 견딤 | E8: =Mission!B17 -> TSE-001 | F8: 열 해석 및 열진공 시험, HW 후처리 | G8: O | I8: O | N8: MDS-006 | O8: Size | P8: 박막 전개장치의 비전개시의 크기는 0.4U 이하 | Q8: =B11 -> PAYR-008 | R8: 질량 계산 및 조립 후 질량 측정 | S8: O | T8: O | Z8: DEP-005 | AA8: Checking Deployment | AB8: 전개부는 전개를 확인할 수 있는 부품을 탑재 | AC8: MDE-002 | AD8: 시뮬레이션 및 전개 실험
B9: PAYR-006 | C9: Integration | D9: 전개형반사탑재체는 발사, 궤도 진입, 운용관점에서 본체와 구조적/전기적으로 결합됨 | E9: =Mission!B17 -> TSE-001 | F9: 시뮬레이션 및 조립 확인, 작동 시험 | G9: O | H9: O | I9: O | N9: MDS-007 | O9: Launch Vehicle Requirement | P9: 박막 전개장치는 본체와 구조적으로 결합되어 발사체 요구조건을 만족함 | Q9: =B9 -> PAYR-006 | R9: 구조해석 및 진동시험, 충격시험 후 작동 시험 | S9: O | U9: O | Z9: DEP-006 | AA9: Thermal Condition | AB9: 전개부는 -40°C에서 +85°C 사이(TBD)에 작동 가능함 | AC9: PAYR-005 | AD9: 데이터 시트 확인, 열해석 및 열 진공 시험
B10: PAYR-007 | C10: Max. Mass | D10: 전개형반사탑재체의 무게는 0.6kg 이하 | E10: =Mission!B31 -> TSE-015 | F10: 질량 계산 및 조립 후 질량 측정 | G10: O | H10: O | Z10: DEP-007 | AA10: Integration Method | AB10: 전개부 내부 부품 간 연결은 M2.5 나사를 통해 연결한다. | AC10: MDS-007 | AD10: 3D 모델링 및 조립
B11: PAYR-008 | C11: Max. Size | D11: 전개형반사탑재체의 비전개시의 크기는 0.4U 이하 | E11: =Mission!B28 -> TSE-012 | F11: 3D 모델링 및 조립 | G11: O | H11: O | Z11: DEP-008 | AA11: Rotating Parts | AB11: Rotating Parts는 Bearing, Axle, Reel로 구성된다. | AC11: MDS-007 | AD11: 3D 모델링
B12: PAYR-009 | C12: Max. Power Consumption | D12: 전개형반사탑재체의 전력 소모는 TBDW 이하 | E12: =Mission!B17 -> TSE-001 | F12: 시뮬레이션 및 소모 전력 시험 | G12: O | I12: O | Z12: DEP-009 | AA12: Tape Spring Size | AB12: Tape Spring의 길이는 750mm 이상, 너비는 20mm 이하, 두께는 0.25mm이하로 구성 | AC12: MDS-001 | AD12: 3D 모델링
A13: blank | B13: PAYR-010 | C13: Data Interface Standard | D13: 전개형반사탑재체의 데이터 인터페이스는 CAN-bus 를 1순위로 사용 | E13: =Mission!B17 -> TSE-001 | F13: 서브시스템 HW 및 MCU 핀 검토 | H13: O | I13: O | M13: blank | Z13: DEP-010 | AA13: Nylon Wire | AB13: Nylon Wire의 직경은 TBD mm로 한다. | AC13: MDS-007 | AD13: 3D 모델링
Z14: DEP-011 | AA14: Vibration Condition | AB14: 전개부는 발사체에서 요구하는 Random/Sinusoidal Vibration을 견딜 수 있어야 함 | AC14: PAYR-005 | AD14: 구조해석 및 진동시험, 충격시험 후 작동 시험
Z17: LEVEL 5 | AA17: 박막부(SAI) | AD17: Verification 내용 | AE17: Verification Method | AI17: 기술문서 | AJ17: 확인
Z18: ID | AA18: Title | AB18: 1 | AC18: Rationale | AE18: A | AF18: I | AG18: T | AH18: D
Z19: SAI-001 | AA19: Deployed size | AB19: 박막 전개장치는 4개의 한변이 50cm인 직각이등변삼각형 박막으로 구성 | AC19: MDS-001 | AD19: 3D 모델링
Z20: SAI-002 | AA20: Cartridge Size | AB20: Sail cartridge 크기는 77mm x 37mm x 8.5mm (TBD) 이하 | AC20: MDS-006 | AD20: 3D 모델링
F21: ` | Z21: SAI-003 | AA21: Sail Size | AB21: 전개시 박막은 0.25m^2의 크기를 가짐 | AC21: SAI-002 | AD21: 3D 모델링
Z22: SAI-004 | AA22: Rigidity | AB22: 박막은 전개시 발생하는 TBD MPa 을 견딜 수 있어야 함 | AC22: PAYR-003 | AD22: 시뮬레이션 및 전개 실험
Z23: SAI-005 | AA23: Thermal Condition | AB23: 박막은 -40°C에서 +85°C 사이(TBD)에 작동 가능함 | AC23: MDT-001 | AD23: 데이터 시트 확인, 열해석 및 열 진공 시험
Z24: SAI-006 | AA24: Radiation Condition | AB24: 박막은 임무 궤도의 방사선 환경을 견딤 | AC24: PAYR-005 | AD24: 실험
Z25: SAI-007 | AA25: Integration | AB25: 박막은 전개부 Tape Spring 및 Cartridge Part와 Nylon Wire로 연결된다. | AC25: MDS-007 | AD25: 3D 모델링 및 조립
Z26: SAI-008 | AA26: Reflectivity | AB26: 박막은 1064nm 파장에 대해 16%이상의 반사도를 가짐 | AC26: MDS-002 | AD26: 데이트 시트 확인
N27: LEVEL 4 | O27: 박막 전개장치 열제어계 (Membrane Deployment Thermal Control Subsystem, MDT) | R27: Verification 내용 | S27: Verification Method | W27: 기술문서 | X27: 확인 | Z27: SAI-009 | AA27: Folding Method | AB27: 비전개시 박막은 Sail Cartridge 내부에 수납 가능해야함 | AC27: SAI-002 | AD27: 시뮬레이션 및 수납 실험
N28: ID | O28: Title | P28: Requirement | Q28: Rationale | S28: A | T28: I | U28: T | V28: D | Z28: SAI-010 | AA28: Vibration Condition | AB28: 박막부는 발사체에서 요구하는 Random/Sinusoidal Vibration을 견딜 수 있어야 함 | AC28: PAYR-005 | AD28: 구조해석 및 진동시험, 충격시험 후 작동 시험
N29: MDT-001 | O29: Thermal Modely analysis | P29: 박막 전개장치의 구조물은 작동 온도 범위에서 적어도 TBD의 uncertainty을 가짐 | Q29: =B8 -> PAYR-005 | R29: 열해석 | S29: O
N30: MDT-002 | O30: Thermal condition | P30: 박막 전개장치의 모든 하드웨어의 온도는 보관 온도 내에 있어야 하며, 해당 하드웨어를 사용하는 경우 작동 온도 범위 내로 온도가 유지됨 | Q30: =B8 -> PAYR-005 | R30: 데이터 시트 확인, 열해석 및 열 진공 시험 | S30: O | T30: O | U30: O
N34: LEVEL 4 | O34: 박막 전개장치 전자계 (Membrane Deployment Electrical Subsystem, MDE) | R34: Verification 내용 | S34: Verification Method | W34: 기술문서 | X34: 확인
N35: ID | O35: Title | P35: Requirement | Q35: Rationale | S35: A | T35: I | U35: T | V35: D | Z35: LEVEL 5 | AA35: 전자부(PWR) | AD35: Verification 내용 | AE35: Verification Method | AI35: 기술문서 | AJ35: 확인
N36: MDE-001 | O36: Power consumption | P36: 박막 전개장치의 전력 소모는 TBD 이하 | Q36: =B12 -> PAYR-009 | R36: MATLAB/SIMULINK 시뮬레이션, 전력시험 | S36: O | U36: O | Z36: ID | AA36: Title | AB36: Requirement | AC36: Rationale | AE36: A | AF36: I | AG36: T | AH36: D
N37: MDE-002 | O37: checking Device | P37: 박막 전개장치의 전자계는 박막 전개장치의 상태 정보를 본체에 전달함 | Q37: =B7 -> PAYR-004 | R37: 데이터 시트 확인 및 OBC 연동 시험 | T37: O | U37: O | Z37: PWR-001 | AA37: Power Interface | AB37: 전자부는 EPS로부터 3.3V, 5V를 받아 작동한다. | AC37: MDE-004 | AD37: MATLAB/SIMULINK 시뮬레이션, 전력시험
N38: MDE-003 | O38: Data Interface | P38: 박막 전개장치의 인터페이스 버스는 CAN-bus와 보조용 인터페이스를 사용함 | Q38: =B13 -> PAYR-010 | R38: 데이터 시트 확인 및 OBC 연동 시험 | T38: O | U38: O | Z38: PWR-002 | AA38: Power Consumption | AB38: 전자부의 전력 소모는 TBDW 이내여야 한다. | AC38: MDE-001 | AD38: 시뮬레이션 및 소모 전력 시험
N39: MDE-004 | O39: Power interface | P39: 박막 전개장치는 본체로 부터 3.3V, 5V 의 전압을 공급받아 운용됨 | Q39: =B9 -> PAYR-006 | R39: MATLAB/SIMULINK 시뮬레이션, 전력시험 | S39: O | U39: O | Z39: PWR-003 | AA39: Operating Temperature | AB39: 전자부는 -40°C에서 +85°C 사이(TBD)에 작동 가능함 | AC39: PAYR-005 | AD39: 데이터 시트 확인, 열해석 및 열 진공 시험
Z40: PWR-004 | AA40: Data Interface | AB40: 전자부의 데이터 인터페이스 버스는 CAN-bus와 보조용 인터페이스를 사용함 | AC40: MDE-003 | AD40: 데이터 시트 확인 및 OBC 연동 시험

Sheet SYS
B1: width 10 | C1: width 30 | D1: width 100 | E1: width 10 | F1: width 30 | G1: width5 | H1: width5 | I1: width5 | J1: width5 | K1: width20 | L1: width5 | N1: width 10 | O1: width 30 | P1: width 100 | Q1: width 10 | R1: width 30 | S1: width5 | T1: width5 | U1: width5 | V1: width5 | W1: width20 | X1: width5 | Z1: width 10 | AA1: width 30 | AB1: width 100 | AC1: width 10 | AD1: width 30 | AE1: width5 | AF1: width5 | AG1: width5 | AH1: width5 | AI1: width20 | AJ1: width5
A2: height 30 | B2: LEVEL 3 | C2: 본체 시스템 요구조건 (BUS System Requirement) | F2: Verification 내용 | G2: Verification Method | K2: 기술문서 | L2: 확인 | N2: LEVEL 4 | O2: 위성 자세 및 궤도 결정 및 제어 (Attitude and Orbit Determination and Control Subsystem, ADCS) | R2: Verification 내용 | S2: Verification Method | W2: 기술문서 | X2: 확인 | Z2: LEVEL 5 | AA2: 별 센서 (Star Tracker, STT) | AD2: Verification 내용 | AE2: Verification Method | AI2: 기술문서 | AJ2: 확인
B3: ID | C3: Title | D3: Requirement | E3: Rationale | G3: A | H3: I | I3: T | J3: D | N3: ID | O3: Title | P3: Requirement | Q3: Rationale | S3: A | T3: I | U3: T | V3: D | Z3: ID | AA3: Title | AB3: Requirement | AC3: Rationale | AE3: A | AF3: I | AG3: T | AH3: D
B4: SYS-001 | C4: System Life time | D4: 큐브 위성 본체의 모든 부품과 하네스는 임무기간인 TBD개월 동안 우주에서 정상 작동함 | E4: =Mission!B19 -> TSE-003 | F4: DOD 분석 및 TID 확인 | G4: O | H4: O | N4: ADCS-001 | O4: Housekeeping Data | P4: ADCS는 상태 데이터 수집이 가능해야 함 | Q4: =B15 -> SYS-012 | R4: OBC/FSW 기능시험 | V4: ○ | Z4: STT-001
B5: SYS-002 | C5: Thermal and radiation Condition | D5: 큐브 위성 본체는 임무 궤도의 열 및 방사선 환경을 견뎌야 함 | E5: =Mission!B17 -> TSE-001 | F5: 열해석 및 열진공주기 시험, 후처리 | G5: O | I5: O | N5: ADCS-002 | O5: Fault Detection & Isolation | P5: ADCS 부품의 고장을 검출 및 수집할 수 있어야 함 | Q5: =B17 -> SYS-014 | R5: OBC/FSW 기능시험 | U5: ○ | Z5: STT-002
B6: SYS-003 | C6: System Storage Duration | D6: 큐브 위성 본체의 모든 부품과 하네스는 개발 완료 후 최소 TBD개월간 지상 보관 후에도 정상 작동함 | E6: =Mission!B26 -> TSE-010 | F6: 배터리 수명 분석 | H6: O | N6: ADCS-003 | O6: Processing Speed | P6: ADCS의 알고리즘은 ≥ TBD Hz 로 운용되어야 함 | Q6: =B25 -> SYS-022 | R6: OBC/FSW 기능시험 | V6: ○ | Z6: STT-003
B7: SYS-004 | C7: Bus mass | D7: 큐브 위성 본체의 질량은 TBD kg 미만 | E7: =Mission!B31 -> TSE-015 | F7: 질량 계산 및 조립 후 질량 측정 | G7: O | H7: O | N7: ADCS-004 | O7: Attitude Stability | P7: ADCS는 특정 지향 모드를 제외하고는 모든 축의 각속도를 ≤ TBD deg/s 로 유지할 수 있어야 함 (단, 태양 지향 모드에서는 TBD deg/s 를 유지해야 함) | Q7: =B25 -> SYS-022 | R7: MATLAB 시뮬레이션 및 FSW 기능 시험 | S7: ○ | U7: ○ | Z7: STT-004
B8: SYS-005 | C8: Bus Size | D8: 큐브 위성 본체의 크기는 100.0 x 100.0 x 340.5 mm3 이하 | E8: =Mission!B28 -> TSE-012 | F8: 3차원 모델링 및 위성 크기 측정 | G8: O | H8: O | N8: ADCS-005 | O8: Detumbling Period | P8: 최대 Detumbling 기간은 TBD sec 이하여야 함 | Q8: =B16 -> SYS-013 | R8: MATLAB 시뮬레이션 및 FSW 기능 시험 | S8: ○ | U8: ○ | Z8: STT-005
B9: SYS-006 | C9: Coordinate system | D9: 큐브 위성 본체의 body coordinate system은 원점을 3U 큐브위성의 형상중심으로 설정하고 사출방향을 +Z 축, PCI-104의 헤더소켓이 쌓여 있는 방향을 +X 축으로 설정 | E9: =Mission!B28 -> TSE-012 | F9: 3차원 모델링 기준 | H9: O | N9: ADCS-006 | O9: Pointing Accuracy; ECI | P9: pointing accuracy ≤ TBD deg | Q9: =B25 -> SYS-022 | R9: MATLAB 시뮬레이션 및 FSW 기능 시험 | S9: ○ | U9: ○ | Y9: blank
B10: SYS-007 | C10: Data Interface Standard | D10: 큐브 위성의 인터페이스 버스는 CAN-bus 를 1순위로 사용 | E10: =Mission!B17 -> TSE-001 | F10: 서브시스템 HW 및 MCU 핀 검토 | H10: O | I10: O | N10: ADCS-007 | O10: Pointing Knowledge; ECEF | P10: pointing accuracy ≤ TBD deg | Q10: =B25 -> SYS-022 | R10: MATLAB 시뮬레이션 및 FSW 기능 시험 | S10: ○ | U10: ○
B11: SYS-008 | C11: Integration | D11: 큐브 위성 모든 부품과 하네스는 발사, 궤도진입, 운용 과정에서 위성체와 구조적/전기적으로 결합됨 | E11: =Mission!B17 -> TSE-001 | F11: 시뮬레이션 및 조립 확인 | G11: O | H11: O | N11: ADCS-008 | O11: Orbit determination | P11: 온보드 항법으로는 Knowledge < 10 m (각 축, 3 σ) (TBD) | Q11: =B23 -> SYS-020 | R11: MATLAB 시뮬레이션 및 FSW 기능 시험 | S11: ○ | U11: ○
B12: SYS-009 | C12: Power Margin in Normal | D12: 큐브 위성의 전력 여유는 TBD 이상 | E12: =Mission!B17 -> TSE-001 | F12: MATLAB/SIMULINK시뮬레이션 및 소모전력 시험 | G12: O | I12: O | N12: ADCS-009 | O12: Data for POD on Ground | P12: 큐브 위성은 GPS 신호로 L1, L2를 사용할 수 있어야 함 | Q12: =B24 -> SYS-021 | Z12: LEVEL 5 | AA12: 정밀 태양 센서 (Fine Sun Sensor, FSS) | AD12: Verification 내용 | AE12: Verification Method | AI12: 기술문서 | AJ12: 확인
B13: SYS-010 | C13: Power interface | D13: 큐브 위성의 모든 서브시스템이 정상 작동하도록 전력이 공급됨 | E13: =Mission!B17 -> TSE-001 | F13: MATLAB/SIMULINK 시뮬레이션 | G13: O | Z13: ID | AA13: Title | AB13: Requirement | AC13: Rationale | AE13: A | AF13: I | AG13: T | AH13: D
B14: SYS-011 | C14: Total Center of Mass | D14: 큐브 위성의 질량중심은 형상중심의 x, y 축 방향으로 TBDmm. z 축방향으로 TBDmm이내에 있음 | E14: =Mission!B17 -> TSE-001 | F14: 3차원 모델링 기준 | G14: O | Z14: FSS-001
B15: SYS-012 | C15: Data collection | D15: 큐브 위성은 TBD 일 이상의 주요 전자 부품 상태 데이터 및 임무 데이터 수집이 가능함 | E15: =Mission!B29 -> TSE-013 | F15: OBC/FSW 기능 시험 | J15: O | Z15: FSS-002
B16: SYS-013 | C16: Autonomic Schedule Execution | D16: 큐브 위성은 예약된 명령으로 자율적인 임무 수행이 가능함 | E16: =Mission!B29 -> TSE-013 | F16: OBC/FSW 기능 시험 | J16: O | Z16: FSS-003
B17: SYS-014 | C17: Fault Detection & Isolation | D17: 큐브 위성은 스스로 각 서브시스템 수준의 고장을 시스템에서 검출 및 분리함 | E17: =Mission!B29 -> TSE-013 | F17: FSW 내 EADC 탑재 | J17: O | Z17: FSS-004
B18: SYS-015 | C18: Alterable parameters | D18: 큐브 위성은 지상국의 명령에 의해 S/W 변경이 가능함 | E18: =Mission!B17 -> TSE-001 | F18: 지상국-위성HW 지상시험 | J18: O | Z18: FSS-005
B19: SYS-016 | C19: Signal start time | D19: 큐브 위성의 모든 신호는 사출장치에서 사출 후 TBD후에 발생됨 | E19: =Mission!B31 -> TSE-015 | F19: OBC/FSW 기능 시험 | J19: O | M19: blank | Y19: blank
B20: SYS-017 | C20: Frequency for Communication | D20: 큐브 위성은 지상국과 UHF 대역 및 (상용/아마추어 대역) S-band 주파수를 이용하여 통신함 | E20: =Mission!B30 -> TSE-014 | F20: RF 계측기를 이용한 주파수 측정 | H20: O
B21: SYS-018 | C21: Telemetry & Telecommand | D21: 큐브 위성은 UHF 및 S-band 주파수 통해 상태 정보 및 명령 송수신을 함 | E21: =Mission!B30 -> TSE-014 | F21: HW 지상시험 | J21: O
B22: SYS-019 | C22: Launch Vehicle Requirement | D22: 큐브 위성의 진동 특성은 발사체 요구조건를 만족함 | E22: =Mission!B31 -> TSE-015 | F22: 구조해석 및 발사환경 시험 | G22: O | I22: O | Z22: LEVEL 5 | AA22: 비정밀 태양 센서 (Coarse Sun Sensor, CSS) | AD22: Verification 내용 | AE22: Verification Method | AI22: 기술문서 | AJ22: 확인
B23: SYS-020 | C23: On-board Navigation | D23: 온보드 항법으로는 Knowledge < 10 m (각 축, 3 σ) (TBD) | E23: =Mission!B23 -> TSE-007 | F23: MATLAB/SIMULINK 시뮬레이션 | G23: O | Z23: ID | AA23: Title | AB23: Requirement | AC23: Rationale | AE23: A | AF23: I | AG23: T | AH23: D
B24: SYS-021 | C24: Data for POD on Ground | D24: 큐브 위성은 GPS 신호로 L1, L2를 사용함 | E24: =Mission!B22 -> TSE-006 | Z24: CSS-001
B25: SYS-022 | C25: Pointing Performance | D25: 임무모드에서 큐브위성의 pointing <5.0 deg (각 축, 3 σ) (TBD) | E25: =Mission!B17 -> TSE-001 | F25: MATLAB/SIMULINK 시뮬레이션 | G25: O | Z25: CSS-002
B26: SYS-023 | C26: UHF Downlink Time | D26: 큐브 위성의 UHF를 이용하여 데이터를 송신하기 위해서는 최대 TBDsec 동안 통신함 | E26: =Mission!B30 -> TSE-014 | F26: HW 지상시험 | J26: O | Z26: CSS-003
B27: SYS-024 | C27: S-band Downlink Time | D27: 큐브 위성의 S-band를 이용하여 데이터를 송신하기 위해서는 최대 TBDsec 동안 통신함 | E27: =Mission!B30 -> TSE-014 | F27: HW 지상시험 | J27: O | Z27: CSS-004
Y28: blank
A29: blank
Z31: LEVEL 5 | AA31: 자기장 센서 (Magnetometer, MMT) | AD31: Verification 내용 | AE31: Verification Method | AI31: 기술문서 | AJ31: 확인
Z32: ID | AA32: Title | AB32: Requirement | AC32: Rationale | AE32: A | AF32: I | AG32: T | AH32: D
Z33: MMT
Z34: MMT
Z35: MMT
Z36: MMT
Y37: blank
Z40: LEVEL 5 | AA40: 자이로 센서 (Gyro) | AD40: Verification 내용 | AE40: Verification Method | AI40: 기술문서 | AJ40: 확인
Z41: ID | AA41: Title | AB41: Requirement | AC41: Rationale | AE41: A | AF41: I | AG41: T | AH41: D
Z42: Gyro-001
Z43: Gyro-002
...

Sheet GRD 
B1: width 10 | C1: width 30 | D1: width 100 | E1: width 10 | F1: width 30 | G1: width5 | H1: width5 | I1: width5 | J1: width5 | K1: width20 | L1: width5 | N1: width 10 | O1: width 30 | P1: width 100 | Q1: width 10 | R1: width 30 | S1: width5 | T1: width5 | U1: width5 | V1: width5 | W1: width20 | X1: width5 | Z1: width 10 | AA1: width 30 | AB1: width 100 | AC1: width 10 | AD1: width 30 | AE1: width5 | AF1: width5 | AG1: width5 | AH1: width5 | AI1: width20 | AJ1: width5 | AL1: width 10 | AM1: width 30 | AN1: width 100 | AO1: width 10 | AP1: width 30 | AQ1: width5 | AR1: width5 | AS1: width5 | AT1: width5 | AU1: width20 | AV1: width5 | AX1: width 10 | AY1: width 30 | AZ1: width 100 | BA1: width 10 | BB1: width 30 | BC1: width5 | BD1: width5 | BE1: width5 | BF1: width5 | BG1: width20 | BH1: width5 | BJ1: width 10 | BK1: width 30 | BL1: width 100 | BM1: width 10 | BN1: width 30 | BO1: width5 | BP1: width5 | BQ1: width5 | BR1: width5 | BS1: width20 | BT1: width5
B2: LEVEL 3 | C2: 지상국(Ground Station, GRD) | F2: Verification 내용 | G2: Verification Method | K2: 기술문서 | L2: 확인 | N2: LEVEL 4 | O2: Instrument Control Subsystem | R2: Verification 내용 | S2: Verification Method | W2: 기술문서 | X2: 확인 | Z2: LEVEL5 | AA2: 지상국 UHF 송수신기(UHF Tranciever) | AD2: Verification 내용 | AE2: Verification Method | AI2: 기술문서 | AJ2: 확인
B3: ID | C3: Title | D3: Requirement | E3: Rationale | G3: A | H3: I | I3: T | J3: D | N3: ID | O3: Title | P3: Requirement | Q3: Rationale | S3: A | T3: I | U3: T | V3: D | Z3: ID | AA3: Title | AB3: Requirement | AC3: Rationale | AE3: A | AF3: I | AG3: T | AH3: D
B4: GRD-001 | C4: Frequency tracking | D4: 지상국은 도플러 효과에 의한 큐브위성시스템의 주파수 변화를 추적할 수 있어야 함 | E4: =Mission!B30 -> TSE-014 | N4: =B38 -> ABP-001 | O4: Amateur radio station | P4: 지상국은 무선국으로 등록되어야 함 | Q4: =B38 -> ABP-001 | R4: 아마추어 무선국 등록 | T4: ○ | Z4: TRXU
B5: GRD-002 | C5: UHF Frequency | D5: 지상국은 큐브위성시스템과 UHF 대역을 이용하여 통신함 | E5: =Mission!B30 -> TSE-014 | F5: 통신 시험 | N5: =B39 -> ABP-002 | O5: Command license | P5: UHF 대역 지상국은 프로젝트의 주 지상국으로 작동해야 함 | Q5: =B39 -> ABP-002 | R5: 통신 전략 확인 | U5: ○ | Z5: TRXU
B6: GRD-003 | C6: S-band Frequency | D6: 지상국은 큐브위성시스템과 S-band 대역을 이용하여 통신함 | E6: =Mission!B30 -> TSE-014 | F6: 통신 시험 | N6: ICS-003 | O6: Communication protocol | P6: 지상국 ICS는 위성 송수신기가 지원하는 프로토콜을 따라야 함 | Q6: =B27 -> GRD-001 | R6: 데이터 시트 확인 | T6: ○ | Z6: TRXU
B7: GRD-004 | C7: UHF Telecommand | D7: 지상국은 UHF 대역으로 최대 TBD sec 동안 위성제어변수 변경 명령을 송신할 수 있어야 함 | E7: =Mission!B30 -> TSE-014 | F7: 통신 시험 | N7: ICS-004 | O7: UHF opertaion frequency | P7: UHF 대역의 TBD 에서 송수신이 가능해야 함 | Q7: =B27 -> GRD-001 | R7: 통신 시험 | V7: ○ | Z7: TRXU
B8: GRD-004 | C8: S-band Telecommand | D8: 지상국은 S-band 대역으로 최대 TBD sec 동안 S/W 변경 명령을 송신할 수 있어야 함 | E8: =Mission!B30 -> TSE-014 | F8: 통신 시험 | N8: ICS-005 | O8: Beacon data rate | P8: 지상국은 위성이 송신하는 비콘을 수신할 수 있어야 함 (> TBD bps) | Q8: =B27 -> GRD-001 | R8: 통신 시험 | V8: ○ | Z8: TRXU
B9: GRD-005 | C9: Telemetry | D9: 지상국은 UHF 대역으로 최대 TBD sec 동안 큐브위성시스템의 상태정보를 수신 | E9: =Mission!B30 -> TSE-014 | F9: 통신 시험 | N9: ICS-006 | O9: UHF downlink date rate | P9: 지상국은 위성이 송신하는 UHF 대역 데이터를 수신할 수 있어야 함 (> TBD bps) | Q9: =B27 -> GRD-001 | R9: 통신 시험 | V9: ○ | Y9: blank
B10: GRD-006 | C10: UHF Mission Data Downlink | D10: 지상국은 UHF 대역으로 최대 TBD sec 동안 큐브위성시스템의 임무데이터를 수신 | E10: =Mission!B30 -> TSE-014 | F10: 지상국 FDS 성능 검증 | N10: ICS-007 | O10: S-band operation frequency | P10: S 대역의 TBD에서 수신이 가능해야 함 | Q10: =B28 -> GRD-002 | R10: 통신 시험 | V10: ○
B11: GRD-007 | C11: S-band Mission Data Downlink | D11: 지상국은 S-band 대역으로 최대 TBD sec 동안 큐브위성시스템의 임무데이터를 수신 | E11: =Mission!B30 -> TSE-014 | N11: ICS-008 | O11: S-band downlink data rate | P11: 지상국은 위성이 송신하는 S 대역 데이터를 수신할 수 있어야 함 (> TBD bps) | Q11: =B28 -> GRD-002 | R11: 통신 시험 | V11: ○
B12: GRD-008 | C12: Monitor Satellite | D12: 지상국은 수신되고 있는 큐브위성시스템의 상태정보를 시각적으로 보여줄 수 있어야 함 | E12: =Mission!B17 -> TSE-001 | F12: 지상국 MPS 성능시험 | N12: ICS-009 | O12: UHF uplink date rate | P12: 지상국은 UHF 대역에서 TBD bps 에상으로 위성에 명령을 데이터 손실 없이 송신할 수 있어야 함 | Q12: =B27 -> GRD-001 | R12: 통신 시험 | V12: ○ | Z12: LEVEL5 | AA12: 지상국 S 대역 수신기(S-band Receiver) | AD12: Verification 내용 | AE12: Verification Method | AI12: 기술문서 | AJ12: 확인
B13: GRD-009 | C13: Data Storage | D13: 지상국은 송수신한 큐브위성시스템의 상태정보를 기록하고 관리할 수 있는 TBD 이상의 저장공간이 필요함 | E13: =Mission!B17 -> TSE-001 | N13: ICS-010 | O13: Uplink link-margin | P13: 지상국의 상향 링크 마진은 TBD 이상이어야 함 | Q13: =B27 -> GRD-001 | R13: 링크 분석 | S13: ○ | U13: ○ | Z13: ID | AA13: Title | AB13: Requirement | AC13: Rationale | AE13: A | AF13: I | AG13: T | AH13: D
B14: GRD-010 | C14: Misstion Data Storage | D14: 지상국은 수신한 큐브위성시스템의 임무데이터를 기록하고 관리할 수 있는 TBD 이상의 저장공간이 필요함 | E14: =Mission!B17 -> TSE-001 | N14: ICS-011 | O14: Satellite tracking | P14: 지상국 안테나는 예측된 위성의 움직임을 TBD deg 이내로 추적지향할 수 있어야 함 | Q14: =B31 -> GRD-005 | R14: raw 데이터 성능 검증 | U14: ○ | Z14: RXS
B15: GRD-011 | C15: Link | D15: 지상국은 저장된 임무데이터를 레이저 능동방어 시스템에 전달 할 수 있어야 함 | E15: =Mission!B18 -> TSE-002 | N15: ICS-012 | O15: Frequency tracking | P15: 지상국은 도플러 효과에 의해 변경된 위성 주파수에 따라 주파수를 변경할 수 있어야 함 | Q15: =B30 -> GRD-004 | R15: 주파수 변경 가능 확인 | T15: ○ | Z15: RXS
B16: GRD-012 | C16: Monitor Satellite orbit | D16: 지상국은 큐브위성시스템의 궤도를 관찰할 수 있어야 함 | E16: =Mission!B17 -> TSE-001 | N16: ICS-013 | O16: Computer spec. | P16: 지상국의 PC는 TBD 이상의 성능을 가져야 함 | Q16: =B33 -> GRD-007 | R16: 데이터 시트 확인 | T16: ○ | Z16: RXS
B17: GRD-013 | C17: Satelllite tracking | D17: 지상국은 큐브위성시스템의 궤도를 예측하여 다음 통신 시간을 TBDsec의 오차 이내로 결정해야 함 | E17: =Mission!B17 -> TSE-001 | N17: ICS-014 | O17: Receiver sensitivity | P17: 지상국의 하드웨어는 위성 신호를 수신기의 민감도 이상으로 수신할 수 있어야 함 | Q17: =B35 -> GRD-009 | R17: 통신 시험 | S17: ○ | V17: ○ | Y17: blank | Z17: RXS
A18: blank | B18: GRD-014 | C18: Mission Timeline | D18: 지상국은 Mission Timeline을 확인하고 큐브위성시스템 상태에 따라 변경할 수 있음 | E18: =Mission!B17 -> TSE-001 | M18: blank
B19: GRD-015 | C19: Data Download Scenario | D19: 지상국은 데이터 download 시나리오를 확인하고 큐브위성시스템 상태에 따라 변경할 수 있음 | E19: =Mission!B17 -> TSE-001
B20: ABP-001 | C20: Amateur radio station | D20: 지상국은 무선국으로 등록되어야 함 | E20: =Mission!B17 -> TSE-001 | Z20: LEVEL5 | AA20: UHF 지상국 안테나 및 로테이터(Antenna, Rotator) | AD20: Verification 내용 | AE20: Verification Method | AI20: 기술문서 | AJ20: 확인
B21: ABP-002 | C21: Command license | D21: 등록된 지상국으로만 큐브위성시스템에 명령을 송신할 수 있음 | E21: =Mission!B30 -> TSE-014 | Z21: ID | AA21: Title | AB21: Requirement | AC21: Rationale | AE21: A | AF21: I | AG21: T | AH21: D
Z22: ANTU
Z23: ANTU
Z24: ANTU
Z25: ANTU
Y26: blank | Z26: ANTU
B27: GRD-001 | C27: UHF Communication | D27: 지상국은 위성과 UHF 대역 신호를 안정적으로 송수신할 수 있어야 함 | F27: 통신 시험 | J27: O
B28: GRD-002 | C28: S-band Communication | D28: 지상국은 위성이 송신하는 S 대역 신호를 안정적으로 수신할 수 있어야 함 | F28: 통신 시험 | J28: O
B29: GRD-003 | C29: Satellite tracking | D29: 위성의 위치를 실시간으로 확인하고 다음 통신 시간을 TBD초의 오차 내로 예측 가능해야 함 | F29: 지상국 GUI/FDS 성능 검증 | I29: O
B30: GRD-004 | C30: Frequency tracking | D30: 지상국은 도플러 효과에 의한 위성의 주파수 변화를 추적할 수 있어야 함 | F30: 지상국 GUI 성능 검증 | H30: O
B31: GRD-005 | C31: GS compatibility | D31: 지상국은 하드웨어, 소프트웨어 간에 호환이 되어야 함 | F31: 인터페이스 확인 | I31: O
B32: GRD-006 | C32: Communication compatibility | D32: 지상국의 하드웨어는 위성 통신계의 하드웨어와 호환이 되어야 함 | F32: 데이터 시트 확인 | H32: O
B33: GRD-007 | C33: Computer spec. | D33: 지상국의 PC는 TBD 이상의 성능을 가져야 함 | F33: 데이터 시트 확인 | H33: O
B34: GRD-008 | C34: Configurability | D34: 지상국은 위성의 제어 변수를 변경하는 명령을 송신할 수 있어야 함 | F34: 통신 시험 | I34: O
B35: GRD-009 | C35: Receiver sensitivity | D35: 지상국의 하드웨어는 위성 신호를 수신기의 민감도 이상으로 수신할 수 있어야 함 | F35: 통신 시험 | J35: O
B36: GRD-010 | C36: Satellite monitoring | D36: 지상국은 수신한 위성 센서 데이터를 바탕으로 위성의 정밀한 상태 정보를 결정할 수 있어야 함 | F36: 지상국 GUI 성능 검증 | I36: O | N36: LEVEL 4 | O36: Ground Station Software | R36: Verification 내용 | S36: Verification Method | W36: 기술문서 | X36: 확인 | Z36: LEVEL5 | AA36: Graphic User Interface | AD36: Verification 내용 | AE36: Verification Method | AI36: 기술문서 | AJ36: 확인
B37: GRD-011 | C37: Satellite state determination | D37: 지상국 소프트웨어는 수신한 위성 정보를 저장하고 시각적으로 보여줄 수 있어야 함 | F37: 지상국 FDS 성능 검증 | I37: O | N37: ID | O37: Title | P37: Requirement | Q37: Rationale | S37: A | T37: I | U37: T | V37: D | Z37: ID | AA37: Title | AB37: Requirement | AC37: Rationale | AE37: A | AF37: I | AG37: T | AH37: D
B38: ABP-001 | C38: Amateur radio station | D38: 지상국은 무선국으로 등록되어야 함 | F38: 아마추어 무선국 등록 | H38: O | N38: GSW-001 | O38: H/W control | P38: 지상국 소프트웨어는 지상국의 모든 하드웨어를 제어할 수 있어야 함 | Q38: =B31 -> GRD-005 | R38: H/W 운용 시험 | U38: ○ | Z38: GUI
B39: ABP-002 | C39: Command license | D39: 지상국은 프로젝트의 주 지상국으로 작동해야함 | F39: 통신 전략 확인 | I39: O | N39: GSW-002 | O39: Data reading | P39: 지상국 소프트웨어는 다른 서브시스템들의 데이터를 읽어올 수 있어야 함 | Q39: =B36 -> GRD-010 | R39: 데이터 인터페이스 시험 | U39: ○ | Z39: GUI
N40: GSW-003 | O40: Data conversion | P40: 지상국 소프트웨어는 다른 서브시스템들의 데이터 양식에 맞춰 읽어온 데이터를 변환할 수 있어야 함 | Q40: =B34 -> GRD-008 | R40: 데이터 인터페이스 시험 | U40: ○ | Z40: GUI
...
